[ 2024-04-30 23:19:17,491 ] 91 root - INFO - Starting all threads
[ 2024-04-30 23:19:17,491 ] 91 root - INFO - Starting all threads
[ 2024-04-30 23:19:17,491 ] 91 root - INFO - Meta: {'__module__': 'src.globals', '__doc__': '        Meta configs        ', 'keyword': '行政', 'test_mode': True, 'debug_mode': True, 'onlyday': True, 'max_num_retry': 5, 'default_num_threads': 1, 'display_number': 50, 'main_phone_number_dash': '080-1583-0891', 'uc': True, 'headless': False, 'timeout': 900, '__dict__': <attribute '__dict__' of 'Meta' objects>, '__weakref__': <attribute '__weakref__' of 'Meta' objects>}
[ 2024-04-30 23:19:17,491 ] 91 root - INFO - Meta: {'__module__': 'src.globals', '__doc__': '        Meta configs        ', 'keyword': '行政', 'test_mode': True, 'debug_mode': True, 'onlyday': True, 'max_num_retry': 5, 'default_num_threads': 1, 'display_number': 50, 'main_phone_number_dash': '080-1583-0891', 'uc': True, 'headless': False, 'timeout': 900, '__dict__': <attribute '__dict__' of 'Meta' objects>, '__weakref__': <attribute '__weakref__' of 'Meta' objects>}
[ 2024-04-30 23:19:17,491 ] 91 root - INFO - Number of dev accounts: 7
[ 2024-04-30 23:19:17,491 ] 91 root - INFO - Number of dev accounts: 7
[ 2024-04-30 23:19:17,492 ] 91 root - INFO - Test mode: True
[ 2024-04-30 23:19:17,492 ] 91 root - INFO - Test mode: True
[ 2024-04-30 23:19:17,493 ] 91 main_controller - INFO - Subprocess 0 started with trial number 0
[ 2024-04-30 23:19:17,493 ] 91 main_controller - ERROR - Account is a dictionary, convert to Account object: Username: luthien5921@gmail.com, Password: aichi@5921
[ 2024-04-30 23:19:19,225 ] 91 main_controller - INFO - Browser opened
[ 2024-04-30 23:19:19,494 ] 91 root - INFO - Thread 0 started
[ 2024-04-30 23:19:19,494 ] 91 root - INFO - Thread 0 started
[ 2024-04-30 23:19:24,724 ] 91 luthien5921 - INFO - Opened login page
[ 2024-04-30 23:19:35,003 ] 79 main_controller - ERROR - Caught exception: sequence item 1: expected str instance, NoSuchWindowException found
Traceback (most recent call last):
  File "D:\luthien\code\Achi.Tool\AichiSelenium\src\controllers\access.py", line 29, in login
    wait_until_presence(browser, By.ID, "userLoginForm.userId")
  File "D:\luthien\code\Achi.Tool\AichiSelenium\src\utils\html_utils.py", line 8, in wait_until_presence
    WebDriverWait(browser, timeout).until(EC.presence_of_element_located((by, html)))
  File "C:\Users\Admin\anaconda3\envs\aichi\lib\site-packages\selenium\webdriver\support\wait.py", line 96, in until
    value = method(self._driver)
  File "C:\Users\Admin\anaconda3\envs\aichi\lib\site-packages\selenium\webdriver\support\expected_conditions.py", line 84, in _predicate
    return driver.find_element(*locator)
  File "C:\Users\Admin\anaconda3\envs\aichi\lib\site-packages\seleniumbase\core\sb_driver.py", line 20, in find_element
    return self.driver.default_find_element(by=by, value=value)
  File "C:\Users\Admin\anaconda3\envs\aichi\lib\site-packages\selenium\webdriver\remote\webdriver.py", line 741, in find_element
    return self.execute(Command.FIND_ELEMENT, {"using": by, "value": value})["value"]
  File "C:\Users\Admin\anaconda3\envs\aichi\lib\site-packages\selenium\webdriver\remote\webdriver.py", line 347, in execute
    self.error_handler.check_response(response)
  File "C:\Users\Admin\anaconda3\envs\aichi\lib\site-packages\selenium\webdriver\remote\errorhandler.py", line 229, in check_response
    raise exception_class(message, screen, stacktrace)
selenium.common.exceptions.NoSuchWindowException: Message: no such window: target window already closed
from unknown error: web view not found
  (Session info: chrome=124.0.6367.91)
Stacktrace:
	GetHandleVerifier [0x00007FF76017F922+3045234]
	(No symbol) [0x00007FF75FE23652]
	(No symbol) [0x00007FF75FCE7564]
	(No symbol) [0x00007FF75FCBDB4F]
	(No symbol) [0x00007FF75FD61087]
	(No symbol) [0x00007FF75FD78871]
	(No symbol) [0x00007FF75FD59B53]
	(No symbol) [0x00007FF75FD2813C]
	(No symbol) [0x00007FF75FD28D71]
	GetHandleVerifier [0x00007FF7601AE89D+3237613]
	GetHandleVerifier [0x00007FF7601F0BA7+3508727]
	GetHandleVerifier [0x00007FF7601E976F+3478975]
	GetHandleVerifier [0x00007FF75FF5F1C6+815126]
	(No symbol) [0x00007FF75FE2ED0F]
	(No symbol) [0x00007FF75FE29854]
	(No symbol) [0x00007FF75FE299E2]
	(No symbol) [0x00007FF75FE1A574]
	BaseThreadInitThunk [0x00007FF83BAC257D+29]
	RtlUserThreadStart [0x00007FF83C52AA48+40]


During handling of the above exception, another exception occurred:

Traceback (most recent call last):
  File "D:\luthien\code\Achi.Tool\AichiSelenium\src\controllers\main_controller.py", line 58, in subprocess
    result = access.login(browser)
  File "D:\luthien\code\Achi.Tool\AichiSelenium\src\controllers\access.py", line 53, in login
    self.logger.error("Failed to login", e)
  File "D:\luthien\code\Achi.Tool\AichiSelenium\src\logs.py", line 73, in error
    self._log(logging.ERROR, *msg)
  File "D:\luthien\code\Achi.Tool\AichiSelenium\src\logs.py", line 90, in _log
    message = " ".join(msg)
TypeError: sequence item 1: expected str instance, NoSuchWindowException found
