[ 2024-04-24 15:03:26,652 ] 91 root - INFO - Starting all threads
[ 2024-04-24 15:03:26,652 ] 91 root - INFO - Starting all threads
[ 2024-04-24 15:03:26,653 ] 91 root - INFO - Meta: {'__module__': 'src.globals', '__doc__': '        Meta configs        ', 'keyword': '行政', 'test_mode': True, 'debug_mode': True, 'onlyday': True, 'max_num_retry': 5, 'default_num_threads': 1, 'display_number': 50, 'main_phone_number_dash': '080-1583-0891', 'uc': True, 'headless': False, 'timeout': 900, '__dict__': <attribute '__dict__' of 'Meta' objects>, '__weakref__': <attribute '__weakref__' of 'Meta' objects>}
[ 2024-04-24 15:03:26,653 ] 91 root - INFO - Meta: {'__module__': 'src.globals', '__doc__': '        Meta configs        ', 'keyword': '行政', 'test_mode': True, 'debug_mode': True, 'onlyday': True, 'max_num_retry': 5, 'default_num_threads': 1, 'display_number': 50, 'main_phone_number_dash': '080-1583-0891', 'uc': True, 'headless': False, 'timeout': 900, '__dict__': <attribute '__dict__' of 'Meta' objects>, '__weakref__': <attribute '__weakref__' of 'Meta' objects>}
[ 2024-04-24 15:03:26,653 ] 91 root - INFO - Number of dev accounts: 0
[ 2024-04-24 15:03:26,653 ] 91 root - INFO - Number of dev accounts: 0
[ 2024-04-24 15:03:26,653 ] 91 root - INFO - Test mode: True
[ 2024-04-24 15:03:26,653 ] 91 root - INFO - Test mode: True
[ 2024-04-24 15:03:26,656 ] 91 main_controller - INFO - Subprocess 0 started with trial number 0
[ 2024-04-24 15:03:26,656 ] 91 main_controller - ERROR - Account is a dictionary, convert to Account object: Username: luthien5921@gmail.com, Password: aichi@5921
[ 2024-04-24 15:03:28,665 ] 91 root - INFO - Thread 0 started
[ 2024-04-24 15:03:28,665 ] 91 root - INFO - Thread 0 started
[ 2024-04-24 15:03:28,700 ] 91 main_controller - INFO - Browser opened
[ 2024-04-24 15:03:34,616 ] 91 luthien5921 - INFO - Opened login page
[ 2024-04-24 15:03:38,544 ] 91 luthien5921 - INFO - Logging in
[ 2024-04-24 15:03:38,549 ] 91 luthien5921 - INFO - Current url: https://www.shinsei.e-aichi.jp/pref-aichi-police-u/offer/offerList_initDisplay
[ 2024-04-24 15:03:38,860 ] 91 luthien5921 - INFO - Logged in finished
[ 2024-04-24 15:03:38,860 ] 91 main_controller - INFO - Logged in successfully
[ 2024-04-24 15:03:39,118 ] 91 main_controller - INFO - Screenshot saved to C:\Users\USER\Projects\AichiTool\AichiSelenium\logs\2024_04_24\15_03_26\screenshot_luthien5921.png
[ 2024-04-24 15:03:39,119 ] 91 main_controller - INFO - Finding forms
[ 2024-04-24 15:03:39,124 ] 91 luthien5921 - INFO - On main page
[ 2024-04-24 15:03:40,838 ] 91 luthien5921 - INFO - Search submitted
[ 2024-04-24 15:03:40,857 ] 91 luthien5921 - INFO - Collected 2 forms
[ 2024-04-24 15:03:40,930 ] 79 main_controller - ERROR - Caught exception: 'NoneType' object has no attribute 'group'
Traceback (most recent call last):
  File "C:\Users\USER\Projects\AichiTool\AichiSelenium\src\controllers\main_controller.py", line 72, in subprocess
    list_form_info = finder.find(browser)
  File "C:\Users\USER\Projects\AichiTool\AichiSelenium\src\controllers\finder.py", line 25, in find
    self._collect(browser)
  File "C:\Users\USER\Projects\AichiTool\AichiSelenium\src\controllers\finder.py", line 58, in _collect
    form_info = self._parse_data(form_text)
  File "C:\Users\USER\Projects\AichiTool\AichiSelenium\src\controllers\finder.py", line 97, in _parse_data
    form_info = FormInfo(title, status, start_date_str, end_date_str, template_seq)
  File "C:\Users\USER\Projects\AichiTool\AichiSelenium\src\models\form.py", line 77, in __init__
    self.url = FormInfo.get_url(template_seq)
  File "C:\Users\USER\Projects\AichiTool\AichiSelenium\src\utils\data_utils.py", line 57, in string_to_datetime
    year = int(match_date.group(1))
AttributeError: 'NoneType' object has no attribute 'group'
[ 2024-04-24 15:03:43,145 ] 91 main_controller - INFO - Subprocess 0 started with trial number 1
[ 2024-04-24 15:03:45,177 ] 91 main_controller - INFO - Browser opened
[ 2024-04-24 15:03:51,160 ] 79 main_controller - ERROR - Caught exception: sequence item 1: expected str instance, InvalidSessionIdException found
Traceback (most recent call last):
  File "C:\Users\USER\Projects\AichiTool\AichiSelenium\src\controllers\main_controller.py", line 72, in subprocess
    list_form_info = finder.find(browser)
  File "C:\Users\USER\Projects\AichiTool\AichiSelenium\src\controllers\finder.py", line 25, in find
    self._collect(browser)
  File "C:\Users\USER\Projects\AichiTool\AichiSelenium\src\controllers\finder.py", line 58, in _collect
    form_info = self._parse_data(form_text)
  File "C:\Users\USER\Projects\AichiTool\AichiSelenium\src\controllers\finder.py", line 97, in _parse_data
    form_info = FormInfo(title, status, start_date_str, end_date_str, template_seq)
  File "C:\Users\USER\Projects\AichiTool\AichiSelenium\src\models\form.py", line 77, in __init__
    self.url = FormInfo.get_url(template_seq)
  File "C:\Users\USER\Projects\AichiTool\AichiSelenium\src\utils\data_utils.py", line 57, in string_to_datetime
    year = int(match_date.group(1))
AttributeError: 'NoneType' object has no attribute 'group'

During handling of the above exception, another exception occurred:

Traceback (most recent call last):
  File "C:\Users\USER\Projects\AichiTool\AichiSelenium\src\controllers\access.py", line 24, in login
    browser.get(URLs.login_url)
  File "C:\Users\USER\anaconda3\envs\aichi\lib\site-packages\seleniumbase\core\browser_launcher.py", line 3739, in <lambda>
    driver.get = lambda url: uc_special_open_if_cf(
  File "C:\Users\USER\anaconda3\envs\aichi\lib\site-packages\seleniumbase\core\browser_launcher.py", line 396, in uc_special_open_if_cf
    driver.switch_to.window(driver.window_handles[-1])
  File "C:\Users\USER\anaconda3\envs\aichi\lib\site-packages\seleniumbase\undetected\__init__.py", line 326, in __getattribute__
    return super().__getattribute__(item)
  File "C:\Users\USER\anaconda3\envs\aichi\lib\site-packages\selenium\webdriver\remote\webdriver.py", line 494, in window_handles
    return self.execute(Command.W3C_GET_WINDOW_HANDLES)["value"]
  File "C:\Users\USER\anaconda3\envs\aichi\lib\site-packages\selenium\webdriver\remote\webdriver.py", line 347, in execute
    self.error_handler.check_response(response)
  File "C:\Users\USER\anaconda3\envs\aichi\lib\site-packages\selenium\webdriver\remote\errorhandler.py", line 229, in check_response
    raise exception_class(message, screen, stacktrace)
selenium.common.exceptions.InvalidSessionIdException: Message: invalid session id
Stacktrace:
	GetHandleVerifier [0x00007FF61B9DF922+3045234]
	(No symbol) [0x00007FF61B683652]
	(No symbol) [0x00007FF61B547393]
	(No symbol) [0x00007FF61B5874F7]
	(No symbol) [0x00007FF61B5B9C59]
	(No symbol) [0x00007FF61B5B3FEC]
	(No symbol) [0x00007FF61B5B3997]
	(No symbol) [0x00007FF61B5132A5]
	GetHandleVerifier [0x00007FF61BA0E89D+3237613]
	GetHandleVerifier [0x00007FF61BA50BA7+3508727]
	GetHandleVerifier [0x00007FF61BA4976F+3478975]
	GetHandleVerifier [0x00007FF61B7BF1C6+815126]
	(No symbol) [0x00007FF61B68ED0F]
	(No symbol) [0x00007FF61B5122DC]
	GetHandleVerifier [0x00007FF61BAA5158+3854248]
	BaseThreadInitThunk [0x00007FF92E12257D+29]
	RtlUserThreadStart [0x00007FF93022AA48+40]


During handling of the above exception, another exception occurred:

Traceback (most recent call last):
  File "C:\Users\USER\Projects\AichiTool\AichiSelenium\src\controllers\main_controller.py", line 58, in subprocess
    result = access.login(browser)
  File "C:\Users\USER\Projects\AichiTool\AichiSelenium\src\controllers\access.py", line 51, in login
    self.logger.error("Failed to login", e)
  File "C:\Users\USER\Projects\AichiTool\AichiSelenium\src\logs.py", line 73, in error
    self._log(logging.ERROR, *msg)
  File "C:\Users\USER\Projects\AichiTool\AichiSelenium\src\logs.py", line 90, in _log
    message = " ".join(msg)
TypeError: sequence item 1: expected str instance, InvalidSessionIdException found
