[ 2024-04-16 04:35:59,269 ] 94 main_controller - ERROR - Account is a dictionary, convert to Account object: Username: luthien5921@gmail.com, Password: aichi@5921
[ 2024-04-16 04:36:01,926 ] 94 main_controller - INFO - Browser opened
[ 2024-04-16 04:36:11,071 ] 94 main_controller - INFO - Logged in successfully
[ 2024-04-16 04:36:11,310 ] 94 main_controller - INFO - Screenshot saved to C:\Users\USER\Projects\AichiTool\AichiSelenium\logs\2024_04_16\04_35_58\screenshot_luthien5921.png
[ 2024-04-16 04:36:11,310 ] 94 main_controller - INFO - Finding forms
[ 2024-04-16 04:36:13,194 ] 94 main_controller - INFO - Found 4 form(s)
[ 2024-04-16 04:36:18,871 ] 94 main_controller - INFO - Form is closed, template sequence: 90548
[ 2024-04-16 04:36:18,871 ] 94 main_controller - INFO - Remaining form(s): 3
[ 2024-04-16 04:36:28,963 ] 82 main_controller - ERROR - Caught exception: argument of type 'UnexpectedAlertPresentException' is not iterable
Traceback (most recent call last):
  File "C:\Users\USER\Projects\AichiTool\AichiSelenium\src\controllers\filler.py", line 89, in fill
    page_src = browser.page_source
  File "C:\ProgramData\anaconda3\envs\aichi\lib\site-packages\seleniumbase\undetected\__init__.py", line 326, in __getattribute__
    return super().__getattribute__(item)
  File "C:\ProgramData\anaconda3\envs\aichi\lib\site-packages\selenium\webdriver\remote\webdriver.py", line 448, in page_source
    return self.execute(Command.GET_PAGE_SOURCE)["value"]
  File "C:\ProgramData\anaconda3\envs\aichi\lib\site-packages\selenium\webdriver\remote\webdriver.py", line 347, in execute
    self.error_handler.check_response(response)
  File "C:\ProgramData\anaconda3\envs\aichi\lib\site-packages\selenium\webdriver\remote\errorhandler.py", line 228, in check_response
    raise exception_class(message, screen, stacktrace, alert_text)  # type: ignore[call-arg]  # mypy is not smart enough here
selenium.common.exceptions.UnexpectedAlertPresentException: Alert Text: 整理番号・パスワードをメモなどにお控えいただくか、
当ページをファイルに保存、または印刷して保管してください。
整理番号・パスワードを紛失すると
申込内容を照会できなくなる可能性がございます。
Message: unexpected alert open: {Alert text : 整理番号・パスワードをメモなどにお控えいただくか、
当ページをファイルに保存、または印刷して保管してください。
整理番号・パスワードを紛失すると
申込内容を照会できなくなる可能性がございます。}
  (Session info: chrome=123.0.6312.107)
Stacktrace:
	GetHandleVerifier [0x00007FF770D87032+63090]
	(No symbol) [0x00007FF770CF2C82]
	(No symbol) [0x00007FF770B8EC65]
	(No symbol) [0x00007FF770C13B70]
	(No symbol) [0x00007FF770BF6D83]
	(No symbol) [0x00007FF770BC83A8]
	(No symbol) [0x00007FF770BC9441]
	GetHandleVerifier [0x00007FF7711825AD+4238317]
	GetHandleVerifier [0x00007FF7711BF70D+4488525]
	GetHandleVerifier [0x00007FF7711B79EF+4456495]
	GetHandleVerifier [0x00007FF770E60576+953270]
	(No symbol) [0x00007FF770CFE54F]
	(No symbol) [0x00007FF770CF9224]
	(No symbol) [0x00007FF770CF935B]
	(No symbol) [0x00007FF770CE9B94]
	BaseThreadInitThunk [0x00007FFDC2F1257D+29]
	RtlUserThreadStart [0x00007FFDC3E0AA48+40]


During handling of the above exception, another exception occurred:

Traceback (most recent call last):
  File "C:\Users\USER\Projects\AichiTool\AichiSelenium\src\controllers\main_controller.py", line 75, in subprocess
    filler.fill(browser, form_info)
  File "C:\Users\USER\Projects\AichiTool\AichiSelenium\src\controllers\filler.py", line 100, in fill
    if EndMessage.DEFENSE_ERROR in e:
TypeError: argument of type 'UnexpectedAlertPresentException' is not iterable
[ 2024-04-16 04:36:28,965 ] 94 main_controller - INFO - Closing browser
[ 2024-04-16 04:36:31,184 ] 94 main_controller - INFO - Browser closed
