[ 2024-04-30 22:44:36,429 ] 91 main_controller - INFO - Subprocess 0 started with trial number 0
[ 2024-04-30 22:44:36,430 ] 91 main_controller - ERROR - Account is a dictionary, convert to Account object: Username: luthien5921@gmail.com, Password: aichi@5921
[ 2024-04-30 22:44:38,433 ] 91 main_controller - INFO - Subprocess 1 started with trial number 0
[ 2024-04-30 22:44:38,433 ] 91 main_controller - INFO - Subprocess 1 started with trial number 0
[ 2024-04-30 22:44:38,433 ] 91 main_controller - ERROR - Account is a dictionary, convert to Account object: Username: luthien5921+shinsei1@gmail.com, Password: aichi@5921
[ 2024-04-30 22:44:38,433 ] 91 main_controller - ERROR - Account is a dictionary, convert to Account object: Username: luthien5921+shinsei1@gmail.com, Password: aichi@5921
[ 2024-04-30 22:44:39,254 ] 91 main_controller - INFO - Browser opened
[ 2024-04-30 22:44:39,254 ] 91 main_controller - INFO - Browser opened
[ 2024-04-30 22:44:40,442 ] 91 main_controller - INFO - Subprocess 2 started with trial number 0
[ 2024-04-30 22:44:40,442 ] 91 main_controller - INFO - Subprocess 2 started with trial number 0
[ 2024-04-30 22:44:40,442 ] 91 main_controller - INFO - Subprocess 2 started with trial number 0
[ 2024-04-30 22:44:40,443 ] 91 main_controller - ERROR - Account is a dictionary, convert to Account object: Username: luthien5921+shinsei2@gmail.com, Password: aichi@5921
[ 2024-04-30 22:44:40,443 ] 91 main_controller - ERROR - Account is a dictionary, convert to Account object: Username: luthien5921+shinsei2@gmail.com, Password: aichi@5921
[ 2024-04-30 22:44:40,443 ] 91 main_controller - ERROR - Account is a dictionary, convert to Account object: Username: luthien5921+shinsei2@gmail.com, Password: aichi@5921
[ 2024-04-30 22:44:42,284 ] 91 main_controller - INFO - Browser opened
[ 2024-04-30 22:44:42,284 ] 91 main_controller - INFO - Browser opened
[ 2024-04-30 22:44:42,284 ] 91 main_controller - INFO - Browser opened
[ 2024-04-30 22:44:44,699 ] 91 main_controller - INFO - Browser opened
[ 2024-04-30 22:44:44,699 ] 91 main_controller - INFO - Browser opened
[ 2024-04-30 22:44:44,699 ] 91 main_controller - INFO - Browser opened
[ 2024-04-30 22:44:57,151 ] 79 main_controller - ERROR - Caught exception: sequence item 1: expected str instance, TimeoutException found
Traceback (most recent call last):
  File "C:\Users\USER\Projects\AichiTool\AichiSelenium\src\controllers\access.py", line 29, in login
    wait_until_presence(browser, By.ID, "userLoginForm.userId")
  File "C:\Users\USER\Projects\AichiTool\AichiSelenium\src\utils\html_utils.py", line 8, in wait_until_presence
    WebDriverWait(browser, timeout).until(EC.presence_of_element_located((by, html)))
  File "C:\Users\USER\anaconda3\envs\aichi\lib\site-packages\selenium\webdriver\support\wait.py", line 105, in until
    raise TimeoutException(message, screen, stacktrace)
selenium.common.exceptions.TimeoutException: Message: 
Stacktrace:
	GetHandleVerifier [0x00007FF72E94F922+3045234]
	(No symbol) [0x00007FF72E5F3652]
	(No symbol) [0x00007FF72E4B7564]
	(No symbol) [0x00007FF72E505F9D]
	(No symbol) [0x00007FF72E50606C]
	(No symbol) [0x00007FF72E54BDD7]
	(No symbol) [0x00007FF72E529DEF]
	(No symbol) [0x00007FF72E5491C4]
	(No symbol) [0x00007FF72E529B53]
	(No symbol) [0x00007FF72E4F813C]
	(No symbol) [0x00007FF72E4F8D71]
	GetHandleVerifier [0x00007FF72E97E89D+3237613]
	GetHandleVerifier [0x00007FF72E9C0BA7+3508727]
	GetHandleVerifier [0x00007FF72E9B976F+3478975]
	GetHandleVerifier [0x00007FF72E72F1C6+815126]
	(No symbol) [0x00007FF72E5FED0F]
	(No symbol) [0x00007FF72E5F9854]
	(No symbol) [0x00007FF72E5F99E2]
	(No symbol) [0x00007FF72E5EA574]
	BaseThreadInitThunk [0x00007FFFFB45257D+29]
	RtlUserThreadStart [0x00007FFFFCEEAA48+40]


During handling of the above exception, another exception occurred:

Traceback (most recent call last):
  File "C:\Users\USER\Projects\AichiTool\AichiSelenium\src\controllers\main_controller.py", line 58, in subprocess
    result = access.login(browser)
  File "C:\Users\USER\Projects\AichiTool\AichiSelenium\src\controllers\access.py", line 53, in login
    self.logger.error("Failed to login", e)
  File "C:\Users\USER\Projects\AichiTool\AichiSelenium\src\logs.py", line 73, in error
    self._log(logging.ERROR, *msg)
  File "C:\Users\USER\Projects\AichiTool\AichiSelenium\src\logs.py", line 90, in _log
    message = " ".join(msg)
TypeError: sequence item 1: expected str instance, TimeoutException found
[ 2024-04-30 22:44:57,151 ] 79 main_controller - ERROR - Caught exception: sequence item 1: expected str instance, TimeoutException found
Traceback (most recent call last):
  File "C:\Users\USER\Projects\AichiTool\AichiSelenium\src\controllers\access.py", line 29, in login
    wait_until_presence(browser, By.ID, "userLoginForm.userId")
  File "C:\Users\USER\Projects\AichiTool\AichiSelenium\src\utils\html_utils.py", line 8, in wait_until_presence
    WebDriverWait(browser, timeout).until(EC.presence_of_element_located((by, html)))
  File "C:\Users\USER\anaconda3\envs\aichi\lib\site-packages\selenium\webdriver\support\wait.py", line 105, in until
    raise TimeoutException(message, screen, stacktrace)
selenium.common.exceptions.TimeoutException: Message: 
Stacktrace:
	GetHandleVerifier [0x00007FF72E94F922+3045234]
	(No symbol) [0x00007FF72E5F3652]
	(No symbol) [0x00007FF72E4B7564]
	(No symbol) [0x00007FF72E505F9D]
	(No symbol) [0x00007FF72E50606C]
	(No symbol) [0x00007FF72E54BDD7]
	(No symbol) [0x00007FF72E529DEF]
	(No symbol) [0x00007FF72E5491C4]
	(No symbol) [0x00007FF72E529B53]
	(No symbol) [0x00007FF72E4F813C]
	(No symbol) [0x00007FF72E4F8D71]
	GetHandleVerifier [0x00007FF72E97E89D+3237613]
	GetHandleVerifier [0x00007FF72E9C0BA7+3508727]
	GetHandleVerifier [0x00007FF72E9B976F+3478975]
	GetHandleVerifier [0x00007FF72E72F1C6+815126]
	(No symbol) [0x00007FF72E5FED0F]
	(No symbol) [0x00007FF72E5F9854]
	(No symbol) [0x00007FF72E5F99E2]
	(No symbol) [0x00007FF72E5EA574]
	BaseThreadInitThunk [0x00007FFFFB45257D+29]
	RtlUserThreadStart [0x00007FFFFCEEAA48+40]


During handling of the above exception, another exception occurred:

Traceback (most recent call last):
  File "C:\Users\USER\Projects\AichiTool\AichiSelenium\src\controllers\main_controller.py", line 58, in subprocess
    result = access.login(browser)
  File "C:\Users\USER\Projects\AichiTool\AichiSelenium\src\controllers\access.py", line 53, in login
    self.logger.error("Failed to login", e)
  File "C:\Users\USER\Projects\AichiTool\AichiSelenium\src\logs.py", line 73, in error
    self._log(logging.ERROR, *msg)
  File "C:\Users\USER\Projects\AichiTool\AichiSelenium\src\logs.py", line 90, in _log
    message = " ".join(msg)
TypeError: sequence item 1: expected str instance, TimeoutException found
[ 2024-04-30 22:44:57,151 ] 79 main_controller - ERROR - Caught exception: sequence item 1: expected str instance, TimeoutException found
Traceback (most recent call last):
  File "C:\Users\USER\Projects\AichiTool\AichiSelenium\src\controllers\access.py", line 29, in login
    wait_until_presence(browser, By.ID, "userLoginForm.userId")
  File "C:\Users\USER\Projects\AichiTool\AichiSelenium\src\utils\html_utils.py", line 8, in wait_until_presence
    WebDriverWait(browser, timeout).until(EC.presence_of_element_located((by, html)))
  File "C:\Users\USER\anaconda3\envs\aichi\lib\site-packages\selenium\webdriver\support\wait.py", line 105, in until
    raise TimeoutException(message, screen, stacktrace)
selenium.common.exceptions.TimeoutException: Message: 
Stacktrace:
	GetHandleVerifier [0x00007FF72E94F922+3045234]
	(No symbol) [0x00007FF72E5F3652]
	(No symbol) [0x00007FF72E4B7564]
	(No symbol) [0x00007FF72E505F9D]
	(No symbol) [0x00007FF72E50606C]
	(No symbol) [0x00007FF72E54BDD7]
	(No symbol) [0x00007FF72E529DEF]
	(No symbol) [0x00007FF72E5491C4]
	(No symbol) [0x00007FF72E529B53]
	(No symbol) [0x00007FF72E4F813C]
	(No symbol) [0x00007FF72E4F8D71]
	GetHandleVerifier [0x00007FF72E97E89D+3237613]
	GetHandleVerifier [0x00007FF72E9C0BA7+3508727]
	GetHandleVerifier [0x00007FF72E9B976F+3478975]
	GetHandleVerifier [0x00007FF72E72F1C6+815126]
	(No symbol) [0x00007FF72E5FED0F]
	(No symbol) [0x00007FF72E5F9854]
	(No symbol) [0x00007FF72E5F99E2]
	(No symbol) [0x00007FF72E5EA574]
	BaseThreadInitThunk [0x00007FFFFB45257D+29]
	RtlUserThreadStart [0x00007FFFFCEEAA48+40]


During handling of the above exception, another exception occurred:

Traceback (most recent call last):
  File "C:\Users\USER\Projects\AichiTool\AichiSelenium\src\controllers\main_controller.py", line 58, in subprocess
    result = access.login(browser)
  File "C:\Users\USER\Projects\AichiTool\AichiSelenium\src\controllers\access.py", line 53, in login
    self.logger.error("Failed to login", e)
  File "C:\Users\USER\Projects\AichiTool\AichiSelenium\src\logs.py", line 73, in error
    self._log(logging.ERROR, *msg)
  File "C:\Users\USER\Projects\AichiTool\AichiSelenium\src\logs.py", line 90, in _log
    message = " ".join(msg)
TypeError: sequence item 1: expected str instance, TimeoutException found
[ 2024-04-30 22:44:59,566 ] 91 main_controller - INFO - Subprocess 0 started with trial number 1
[ 2024-04-30 22:44:59,566 ] 91 main_controller - INFO - Subprocess 0 started with trial number 1
[ 2024-04-30 22:44:59,566 ] 91 main_controller - INFO - Subprocess 0 started with trial number 1
[ 2024-04-30 22:44:59,566 ] 91 main_controller - INFO - Subprocess 0 started with trial number 1
[ 2024-04-30 22:44:59,887 ] 79 main_controller - ERROR - Caught exception: sequence item 1: expected str instance, TimeoutException found
Traceback (most recent call last):
  File "C:\Users\USER\Projects\AichiTool\AichiSelenium\src\controllers\access.py", line 29, in login
    wait_until_presence(browser, By.ID, "userLoginForm.userId")
  File "C:\Users\USER\Projects\AichiTool\AichiSelenium\src\utils\html_utils.py", line 8, in wait_until_presence
    WebDriverWait(browser, timeout).until(EC.presence_of_element_located((by, html)))
  File "C:\Users\USER\anaconda3\envs\aichi\lib\site-packages\selenium\webdriver\support\wait.py", line 105, in until
    raise TimeoutException(message, screen, stacktrace)
selenium.common.exceptions.TimeoutException: Message: 
Stacktrace:
	GetHandleVerifier [0x00007FF72E94F922+3045234]
	(No symbol) [0x00007FF72E5F3652]
	(No symbol) [0x00007FF72E4B7564]
	(No symbol) [0x00007FF72E505F9D]
	(No symbol) [0x00007FF72E50606C]
	(No symbol) [0x00007FF72E54BDD7]
	(No symbol) [0x00007FF72E529DEF]
	(No symbol) [0x00007FF72E5491C4]
	(No symbol) [0x00007FF72E529B53]
	(No symbol) [0x00007FF72E4F813C]
	(No symbol) [0x00007FF72E4F8D71]
	GetHandleVerifier [0x00007FF72E97E89D+3237613]
	GetHandleVerifier [0x00007FF72E9C0BA7+3508727]
	GetHandleVerifier [0x00007FF72E9B976F+3478975]
	GetHandleVerifier [0x00007FF72E72F1C6+815126]
	(No symbol) [0x00007FF72E5FED0F]
	(No symbol) [0x00007FF72E5F9854]
	(No symbol) [0x00007FF72E5F99E2]
	(No symbol) [0x00007FF72E5EA574]
	BaseThreadInitThunk [0x00007FFFFB45257D+29]
	RtlUserThreadStart [0x00007FFFFCEEAA48+40]


During handling of the above exception, another exception occurred:

Traceback (most recent call last):
  File "C:\Users\USER\Projects\AichiTool\AichiSelenium\src\controllers\main_controller.py", line 58, in subprocess
    result = access.login(browser)
  File "C:\Users\USER\Projects\AichiTool\AichiSelenium\src\controllers\access.py", line 53, in login
    self.logger.error("Failed to login", e)
  File "C:\Users\USER\Projects\AichiTool\AichiSelenium\src\logs.py", line 73, in error
    self._log(logging.ERROR, *msg)
  File "C:\Users\USER\Projects\AichiTool\AichiSelenium\src\logs.py", line 90, in _log
    message = " ".join(msg)
TypeError: sequence item 1: expected str instance, TimeoutException found
[ 2024-04-30 22:44:59,887 ] 79 main_controller - ERROR - Caught exception: sequence item 1: expected str instance, TimeoutException found
Traceback (most recent call last):
  File "C:\Users\USER\Projects\AichiTool\AichiSelenium\src\controllers\access.py", line 29, in login
    wait_until_presence(browser, By.ID, "userLoginForm.userId")
  File "C:\Users\USER\Projects\AichiTool\AichiSelenium\src\utils\html_utils.py", line 8, in wait_until_presence
    WebDriverWait(browser, timeout).until(EC.presence_of_element_located((by, html)))
  File "C:\Users\USER\anaconda3\envs\aichi\lib\site-packages\selenium\webdriver\support\wait.py", line 105, in until
    raise TimeoutException(message, screen, stacktrace)
selenium.common.exceptions.TimeoutException: Message: 
Stacktrace:
	GetHandleVerifier [0x00007FF72E94F922+3045234]
	(No symbol) [0x00007FF72E5F3652]
	(No symbol) [0x00007FF72E4B7564]
	(No symbol) [0x00007FF72E505F9D]
	(No symbol) [0x00007FF72E50606C]
	(No symbol) [0x00007FF72E54BDD7]
	(No symbol) [0x00007FF72E529DEF]
	(No symbol) [0x00007FF72E5491C4]
	(No symbol) [0x00007FF72E529B53]
	(No symbol) [0x00007FF72E4F813C]
	(No symbol) [0x00007FF72E4F8D71]
	GetHandleVerifier [0x00007FF72E97E89D+3237613]
	GetHandleVerifier [0x00007FF72E9C0BA7+3508727]
	GetHandleVerifier [0x00007FF72E9B976F+3478975]
	GetHandleVerifier [0x00007FF72E72F1C6+815126]
	(No symbol) [0x00007FF72E5FED0F]
	(No symbol) [0x00007FF72E5F9854]
	(No symbol) [0x00007FF72E5F99E2]
	(No symbol) [0x00007FF72E5EA574]
	BaseThreadInitThunk [0x00007FFFFB45257D+29]
	RtlUserThreadStart [0x00007FFFFCEEAA48+40]


During handling of the above exception, another exception occurred:

Traceback (most recent call last):
  File "C:\Users\USER\Projects\AichiTool\AichiSelenium\src\controllers\main_controller.py", line 58, in subprocess
    result = access.login(browser)
  File "C:\Users\USER\Projects\AichiTool\AichiSelenium\src\controllers\access.py", line 53, in login
    self.logger.error("Failed to login", e)
  File "C:\Users\USER\Projects\AichiTool\AichiSelenium\src\logs.py", line 73, in error
    self._log(logging.ERROR, *msg)
  File "C:\Users\USER\Projects\AichiTool\AichiSelenium\src\logs.py", line 90, in _log
    message = " ".join(msg)
TypeError: sequence item 1: expected str instance, TimeoutException found
[ 2024-04-30 22:44:59,887 ] 79 main_controller - ERROR - Caught exception: sequence item 1: expected str instance, TimeoutException found
Traceback (most recent call last):
  File "C:\Users\USER\Projects\AichiTool\AichiSelenium\src\controllers\access.py", line 29, in login
    wait_until_presence(browser, By.ID, "userLoginForm.userId")
  File "C:\Users\USER\Projects\AichiTool\AichiSelenium\src\utils\html_utils.py", line 8, in wait_until_presence
    WebDriverWait(browser, timeout).until(EC.presence_of_element_located((by, html)))
  File "C:\Users\USER\anaconda3\envs\aichi\lib\site-packages\selenium\webdriver\support\wait.py", line 105, in until
    raise TimeoutException(message, screen, stacktrace)
selenium.common.exceptions.TimeoutException: Message: 
Stacktrace:
	GetHandleVerifier [0x00007FF72E94F922+3045234]
	(No symbol) [0x00007FF72E5F3652]
	(No symbol) [0x00007FF72E4B7564]
	(No symbol) [0x00007FF72E505F9D]
	(No symbol) [0x00007FF72E50606C]
	(No symbol) [0x00007FF72E54BDD7]
	(No symbol) [0x00007FF72E529DEF]
	(No symbol) [0x00007FF72E5491C4]
	(No symbol) [0x00007FF72E529B53]
	(No symbol) [0x00007FF72E4F813C]
	(No symbol) [0x00007FF72E4F8D71]
	GetHandleVerifier [0x00007FF72E97E89D+3237613]
	GetHandleVerifier [0x00007FF72E9C0BA7+3508727]
	GetHandleVerifier [0x00007FF72E9B976F+3478975]
	GetHandleVerifier [0x00007FF72E72F1C6+815126]
	(No symbol) [0x00007FF72E5FED0F]
	(No symbol) [0x00007FF72E5F9854]
	(No symbol) [0x00007FF72E5F99E2]
	(No symbol) [0x00007FF72E5EA574]
	BaseThreadInitThunk [0x00007FFFFB45257D+29]
	RtlUserThreadStart [0x00007FFFFCEEAA48+40]


During handling of the above exception, another exception occurred:

Traceback (most recent call last):
  File "C:\Users\USER\Projects\AichiTool\AichiSelenium\src\controllers\main_controller.py", line 58, in subprocess
    result = access.login(browser)
  File "C:\Users\USER\Projects\AichiTool\AichiSelenium\src\controllers\access.py", line 53, in login
    self.logger.error("Failed to login", e)
  File "C:\Users\USER\Projects\AichiTool\AichiSelenium\src\logs.py", line 73, in error
    self._log(logging.ERROR, *msg)
  File "C:\Users\USER\Projects\AichiTool\AichiSelenium\src\logs.py", line 90, in _log
    message = " ".join(msg)
TypeError: sequence item 1: expected str instance, TimeoutException found
[ 2024-04-30 22:44:59,887 ] 79 main_controller - ERROR - Caught exception: sequence item 1: expected str instance, TimeoutException found
Traceback (most recent call last):
  File "C:\Users\USER\Projects\AichiTool\AichiSelenium\src\controllers\access.py", line 29, in login
    wait_until_presence(browser, By.ID, "userLoginForm.userId")
  File "C:\Users\USER\Projects\AichiTool\AichiSelenium\src\utils\html_utils.py", line 8, in wait_until_presence
    WebDriverWait(browser, timeout).until(EC.presence_of_element_located((by, html)))
  File "C:\Users\USER\anaconda3\envs\aichi\lib\site-packages\selenium\webdriver\support\wait.py", line 105, in until
    raise TimeoutException(message, screen, stacktrace)
selenium.common.exceptions.TimeoutException: Message: 
Stacktrace:
	GetHandleVerifier [0x00007FF72E94F922+3045234]
	(No symbol) [0x00007FF72E5F3652]
	(No symbol) [0x00007FF72E4B7564]
	(No symbol) [0x00007FF72E505F9D]
	(No symbol) [0x00007FF72E50606C]
	(No symbol) [0x00007FF72E54BDD7]
	(No symbol) [0x00007FF72E529DEF]
	(No symbol) [0x00007FF72E5491C4]
	(No symbol) [0x00007FF72E529B53]
	(No symbol) [0x00007FF72E4F813C]
	(No symbol) [0x00007FF72E4F8D71]
	GetHandleVerifier [0x00007FF72E97E89D+3237613]
	GetHandleVerifier [0x00007FF72E9C0BA7+3508727]
	GetHandleVerifier [0x00007FF72E9B976F+3478975]
	GetHandleVerifier [0x00007FF72E72F1C6+815126]
	(No symbol) [0x00007FF72E5FED0F]
	(No symbol) [0x00007FF72E5F9854]
	(No symbol) [0x00007FF72E5F99E2]
	(No symbol) [0x00007FF72E5EA574]
	BaseThreadInitThunk [0x00007FFFFB45257D+29]
	RtlUserThreadStart [0x00007FFFFCEEAA48+40]


During handling of the above exception, another exception occurred:

Traceback (most recent call last):
  File "C:\Users\USER\Projects\AichiTool\AichiSelenium\src\controllers\main_controller.py", line 58, in subprocess
    result = access.login(browser)
  File "C:\Users\USER\Projects\AichiTool\AichiSelenium\src\controllers\access.py", line 53, in login
    self.logger.error("Failed to login", e)
  File "C:\Users\USER\Projects\AichiTool\AichiSelenium\src\logs.py", line 73, in error
    self._log(logging.ERROR, *msg)
  File "C:\Users\USER\Projects\AichiTool\AichiSelenium\src\logs.py", line 90, in _log
    message = " ".join(msg)
TypeError: sequence item 1: expected str instance, TimeoutException found
[ 2024-04-30 22:45:02,370 ] 91 main_controller - INFO - Browser opened
[ 2024-04-30 22:45:02,370 ] 91 main_controller - INFO - Browser opened
[ 2024-04-30 22:45:02,370 ] 91 main_controller - INFO - Browser opened
[ 2024-04-30 22:45:02,370 ] 91 main_controller - INFO - Browser opened
[ 2024-04-30 22:45:02,785 ] 91 main_controller - INFO - Subprocess 1 started with trial number 1
[ 2024-04-30 22:45:02,785 ] 91 main_controller - INFO - Subprocess 1 started with trial number 1
[ 2024-04-30 22:45:02,785 ] 91 main_controller - INFO - Subprocess 1 started with trial number 1
[ 2024-04-30 22:45:02,785 ] 91 main_controller - INFO - Subprocess 1 started with trial number 1
[ 2024-04-30 22:45:02,785 ] 91 main_controller - INFO - Subprocess 1 started with trial number 1
[ 2024-04-30 22:45:04,483 ] 91 main_controller - INFO - Browser opened
[ 2024-04-30 22:45:04,483 ] 91 main_controller - INFO - Browser opened
[ 2024-04-30 22:45:04,483 ] 91 main_controller - INFO - Browser opened
[ 2024-04-30 22:45:04,483 ] 91 main_controller - INFO - Browser opened
[ 2024-04-30 22:45:04,483 ] 91 main_controller - INFO - Browser opened
[ 2024-04-30 22:45:04,626 ] 79 main_controller - ERROR - Caught exception: sequence item 1: expected str instance, TimeoutException found
Traceback (most recent call last):
  File "C:\Users\USER\Projects\AichiTool\AichiSelenium\src\controllers\access.py", line 29, in login
    wait_until_presence(browser, By.ID, "userLoginForm.userId")
  File "C:\Users\USER\Projects\AichiTool\AichiSelenium\src\utils\html_utils.py", line 8, in wait_until_presence
    WebDriverWait(browser, timeout).until(EC.presence_of_element_located((by, html)))
  File "C:\Users\USER\anaconda3\envs\aichi\lib\site-packages\selenium\webdriver\support\wait.py", line 105, in until
    raise TimeoutException(message, screen, stacktrace)
selenium.common.exceptions.TimeoutException: Message: 
Stacktrace:
	GetHandleVerifier [0x00007FF72E94F922+3045234]
	(No symbol) [0x00007FF72E5F3652]
	(No symbol) [0x00007FF72E4B7564]
	(No symbol) [0x00007FF72E505F9D]
	(No symbol) [0x00007FF72E50606C]
	(No symbol) [0x00007FF72E54BDD7]
	(No symbol) [0x00007FF72E529DEF]
	(No symbol) [0x00007FF72E5491C4]
	(No symbol) [0x00007FF72E529B53]
	(No symbol) [0x00007FF72E4F813C]
	(No symbol) [0x00007FF72E4F8D71]
	GetHandleVerifier [0x00007FF72E97E89D+3237613]
	GetHandleVerifier [0x00007FF72E9C0BA7+3508727]
	GetHandleVerifier [0x00007FF72E9B976F+3478975]
	GetHandleVerifier [0x00007FF72E72F1C6+815126]
	(No symbol) [0x00007FF72E5FED0F]
	(No symbol) [0x00007FF72E5F9854]
	(No symbol) [0x00007FF72E5F99E2]
	(No symbol) [0x00007FF72E5EA574]
	BaseThreadInitThunk [0x00007FFFFB45257D+29]
	RtlUserThreadStart [0x00007FFFFCEEAA48+40]


During handling of the above exception, another exception occurred:

Traceback (most recent call last):
  File "C:\Users\USER\Projects\AichiTool\AichiSelenium\src\controllers\main_controller.py", line 58, in subprocess
    result = access.login(browser)
  File "C:\Users\USER\Projects\AichiTool\AichiSelenium\src\controllers\access.py", line 53, in login
    self.logger.error("Failed to login", e)
  File "C:\Users\USER\Projects\AichiTool\AichiSelenium\src\logs.py", line 73, in error
    self._log(logging.ERROR, *msg)
  File "C:\Users\USER\Projects\AichiTool\AichiSelenium\src\logs.py", line 90, in _log
    message = " ".join(msg)
TypeError: sequence item 1: expected str instance, TimeoutException found
[ 2024-04-30 22:45:04,626 ] 79 main_controller - ERROR - Caught exception: sequence item 1: expected str instance, TimeoutException found
Traceback (most recent call last):
  File "C:\Users\USER\Projects\AichiTool\AichiSelenium\src\controllers\access.py", line 29, in login
    wait_until_presence(browser, By.ID, "userLoginForm.userId")
  File "C:\Users\USER\Projects\AichiTool\AichiSelenium\src\utils\html_utils.py", line 8, in wait_until_presence
    WebDriverWait(browser, timeout).until(EC.presence_of_element_located((by, html)))
  File "C:\Users\USER\anaconda3\envs\aichi\lib\site-packages\selenium\webdriver\support\wait.py", line 105, in until
    raise TimeoutException(message, screen, stacktrace)
selenium.common.exceptions.TimeoutException: Message: 
Stacktrace:
	GetHandleVerifier [0x00007FF72E94F922+3045234]
	(No symbol) [0x00007FF72E5F3652]
	(No symbol) [0x00007FF72E4B7564]
	(No symbol) [0x00007FF72E505F9D]
	(No symbol) [0x00007FF72E50606C]
	(No symbol) [0x00007FF72E54BDD7]
	(No symbol) [0x00007FF72E529DEF]
	(No symbol) [0x00007FF72E5491C4]
	(No symbol) [0x00007FF72E529B53]
	(No symbol) [0x00007FF72E4F813C]
	(No symbol) [0x00007FF72E4F8D71]
	GetHandleVerifier [0x00007FF72E97E89D+3237613]
	GetHandleVerifier [0x00007FF72E9C0BA7+3508727]
	GetHandleVerifier [0x00007FF72E9B976F+3478975]
	GetHandleVerifier [0x00007FF72E72F1C6+815126]
	(No symbol) [0x00007FF72E5FED0F]
	(No symbol) [0x00007FF72E5F9854]
	(No symbol) [0x00007FF72E5F99E2]
	(No symbol) [0x00007FF72E5EA574]
	BaseThreadInitThunk [0x00007FFFFB45257D+29]
	RtlUserThreadStart [0x00007FFFFCEEAA48+40]


During handling of the above exception, another exception occurred:

Traceback (most recent call last):
  File "C:\Users\USER\Projects\AichiTool\AichiSelenium\src\controllers\main_controller.py", line 58, in subprocess
    result = access.login(browser)
  File "C:\Users\USER\Projects\AichiTool\AichiSelenium\src\controllers\access.py", line 53, in login
    self.logger.error("Failed to login", e)
  File "C:\Users\USER\Projects\AichiTool\AichiSelenium\src\logs.py", line 73, in error
    self._log(logging.ERROR, *msg)
  File "C:\Users\USER\Projects\AichiTool\AichiSelenium\src\logs.py", line 90, in _log
    message = " ".join(msg)
TypeError: sequence item 1: expected str instance, TimeoutException found
[ 2024-04-30 22:45:04,626 ] 79 main_controller - ERROR - Caught exception: sequence item 1: expected str instance, TimeoutException found
Traceback (most recent call last):
  File "C:\Users\USER\Projects\AichiTool\AichiSelenium\src\controllers\access.py", line 29, in login
    wait_until_presence(browser, By.ID, "userLoginForm.userId")
  File "C:\Users\USER\Projects\AichiTool\AichiSelenium\src\utils\html_utils.py", line 8, in wait_until_presence
    WebDriverWait(browser, timeout).until(EC.presence_of_element_located((by, html)))
  File "C:\Users\USER\anaconda3\envs\aichi\lib\site-packages\selenium\webdriver\support\wait.py", line 105, in until
    raise TimeoutException(message, screen, stacktrace)
selenium.common.exceptions.TimeoutException: Message: 
Stacktrace:
	GetHandleVerifier [0x00007FF72E94F922+3045234]
	(No symbol) [0x00007FF72E5F3652]
	(No symbol) [0x00007FF72E4B7564]
	(No symbol) [0x00007FF72E505F9D]
	(No symbol) [0x00007FF72E50606C]
	(No symbol) [0x00007FF72E54BDD7]
	(No symbol) [0x00007FF72E529DEF]
	(No symbol) [0x00007FF72E5491C4]
	(No symbol) [0x00007FF72E529B53]
	(No symbol) [0x00007FF72E4F813C]
	(No symbol) [0x00007FF72E4F8D71]
	GetHandleVerifier [0x00007FF72E97E89D+3237613]
	GetHandleVerifier [0x00007FF72E9C0BA7+3508727]
	GetHandleVerifier [0x00007FF72E9B976F+3478975]
	GetHandleVerifier [0x00007FF72E72F1C6+815126]
	(No symbol) [0x00007FF72E5FED0F]
	(No symbol) [0x00007FF72E5F9854]
	(No symbol) [0x00007FF72E5F99E2]
	(No symbol) [0x00007FF72E5EA574]
	BaseThreadInitThunk [0x00007FFFFB45257D+29]
	RtlUserThreadStart [0x00007FFFFCEEAA48+40]


During handling of the above exception, another exception occurred:

Traceback (most recent call last):
  File "C:\Users\USER\Projects\AichiTool\AichiSelenium\src\controllers\main_controller.py", line 58, in subprocess
    result = access.login(browser)
  File "C:\Users\USER\Projects\AichiTool\AichiSelenium\src\controllers\access.py", line 53, in login
    self.logger.error("Failed to login", e)
  File "C:\Users\USER\Projects\AichiTool\AichiSelenium\src\logs.py", line 73, in error
    self._log(logging.ERROR, *msg)
  File "C:\Users\USER\Projects\AichiTool\AichiSelenium\src\logs.py", line 90, in _log
    message = " ".join(msg)
TypeError: sequence item 1: expected str instance, TimeoutException found
[ 2024-04-30 22:45:04,626 ] 79 main_controller - ERROR - Caught exception: sequence item 1: expected str instance, TimeoutException found
Traceback (most recent call last):
  File "C:\Users\USER\Projects\AichiTool\AichiSelenium\src\controllers\access.py", line 29, in login
    wait_until_presence(browser, By.ID, "userLoginForm.userId")
  File "C:\Users\USER\Projects\AichiTool\AichiSelenium\src\utils\html_utils.py", line 8, in wait_until_presence
    WebDriverWait(browser, timeout).until(EC.presence_of_element_located((by, html)))
  File "C:\Users\USER\anaconda3\envs\aichi\lib\site-packages\selenium\webdriver\support\wait.py", line 105, in until
    raise TimeoutException(message, screen, stacktrace)
selenium.common.exceptions.TimeoutException: Message: 
Stacktrace:
	GetHandleVerifier [0x00007FF72E94F922+3045234]
	(No symbol) [0x00007FF72E5F3652]
	(No symbol) [0x00007FF72E4B7564]
	(No symbol) [0x00007FF72E505F9D]
	(No symbol) [0x00007FF72E50606C]
	(No symbol) [0x00007FF72E54BDD7]
	(No symbol) [0x00007FF72E529DEF]
	(No symbol) [0x00007FF72E5491C4]
	(No symbol) [0x00007FF72E529B53]
	(No symbol) [0x00007FF72E4F813C]
	(No symbol) [0x00007FF72E4F8D71]
	GetHandleVerifier [0x00007FF72E97E89D+3237613]
	GetHandleVerifier [0x00007FF72E9C0BA7+3508727]
	GetHandleVerifier [0x00007FF72E9B976F+3478975]
	GetHandleVerifier [0x00007FF72E72F1C6+815126]
	(No symbol) [0x00007FF72E5FED0F]
	(No symbol) [0x00007FF72E5F9854]
	(No symbol) [0x00007FF72E5F99E2]
	(No symbol) [0x00007FF72E5EA574]
	BaseThreadInitThunk [0x00007FFFFB45257D+29]
	RtlUserThreadStart [0x00007FFFFCEEAA48+40]


During handling of the above exception, another exception occurred:

Traceback (most recent call last):
  File "C:\Users\USER\Projects\AichiTool\AichiSelenium\src\controllers\main_controller.py", line 58, in subprocess
    result = access.login(browser)
  File "C:\Users\USER\Projects\AichiTool\AichiSelenium\src\controllers\access.py", line 53, in login
    self.logger.error("Failed to login", e)
  File "C:\Users\USER\Projects\AichiTool\AichiSelenium\src\logs.py", line 73, in error
    self._log(logging.ERROR, *msg)
  File "C:\Users\USER\Projects\AichiTool\AichiSelenium\src\logs.py", line 90, in _log
    message = " ".join(msg)
TypeError: sequence item 1: expected str instance, TimeoutException found
[ 2024-04-30 22:45:04,626 ] 79 main_controller - ERROR - Caught exception: sequence item 1: expected str instance, TimeoutException found
Traceback (most recent call last):
  File "C:\Users\USER\Projects\AichiTool\AichiSelenium\src\controllers\access.py", line 29, in login
    wait_until_presence(browser, By.ID, "userLoginForm.userId")
  File "C:\Users\USER\Projects\AichiTool\AichiSelenium\src\utils\html_utils.py", line 8, in wait_until_presence
    WebDriverWait(browser, timeout).until(EC.presence_of_element_located((by, html)))
  File "C:\Users\USER\anaconda3\envs\aichi\lib\site-packages\selenium\webdriver\support\wait.py", line 105, in until
    raise TimeoutException(message, screen, stacktrace)
selenium.common.exceptions.TimeoutException: Message: 
Stacktrace:
	GetHandleVerifier [0x00007FF72E94F922+3045234]
	(No symbol) [0x00007FF72E5F3652]
	(No symbol) [0x00007FF72E4B7564]
	(No symbol) [0x00007FF72E505F9D]
	(No symbol) [0x00007FF72E50606C]
	(No symbol) [0x00007FF72E54BDD7]
	(No symbol) [0x00007FF72E529DEF]
	(No symbol) [0x00007FF72E5491C4]
	(No symbol) [0x00007FF72E529B53]
	(No symbol) [0x00007FF72E4F813C]
	(No symbol) [0x00007FF72E4F8D71]
	GetHandleVerifier [0x00007FF72E97E89D+3237613]
	GetHandleVerifier [0x00007FF72E9C0BA7+3508727]
	GetHandleVerifier [0x00007FF72E9B976F+3478975]
	GetHandleVerifier [0x00007FF72E72F1C6+815126]
	(No symbol) [0x00007FF72E5FED0F]
	(No symbol) [0x00007FF72E5F9854]
	(No symbol) [0x00007FF72E5F99E2]
	(No symbol) [0x00007FF72E5EA574]
	BaseThreadInitThunk [0x00007FFFFB45257D+29]
	RtlUserThreadStart [0x00007FFFFCEEAA48+40]


During handling of the above exception, another exception occurred:

Traceback (most recent call last):
  File "C:\Users\USER\Projects\AichiTool\AichiSelenium\src\controllers\main_controller.py", line 58, in subprocess
    result = access.login(browser)
  File "C:\Users\USER\Projects\AichiTool\AichiSelenium\src\controllers\access.py", line 53, in login
    self.logger.error("Failed to login", e)
  File "C:\Users\USER\Projects\AichiTool\AichiSelenium\src\logs.py", line 73, in error
    self._log(logging.ERROR, *msg)
  File "C:\Users\USER\Projects\AichiTool\AichiSelenium\src\logs.py", line 90, in _log
    message = " ".join(msg)
TypeError: sequence item 1: expected str instance, TimeoutException found
[ 2024-04-30 22:45:07,149 ] 91 main_controller - INFO - Subprocess 2 started with trial number 1
[ 2024-04-30 22:45:07,149 ] 91 main_controller - INFO - Subprocess 2 started with trial number 1
[ 2024-04-30 22:45:07,149 ] 91 main_controller - INFO - Subprocess 2 started with trial number 1
[ 2024-04-30 22:45:07,149 ] 91 main_controller - INFO - Subprocess 2 started with trial number 1
[ 2024-04-30 22:45:07,149 ] 91 main_controller - INFO - Subprocess 2 started with trial number 1
[ 2024-04-30 22:45:07,149 ] 91 main_controller - INFO - Subprocess 2 started with trial number 1
[ 2024-04-30 22:45:09,102 ] 91 main_controller - INFO - Browser opened
[ 2024-04-30 22:45:09,102 ] 91 main_controller - INFO - Browser opened
[ 2024-04-30 22:45:09,102 ] 91 main_controller - INFO - Browser opened
[ 2024-04-30 22:45:09,102 ] 91 main_controller - INFO - Browser opened
[ 2024-04-30 22:45:09,102 ] 91 main_controller - INFO - Browser opened
[ 2024-04-30 22:45:09,102 ] 91 main_controller - INFO - Browser opened
[ 2024-04-30 22:45:19,966 ] 79 main_controller - ERROR - Caught exception: sequence item 1: expected str instance, NoSuchWindowException found
Traceback (most recent call last):
  File "C:\Users\USER\Projects\AichiTool\AichiSelenium\src\controllers\access.py", line 29, in login
    wait_until_presence(browser, By.ID, "userLoginForm.userId")
  File "C:\Users\USER\Projects\AichiTool\AichiSelenium\src\utils\html_utils.py", line 8, in wait_until_presence
    WebDriverWait(browser, timeout).until(EC.presence_of_element_located((by, html)))
  File "C:\Users\USER\anaconda3\envs\aichi\lib\site-packages\selenium\webdriver\support\wait.py", line 105, in until
    raise TimeoutException(message, screen, stacktrace)
selenium.common.exceptions.TimeoutException: Message: 
Stacktrace:
	GetHandleVerifier [0x00007FF72E94F922+3045234]
	(No symbol) [0x00007FF72E5F3652]
	(No symbol) [0x00007FF72E4B7564]
	(No symbol) [0x00007FF72E505F9D]
	(No symbol) [0x00007FF72E50606C]
	(No symbol) [0x00007FF72E54BDD7]
	(No symbol) [0x00007FF72E529DEF]
	(No symbol) [0x00007FF72E5491C4]
	(No symbol) [0x00007FF72E529B53]
	(No symbol) [0x00007FF72E4F813C]
	(No symbol) [0x00007FF72E4F8D71]
	GetHandleVerifier [0x00007FF72E97E89D+3237613]
	GetHandleVerifier [0x00007FF72E9C0BA7+3508727]
	GetHandleVerifier [0x00007FF72E9B976F+3478975]
	GetHandleVerifier [0x00007FF72E72F1C6+815126]
	(No symbol) [0x00007FF72E5FED0F]
	(No symbol) [0x00007FF72E5F9854]
	(No symbol) [0x00007FF72E5F99E2]
	(No symbol) [0x00007FF72E5EA574]
	BaseThreadInitThunk [0x00007FFFFB45257D+29]
	RtlUserThreadStart [0x00007FFFFCEEAA48+40]


During handling of the above exception, another exception occurred:

Traceback (most recent call last):
  File "C:\Users\USER\Projects\AichiTool\AichiSelenium\src\controllers\main_controller.py", line 58, in subprocess
    result = access.login(browser)
  File "C:\Users\USER\Projects\AichiTool\AichiSelenium\src\controllers\access.py", line 53, in login
    self.logger.error("Failed to login", e)
  File "C:\Users\USER\Projects\AichiTool\AichiSelenium\src\logs.py", line 73, in error
    self._log(logging.ERROR, *msg)
  File "C:\Users\USER\Projects\AichiTool\AichiSelenium\src\logs.py", line 90, in _log
    message = " ".join(msg)
TypeError: sequence item 1: expected str instance, TimeoutException found

During handling of the above exception, another exception occurred:

Traceback (most recent call last):
  File "C:\Users\USER\Projects\AichiTool\AichiSelenium\src\controllers\access.py", line 29, in login
    wait_until_presence(browser, By.ID, "userLoginForm.userId")
  File "C:\Users\USER\Projects\AichiTool\AichiSelenium\src\utils\html_utils.py", line 8, in wait_until_presence
    WebDriverWait(browser, timeout).until(EC.presence_of_element_located((by, html)))
  File "C:\Users\USER\anaconda3\envs\aichi\lib\site-packages\selenium\webdriver\support\wait.py", line 96, in until
    value = method(self._driver)
  File "C:\Users\USER\anaconda3\envs\aichi\lib\site-packages\selenium\webdriver\support\expected_conditions.py", line 84, in _predicate
    return driver.find_element(*locator)
  File "C:\Users\USER\anaconda3\envs\aichi\lib\site-packages\seleniumbase\core\sb_driver.py", line 20, in find_element
    return self.driver.default_find_element(by=by, value=value)
  File "C:\Users\USER\anaconda3\envs\aichi\lib\site-packages\selenium\webdriver\remote\webdriver.py", line 741, in find_element
    return self.execute(Command.FIND_ELEMENT, {"using": by, "value": value})["value"]
  File "C:\Users\USER\anaconda3\envs\aichi\lib\site-packages\selenium\webdriver\remote\webdriver.py", line 347, in execute
    self.error_handler.check_response(response)
  File "C:\Users\USER\anaconda3\envs\aichi\lib\site-packages\selenium\webdriver\remote\errorhandler.py", line 229, in check_response
    raise exception_class(message, screen, stacktrace)
selenium.common.exceptions.NoSuchWindowException: Message: no such window: target window already closed
from unknown error: web view not found
  (Session info: chrome=124.0.6367.63)
Stacktrace:
	GetHandleVerifier [0x00007FF72E94F922+3045234]
	(No symbol) [0x00007FF72E5F3652]
	(No symbol) [0x00007FF72E4B7564]
	(No symbol) [0x00007FF72E48DB4F]
	(No symbol) [0x00007FF72E531087]
	(No symbol) [0x00007FF72E548871]
	(No symbol) [0x00007FF72E529B53]
	(No symbol) [0x00007FF72E4F813C]
	(No symbol) [0x00007FF72E4F8D71]
	GetHandleVerifier [0x00007FF72E97E89D+3237613]
	GetHandleVerifier [0x00007FF72E9C0BA7+3508727]
	GetHandleVerifier [0x00007FF72E9B976F+3478975]
	GetHandleVerifier [0x00007FF72E72F1C6+815126]
	(No symbol) [0x00007FF72E5FED0F]
	(No symbol) [0x00007FF72E5F9854]
	(No symbol) [0x00007FF72E5F99E2]
	(No symbol) [0x00007FF72E5EA574]
	BaseThreadInitThunk [0x00007FFFFB45257D+29]
	RtlUserThreadStart [0x00007FFFFCEEAA48+40]


During handling of the above exception, another exception occurred:

Traceback (most recent call last):
  File "C:\Users\USER\Projects\AichiTool\AichiSelenium\src\controllers\main_controller.py", line 58, in subprocess
    result = access.login(browser)
  File "C:\Users\USER\Projects\AichiTool\AichiSelenium\src\controllers\access.py", line 53, in login
    self.logger.error("Failed to login", e)
  File "C:\Users\USER\Projects\AichiTool\AichiSelenium\src\logs.py", line 73, in error
    self._log(logging.ERROR, *msg)
  File "C:\Users\USER\Projects\AichiTool\AichiSelenium\src\logs.py", line 90, in _log
    message = " ".join(msg)
TypeError: sequence item 1: expected str instance, NoSuchWindowException found
[ 2024-04-30 22:45:19,966 ] 79 main_controller - ERROR - Caught exception: sequence item 1: expected str instance, NoSuchWindowException found
Traceback (most recent call last):
  File "C:\Users\USER\Projects\AichiTool\AichiSelenium\src\controllers\access.py", line 29, in login
    wait_until_presence(browser, By.ID, "userLoginForm.userId")
  File "C:\Users\USER\Projects\AichiTool\AichiSelenium\src\utils\html_utils.py", line 8, in wait_until_presence
    WebDriverWait(browser, timeout).until(EC.presence_of_element_located((by, html)))
  File "C:\Users\USER\anaconda3\envs\aichi\lib\site-packages\selenium\webdriver\support\wait.py", line 105, in until
    raise TimeoutException(message, screen, stacktrace)
selenium.common.exceptions.TimeoutException: Message: 
Stacktrace:
	GetHandleVerifier [0x00007FF72E94F922+3045234]
	(No symbol) [0x00007FF72E5F3652]
	(No symbol) [0x00007FF72E4B7564]
	(No symbol) [0x00007FF72E505F9D]
	(No symbol) [0x00007FF72E50606C]
	(No symbol) [0x00007FF72E54BDD7]
	(No symbol) [0x00007FF72E529DEF]
	(No symbol) [0x00007FF72E5491C4]
	(No symbol) [0x00007FF72E529B53]
	(No symbol) [0x00007FF72E4F813C]
	(No symbol) [0x00007FF72E4F8D71]
	GetHandleVerifier [0x00007FF72E97E89D+3237613]
	GetHandleVerifier [0x00007FF72E9C0BA7+3508727]
	GetHandleVerifier [0x00007FF72E9B976F+3478975]
	GetHandleVerifier [0x00007FF72E72F1C6+815126]
	(No symbol) [0x00007FF72E5FED0F]
	(No symbol) [0x00007FF72E5F9854]
	(No symbol) [0x00007FF72E5F99E2]
	(No symbol) [0x00007FF72E5EA574]
	BaseThreadInitThunk [0x00007FFFFB45257D+29]
	RtlUserThreadStart [0x00007FFFFCEEAA48+40]


During handling of the above exception, another exception occurred:

Traceback (most recent call last):
  File "C:\Users\USER\Projects\AichiTool\AichiSelenium\src\controllers\main_controller.py", line 58, in subprocess
    result = access.login(browser)
  File "C:\Users\USER\Projects\AichiTool\AichiSelenium\src\controllers\access.py", line 53, in login
    self.logger.error("Failed to login", e)
  File "C:\Users\USER\Projects\AichiTool\AichiSelenium\src\logs.py", line 73, in error
    self._log(logging.ERROR, *msg)
  File "C:\Users\USER\Projects\AichiTool\AichiSelenium\src\logs.py", line 90, in _log
    message = " ".join(msg)
TypeError: sequence item 1: expected str instance, TimeoutException found

During handling of the above exception, another exception occurred:

Traceback (most recent call last):
  File "C:\Users\USER\Projects\AichiTool\AichiSelenium\src\controllers\access.py", line 29, in login
    wait_until_presence(browser, By.ID, "userLoginForm.userId")
  File "C:\Users\USER\Projects\AichiTool\AichiSelenium\src\utils\html_utils.py", line 8, in wait_until_presence
    WebDriverWait(browser, timeout).until(EC.presence_of_element_located((by, html)))
  File "C:\Users\USER\anaconda3\envs\aichi\lib\site-packages\selenium\webdriver\support\wait.py", line 96, in until
    value = method(self._driver)
  File "C:\Users\USER\anaconda3\envs\aichi\lib\site-packages\selenium\webdriver\support\expected_conditions.py", line 84, in _predicate
    return driver.find_element(*locator)
  File "C:\Users\USER\anaconda3\envs\aichi\lib\site-packages\seleniumbase\core\sb_driver.py", line 20, in find_element
    return self.driver.default_find_element(by=by, value=value)
  File "C:\Users\USER\anaconda3\envs\aichi\lib\site-packages\selenium\webdriver\remote\webdriver.py", line 741, in find_element
    return self.execute(Command.FIND_ELEMENT, {"using": by, "value": value})["value"]
  File "C:\Users\USER\anaconda3\envs\aichi\lib\site-packages\selenium\webdriver\remote\webdriver.py", line 347, in execute
    self.error_handler.check_response(response)
  File "C:\Users\USER\anaconda3\envs\aichi\lib\site-packages\selenium\webdriver\remote\errorhandler.py", line 229, in check_response
    raise exception_class(message, screen, stacktrace)
selenium.common.exceptions.NoSuchWindowException: Message: no such window: target window already closed
from unknown error: web view not found
  (Session info: chrome=124.0.6367.63)
Stacktrace:
	GetHandleVerifier [0x00007FF72E94F922+3045234]
	(No symbol) [0x00007FF72E5F3652]
	(No symbol) [0x00007FF72E4B7564]
	(No symbol) [0x00007FF72E48DB4F]
	(No symbol) [0x00007FF72E531087]
	(No symbol) [0x00007FF72E548871]
	(No symbol) [0x00007FF72E529B53]
	(No symbol) [0x00007FF72E4F813C]
	(No symbol) [0x00007FF72E4F8D71]
	GetHandleVerifier [0x00007FF72E97E89D+3237613]
	GetHandleVerifier [0x00007FF72E9C0BA7+3508727]
	GetHandleVerifier [0x00007FF72E9B976F+3478975]
	GetHandleVerifier [0x00007FF72E72F1C6+815126]
	(No symbol) [0x00007FF72E5FED0F]
	(No symbol) [0x00007FF72E5F9854]
	(No symbol) [0x00007FF72E5F99E2]
	(No symbol) [0x00007FF72E5EA574]
	BaseThreadInitThunk [0x00007FFFFB45257D+29]
	RtlUserThreadStart [0x00007FFFFCEEAA48+40]


During handling of the above exception, another exception occurred:

Traceback (most recent call last):
  File "C:\Users\USER\Projects\AichiTool\AichiSelenium\src\controllers\main_controller.py", line 58, in subprocess
    result = access.login(browser)
  File "C:\Users\USER\Projects\AichiTool\AichiSelenium\src\controllers\access.py", line 53, in login
    self.logger.error("Failed to login", e)
  File "C:\Users\USER\Projects\AichiTool\AichiSelenium\src\logs.py", line 73, in error
    self._log(logging.ERROR, *msg)
  File "C:\Users\USER\Projects\AichiTool\AichiSelenium\src\logs.py", line 90, in _log
    message = " ".join(msg)
TypeError: sequence item 1: expected str instance, NoSuchWindowException found
[ 2024-04-30 22:45:19,966 ] 79 main_controller - ERROR - Caught exception: sequence item 1: expected str instance, NoSuchWindowException found
Traceback (most recent call last):
  File "C:\Users\USER\Projects\AichiTool\AichiSelenium\src\controllers\access.py", line 29, in login
    wait_until_presence(browser, By.ID, "userLoginForm.userId")
  File "C:\Users\USER\Projects\AichiTool\AichiSelenium\src\utils\html_utils.py", line 8, in wait_until_presence
    WebDriverWait(browser, timeout).until(EC.presence_of_element_located((by, html)))
  File "C:\Users\USER\anaconda3\envs\aichi\lib\site-packages\selenium\webdriver\support\wait.py", line 105, in until
    raise TimeoutException(message, screen, stacktrace)
selenium.common.exceptions.TimeoutException: Message: 
Stacktrace:
	GetHandleVerifier [0x00007FF72E94F922+3045234]
	(No symbol) [0x00007FF72E5F3652]
	(No symbol) [0x00007FF72E4B7564]
	(No symbol) [0x00007FF72E505F9D]
	(No symbol) [0x00007FF72E50606C]
	(No symbol) [0x00007FF72E54BDD7]
	(No symbol) [0x00007FF72E529DEF]
	(No symbol) [0x00007FF72E5491C4]
	(No symbol) [0x00007FF72E529B53]
	(No symbol) [0x00007FF72E4F813C]
	(No symbol) [0x00007FF72E4F8D71]
	GetHandleVerifier [0x00007FF72E97E89D+3237613]
	GetHandleVerifier [0x00007FF72E9C0BA7+3508727]
	GetHandleVerifier [0x00007FF72E9B976F+3478975]
	GetHandleVerifier [0x00007FF72E72F1C6+815126]
	(No symbol) [0x00007FF72E5FED0F]
	(No symbol) [0x00007FF72E5F9854]
	(No symbol) [0x00007FF72E5F99E2]
	(No symbol) [0x00007FF72E5EA574]
	BaseThreadInitThunk [0x00007FFFFB45257D+29]
	RtlUserThreadStart [0x00007FFFFCEEAA48+40]


During handling of the above exception, another exception occurred:

Traceback (most recent call last):
  File "C:\Users\USER\Projects\AichiTool\AichiSelenium\src\controllers\main_controller.py", line 58, in subprocess
    result = access.login(browser)
  File "C:\Users\USER\Projects\AichiTool\AichiSelenium\src\controllers\access.py", line 53, in login
    self.logger.error("Failed to login", e)
  File "C:\Users\USER\Projects\AichiTool\AichiSelenium\src\logs.py", line 73, in error
    self._log(logging.ERROR, *msg)
  File "C:\Users\USER\Projects\AichiTool\AichiSelenium\src\logs.py", line 90, in _log
    message = " ".join(msg)
TypeError: sequence item 1: expected str instance, TimeoutException found

During handling of the above exception, another exception occurred:

Traceback (most recent call last):
  File "C:\Users\USER\Projects\AichiTool\AichiSelenium\src\controllers\access.py", line 29, in login
    wait_until_presence(browser, By.ID, "userLoginForm.userId")
  File "C:\Users\USER\Projects\AichiTool\AichiSelenium\src\utils\html_utils.py", line 8, in wait_until_presence
    WebDriverWait(browser, timeout).until(EC.presence_of_element_located((by, html)))
  File "C:\Users\USER\anaconda3\envs\aichi\lib\site-packages\selenium\webdriver\support\wait.py", line 96, in until
    value = method(self._driver)
  File "C:\Users\USER\anaconda3\envs\aichi\lib\site-packages\selenium\webdriver\support\expected_conditions.py", line 84, in _predicate
    return driver.find_element(*locator)
  File "C:\Users\USER\anaconda3\envs\aichi\lib\site-packages\seleniumbase\core\sb_driver.py", line 20, in find_element
    return self.driver.default_find_element(by=by, value=value)
  File "C:\Users\USER\anaconda3\envs\aichi\lib\site-packages\selenium\webdriver\remote\webdriver.py", line 741, in find_element
    return self.execute(Command.FIND_ELEMENT, {"using": by, "value": value})["value"]
  File "C:\Users\USER\anaconda3\envs\aichi\lib\site-packages\selenium\webdriver\remote\webdriver.py", line 347, in execute
    self.error_handler.check_response(response)
  File "C:\Users\USER\anaconda3\envs\aichi\lib\site-packages\selenium\webdriver\remote\errorhandler.py", line 229, in check_response
    raise exception_class(message, screen, stacktrace)
selenium.common.exceptions.NoSuchWindowException: Message: no such window: target window already closed
from unknown error: web view not found
  (Session info: chrome=124.0.6367.63)
Stacktrace:
	GetHandleVerifier [0x00007FF72E94F922+3045234]
	(No symbol) [0x00007FF72E5F3652]
	(No symbol) [0x00007FF72E4B7564]
	(No symbol) [0x00007FF72E48DB4F]
	(No symbol) [0x00007FF72E531087]
	(No symbol) [0x00007FF72E548871]
	(No symbol) [0x00007FF72E529B53]
	(No symbol) [0x00007FF72E4F813C]
	(No symbol) [0x00007FF72E4F8D71]
	GetHandleVerifier [0x00007FF72E97E89D+3237613]
	GetHandleVerifier [0x00007FF72E9C0BA7+3508727]
	GetHandleVerifier [0x00007FF72E9B976F+3478975]
	GetHandleVerifier [0x00007FF72E72F1C6+815126]
	(No symbol) [0x00007FF72E5FED0F]
	(No symbol) [0x00007FF72E5F9854]
	(No symbol) [0x00007FF72E5F99E2]
	(No symbol) [0x00007FF72E5EA574]
	BaseThreadInitThunk [0x00007FFFFB45257D+29]
	RtlUserThreadStart [0x00007FFFFCEEAA48+40]


During handling of the above exception, another exception occurred:

Traceback (most recent call last):
  File "C:\Users\USER\Projects\AichiTool\AichiSelenium\src\controllers\main_controller.py", line 58, in subprocess
    result = access.login(browser)
  File "C:\Users\USER\Projects\AichiTool\AichiSelenium\src\controllers\access.py", line 53, in login
    self.logger.error("Failed to login", e)
  File "C:\Users\USER\Projects\AichiTool\AichiSelenium\src\logs.py", line 73, in error
    self._log(logging.ERROR, *msg)
  File "C:\Users\USER\Projects\AichiTool\AichiSelenium\src\logs.py", line 90, in _log
    message = " ".join(msg)
TypeError: sequence item 1: expected str instance, NoSuchWindowException found
[ 2024-04-30 22:45:19,966 ] 79 main_controller - ERROR - Caught exception: sequence item 1: expected str instance, NoSuchWindowException found
Traceback (most recent call last):
  File "C:\Users\USER\Projects\AichiTool\AichiSelenium\src\controllers\access.py", line 29, in login
    wait_until_presence(browser, By.ID, "userLoginForm.userId")
  File "C:\Users\USER\Projects\AichiTool\AichiSelenium\src\utils\html_utils.py", line 8, in wait_until_presence
    WebDriverWait(browser, timeout).until(EC.presence_of_element_located((by, html)))
  File "C:\Users\USER\anaconda3\envs\aichi\lib\site-packages\selenium\webdriver\support\wait.py", line 105, in until
    raise TimeoutException(message, screen, stacktrace)
selenium.common.exceptions.TimeoutException: Message: 
Stacktrace:
	GetHandleVerifier [0x00007FF72E94F922+3045234]
	(No symbol) [0x00007FF72E5F3652]
	(No symbol) [0x00007FF72E4B7564]
	(No symbol) [0x00007FF72E505F9D]
	(No symbol) [0x00007FF72E50606C]
	(No symbol) [0x00007FF72E54BDD7]
	(No symbol) [0x00007FF72E529DEF]
	(No symbol) [0x00007FF72E5491C4]
	(No symbol) [0x00007FF72E529B53]
	(No symbol) [0x00007FF72E4F813C]
	(No symbol) [0x00007FF72E4F8D71]
	GetHandleVerifier [0x00007FF72E97E89D+3237613]
	GetHandleVerifier [0x00007FF72E9C0BA7+3508727]
	GetHandleVerifier [0x00007FF72E9B976F+3478975]
	GetHandleVerifier [0x00007FF72E72F1C6+815126]
	(No symbol) [0x00007FF72E5FED0F]
	(No symbol) [0x00007FF72E5F9854]
	(No symbol) [0x00007FF72E5F99E2]
	(No symbol) [0x00007FF72E5EA574]
	BaseThreadInitThunk [0x00007FFFFB45257D+29]
	RtlUserThreadStart [0x00007FFFFCEEAA48+40]


During handling of the above exception, another exception occurred:

Traceback (most recent call last):
  File "C:\Users\USER\Projects\AichiTool\AichiSelenium\src\controllers\main_controller.py", line 58, in subprocess
    result = access.login(browser)
  File "C:\Users\USER\Projects\AichiTool\AichiSelenium\src\controllers\access.py", line 53, in login
    self.logger.error("Failed to login", e)
  File "C:\Users\USER\Projects\AichiTool\AichiSelenium\src\logs.py", line 73, in error
    self._log(logging.ERROR, *msg)
  File "C:\Users\USER\Projects\AichiTool\AichiSelenium\src\logs.py", line 90, in _log
    message = " ".join(msg)
TypeError: sequence item 1: expected str instance, TimeoutException found

During handling of the above exception, another exception occurred:

Traceback (most recent call last):
  File "C:\Users\USER\Projects\AichiTool\AichiSelenium\src\controllers\access.py", line 29, in login
    wait_until_presence(browser, By.ID, "userLoginForm.userId")
  File "C:\Users\USER\Projects\AichiTool\AichiSelenium\src\utils\html_utils.py", line 8, in wait_until_presence
    WebDriverWait(browser, timeout).until(EC.presence_of_element_located((by, html)))
  File "C:\Users\USER\anaconda3\envs\aichi\lib\site-packages\selenium\webdriver\support\wait.py", line 96, in until
    value = method(self._driver)
  File "C:\Users\USER\anaconda3\envs\aichi\lib\site-packages\selenium\webdriver\support\expected_conditions.py", line 84, in _predicate
    return driver.find_element(*locator)
  File "C:\Users\USER\anaconda3\envs\aichi\lib\site-packages\seleniumbase\core\sb_driver.py", line 20, in find_element
    return self.driver.default_find_element(by=by, value=value)
  File "C:\Users\USER\anaconda3\envs\aichi\lib\site-packages\selenium\webdriver\remote\webdriver.py", line 741, in find_element
    return self.execute(Command.FIND_ELEMENT, {"using": by, "value": value})["value"]
  File "C:\Users\USER\anaconda3\envs\aichi\lib\site-packages\selenium\webdriver\remote\webdriver.py", line 347, in execute
    self.error_handler.check_response(response)
  File "C:\Users\USER\anaconda3\envs\aichi\lib\site-packages\selenium\webdriver\remote\errorhandler.py", line 229, in check_response
    raise exception_class(message, screen, stacktrace)
selenium.common.exceptions.NoSuchWindowException: Message: no such window: target window already closed
from unknown error: web view not found
  (Session info: chrome=124.0.6367.63)
Stacktrace:
	GetHandleVerifier [0x00007FF72E94F922+3045234]
	(No symbol) [0x00007FF72E5F3652]
	(No symbol) [0x00007FF72E4B7564]
	(No symbol) [0x00007FF72E48DB4F]
	(No symbol) [0x00007FF72E531087]
	(No symbol) [0x00007FF72E548871]
	(No symbol) [0x00007FF72E529B53]
	(No symbol) [0x00007FF72E4F813C]
	(No symbol) [0x00007FF72E4F8D71]
	GetHandleVerifier [0x00007FF72E97E89D+3237613]
	GetHandleVerifier [0x00007FF72E9C0BA7+3508727]
	GetHandleVerifier [0x00007FF72E9B976F+3478975]
	GetHandleVerifier [0x00007FF72E72F1C6+815126]
	(No symbol) [0x00007FF72E5FED0F]
	(No symbol) [0x00007FF72E5F9854]
	(No symbol) [0x00007FF72E5F99E2]
	(No symbol) [0x00007FF72E5EA574]
	BaseThreadInitThunk [0x00007FFFFB45257D+29]
	RtlUserThreadStart [0x00007FFFFCEEAA48+40]


During handling of the above exception, another exception occurred:

Traceback (most recent call last):
  File "C:\Users\USER\Projects\AichiTool\AichiSelenium\src\controllers\main_controller.py", line 58, in subprocess
    result = access.login(browser)
  File "C:\Users\USER\Projects\AichiTool\AichiSelenium\src\controllers\access.py", line 53, in login
    self.logger.error("Failed to login", e)
  File "C:\Users\USER\Projects\AichiTool\AichiSelenium\src\logs.py", line 73, in error
    self._log(logging.ERROR, *msg)
  File "C:\Users\USER\Projects\AichiTool\AichiSelenium\src\logs.py", line 90, in _log
    message = " ".join(msg)
TypeError: sequence item 1: expected str instance, NoSuchWindowException found
[ 2024-04-30 22:45:19,966 ] 79 main_controller - ERROR - Caught exception: sequence item 1: expected str instance, NoSuchWindowException found
Traceback (most recent call last):
  File "C:\Users\USER\Projects\AichiTool\AichiSelenium\src\controllers\access.py", line 29, in login
    wait_until_presence(browser, By.ID, "userLoginForm.userId")
  File "C:\Users\USER\Projects\AichiTool\AichiSelenium\src\utils\html_utils.py", line 8, in wait_until_presence
    WebDriverWait(browser, timeout).until(EC.presence_of_element_located((by, html)))
  File "C:\Users\USER\anaconda3\envs\aichi\lib\site-packages\selenium\webdriver\support\wait.py", line 105, in until
    raise TimeoutException(message, screen, stacktrace)
selenium.common.exceptions.TimeoutException: Message: 
Stacktrace:
	GetHandleVerifier [0x00007FF72E94F922+3045234]
	(No symbol) [0x00007FF72E5F3652]
	(No symbol) [0x00007FF72E4B7564]
	(No symbol) [0x00007FF72E505F9D]
	(No symbol) [0x00007FF72E50606C]
	(No symbol) [0x00007FF72E54BDD7]
	(No symbol) [0x00007FF72E529DEF]
	(No symbol) [0x00007FF72E5491C4]
	(No symbol) [0x00007FF72E529B53]
	(No symbol) [0x00007FF72E4F813C]
	(No symbol) [0x00007FF72E4F8D71]
	GetHandleVerifier [0x00007FF72E97E89D+3237613]
	GetHandleVerifier [0x00007FF72E9C0BA7+3508727]
	GetHandleVerifier [0x00007FF72E9B976F+3478975]
	GetHandleVerifier [0x00007FF72E72F1C6+815126]
	(No symbol) [0x00007FF72E5FED0F]
	(No symbol) [0x00007FF72E5F9854]
	(No symbol) [0x00007FF72E5F99E2]
	(No symbol) [0x00007FF72E5EA574]
	BaseThreadInitThunk [0x00007FFFFB45257D+29]
	RtlUserThreadStart [0x00007FFFFCEEAA48+40]


During handling of the above exception, another exception occurred:

Traceback (most recent call last):
  File "C:\Users\USER\Projects\AichiTool\AichiSelenium\src\controllers\main_controller.py", line 58, in subprocess
    result = access.login(browser)
  File "C:\Users\USER\Projects\AichiTool\AichiSelenium\src\controllers\access.py", line 53, in login
    self.logger.error("Failed to login", e)
  File "C:\Users\USER\Projects\AichiTool\AichiSelenium\src\logs.py", line 73, in error
    self._log(logging.ERROR, *msg)
  File "C:\Users\USER\Projects\AichiTool\AichiSelenium\src\logs.py", line 90, in _log
    message = " ".join(msg)
TypeError: sequence item 1: expected str instance, TimeoutException found

During handling of the above exception, another exception occurred:

Traceback (most recent call last):
  File "C:\Users\USER\Projects\AichiTool\AichiSelenium\src\controllers\access.py", line 29, in login
    wait_until_presence(browser, By.ID, "userLoginForm.userId")
  File "C:\Users\USER\Projects\AichiTool\AichiSelenium\src\utils\html_utils.py", line 8, in wait_until_presence
    WebDriverWait(browser, timeout).until(EC.presence_of_element_located((by, html)))
  File "C:\Users\USER\anaconda3\envs\aichi\lib\site-packages\selenium\webdriver\support\wait.py", line 96, in until
    value = method(self._driver)
  File "C:\Users\USER\anaconda3\envs\aichi\lib\site-packages\selenium\webdriver\support\expected_conditions.py", line 84, in _predicate
    return driver.find_element(*locator)
  File "C:\Users\USER\anaconda3\envs\aichi\lib\site-packages\seleniumbase\core\sb_driver.py", line 20, in find_element
    return self.driver.default_find_element(by=by, value=value)
  File "C:\Users\USER\anaconda3\envs\aichi\lib\site-packages\selenium\webdriver\remote\webdriver.py", line 741, in find_element
    return self.execute(Command.FIND_ELEMENT, {"using": by, "value": value})["value"]
  File "C:\Users\USER\anaconda3\envs\aichi\lib\site-packages\selenium\webdriver\remote\webdriver.py", line 347, in execute
    self.error_handler.check_response(response)
  File "C:\Users\USER\anaconda3\envs\aichi\lib\site-packages\selenium\webdriver\remote\errorhandler.py", line 229, in check_response
    raise exception_class(message, screen, stacktrace)
selenium.common.exceptions.NoSuchWindowException: Message: no such window: target window already closed
from unknown error: web view not found
  (Session info: chrome=124.0.6367.63)
Stacktrace:
	GetHandleVerifier [0x00007FF72E94F922+3045234]
	(No symbol) [0x00007FF72E5F3652]
	(No symbol) [0x00007FF72E4B7564]
	(No symbol) [0x00007FF72E48DB4F]
	(No symbol) [0x00007FF72E531087]
	(No symbol) [0x00007FF72E548871]
	(No symbol) [0x00007FF72E529B53]
	(No symbol) [0x00007FF72E4F813C]
	(No symbol) [0x00007FF72E4F8D71]
	GetHandleVerifier [0x00007FF72E97E89D+3237613]
	GetHandleVerifier [0x00007FF72E9C0BA7+3508727]
	GetHandleVerifier [0x00007FF72E9B976F+3478975]
	GetHandleVerifier [0x00007FF72E72F1C6+815126]
	(No symbol) [0x00007FF72E5FED0F]
	(No symbol) [0x00007FF72E5F9854]
	(No symbol) [0x00007FF72E5F99E2]
	(No symbol) [0x00007FF72E5EA574]
	BaseThreadInitThunk [0x00007FFFFB45257D+29]
	RtlUserThreadStart [0x00007FFFFCEEAA48+40]


During handling of the above exception, another exception occurred:

Traceback (most recent call last):
  File "C:\Users\USER\Projects\AichiTool\AichiSelenium\src\controllers\main_controller.py", line 58, in subprocess
    result = access.login(browser)
  File "C:\Users\USER\Projects\AichiTool\AichiSelenium\src\controllers\access.py", line 53, in login
    self.logger.error("Failed to login", e)
  File "C:\Users\USER\Projects\AichiTool\AichiSelenium\src\logs.py", line 73, in error
    self._log(logging.ERROR, *msg)
  File "C:\Users\USER\Projects\AichiTool\AichiSelenium\src\logs.py", line 90, in _log
    message = " ".join(msg)
TypeError: sequence item 1: expected str instance, NoSuchWindowException found
[ 2024-04-30 22:45:19,966 ] 79 main_controller - ERROR - Caught exception: sequence item 1: expected str instance, NoSuchWindowException found
Traceback (most recent call last):
  File "C:\Users\USER\Projects\AichiTool\AichiSelenium\src\controllers\access.py", line 29, in login
    wait_until_presence(browser, By.ID, "userLoginForm.userId")
  File "C:\Users\USER\Projects\AichiTool\AichiSelenium\src\utils\html_utils.py", line 8, in wait_until_presence
    WebDriverWait(browser, timeout).until(EC.presence_of_element_located((by, html)))
  File "C:\Users\USER\anaconda3\envs\aichi\lib\site-packages\selenium\webdriver\support\wait.py", line 105, in until
    raise TimeoutException(message, screen, stacktrace)
selenium.common.exceptions.TimeoutException: Message: 
Stacktrace:
	GetHandleVerifier [0x00007FF72E94F922+3045234]
	(No symbol) [0x00007FF72E5F3652]
	(No symbol) [0x00007FF72E4B7564]
	(No symbol) [0x00007FF72E505F9D]
	(No symbol) [0x00007FF72E50606C]
	(No symbol) [0x00007FF72E54BDD7]
	(No symbol) [0x00007FF72E529DEF]
	(No symbol) [0x00007FF72E5491C4]
	(No symbol) [0x00007FF72E529B53]
	(No symbol) [0x00007FF72E4F813C]
	(No symbol) [0x00007FF72E4F8D71]
	GetHandleVerifier [0x00007FF72E97E89D+3237613]
	GetHandleVerifier [0x00007FF72E9C0BA7+3508727]
	GetHandleVerifier [0x00007FF72E9B976F+3478975]
	GetHandleVerifier [0x00007FF72E72F1C6+815126]
	(No symbol) [0x00007FF72E5FED0F]
	(No symbol) [0x00007FF72E5F9854]
	(No symbol) [0x00007FF72E5F99E2]
	(No symbol) [0x00007FF72E5EA574]
	BaseThreadInitThunk [0x00007FFFFB45257D+29]
	RtlUserThreadStart [0x00007FFFFCEEAA48+40]


During handling of the above exception, another exception occurred:

Traceback (most recent call last):
  File "C:\Users\USER\Projects\AichiTool\AichiSelenium\src\controllers\main_controller.py", line 58, in subprocess
    result = access.login(browser)
  File "C:\Users\USER\Projects\AichiTool\AichiSelenium\src\controllers\access.py", line 53, in login
    self.logger.error("Failed to login", e)
  File "C:\Users\USER\Projects\AichiTool\AichiSelenium\src\logs.py", line 73, in error
    self._log(logging.ERROR, *msg)
  File "C:\Users\USER\Projects\AichiTool\AichiSelenium\src\logs.py", line 90, in _log
    message = " ".join(msg)
TypeError: sequence item 1: expected str instance, TimeoutException found

During handling of the above exception, another exception occurred:

Traceback (most recent call last):
  File "C:\Users\USER\Projects\AichiTool\AichiSelenium\src\controllers\access.py", line 29, in login
    wait_until_presence(browser, By.ID, "userLoginForm.userId")
  File "C:\Users\USER\Projects\AichiTool\AichiSelenium\src\utils\html_utils.py", line 8, in wait_until_presence
    WebDriverWait(browser, timeout).until(EC.presence_of_element_located((by, html)))
  File "C:\Users\USER\anaconda3\envs\aichi\lib\site-packages\selenium\webdriver\support\wait.py", line 96, in until
    value = method(self._driver)
  File "C:\Users\USER\anaconda3\envs\aichi\lib\site-packages\selenium\webdriver\support\expected_conditions.py", line 84, in _predicate
    return driver.find_element(*locator)
  File "C:\Users\USER\anaconda3\envs\aichi\lib\site-packages\seleniumbase\core\sb_driver.py", line 20, in find_element
    return self.driver.default_find_element(by=by, value=value)
  File "C:\Users\USER\anaconda3\envs\aichi\lib\site-packages\selenium\webdriver\remote\webdriver.py", line 741, in find_element
    return self.execute(Command.FIND_ELEMENT, {"using": by, "value": value})["value"]
  File "C:\Users\USER\anaconda3\envs\aichi\lib\site-packages\selenium\webdriver\remote\webdriver.py", line 347, in execute
    self.error_handler.check_response(response)
  File "C:\Users\USER\anaconda3\envs\aichi\lib\site-packages\selenium\webdriver\remote\errorhandler.py", line 229, in check_response
    raise exception_class(message, screen, stacktrace)
selenium.common.exceptions.NoSuchWindowException: Message: no such window: target window already closed
from unknown error: web view not found
  (Session info: chrome=124.0.6367.63)
Stacktrace:
	GetHandleVerifier [0x00007FF72E94F922+3045234]
	(No symbol) [0x00007FF72E5F3652]
	(No symbol) [0x00007FF72E4B7564]
	(No symbol) [0x00007FF72E48DB4F]
	(No symbol) [0x00007FF72E531087]
	(No symbol) [0x00007FF72E548871]
	(No symbol) [0x00007FF72E529B53]
	(No symbol) [0x00007FF72E4F813C]
	(No symbol) [0x00007FF72E4F8D71]
	GetHandleVerifier [0x00007FF72E97E89D+3237613]
	GetHandleVerifier [0x00007FF72E9C0BA7+3508727]
	GetHandleVerifier [0x00007FF72E9B976F+3478975]
	GetHandleVerifier [0x00007FF72E72F1C6+815126]
	(No symbol) [0x00007FF72E5FED0F]
	(No symbol) [0x00007FF72E5F9854]
	(No symbol) [0x00007FF72E5F99E2]
	(No symbol) [0x00007FF72E5EA574]
	BaseThreadInitThunk [0x00007FFFFB45257D+29]
	RtlUserThreadStart [0x00007FFFFCEEAA48+40]


During handling of the above exception, another exception occurred:

Traceback (most recent call last):
  File "C:\Users\USER\Projects\AichiTool\AichiSelenium\src\controllers\main_controller.py", line 58, in subprocess
    result = access.login(browser)
  File "C:\Users\USER\Projects\AichiTool\AichiSelenium\src\controllers\access.py", line 53, in login
    self.logger.error("Failed to login", e)
  File "C:\Users\USER\Projects\AichiTool\AichiSelenium\src\logs.py", line 73, in error
    self._log(logging.ERROR, *msg)
  File "C:\Users\USER\Projects\AichiTool\AichiSelenium\src\logs.py", line 90, in _log
    message = " ".join(msg)
TypeError: sequence item 1: expected str instance, NoSuchWindowException found
[ 2024-04-30 22:45:21,632 ] 79 main_controller - ERROR - Caught exception: sequence item 1: expected str instance, NoSuchWindowException found
Traceback (most recent call last):
  File "C:\Users\USER\Projects\AichiTool\AichiSelenium\src\controllers\access.py", line 29, in login
    wait_until_presence(browser, By.ID, "userLoginForm.userId")
  File "C:\Users\USER\Projects\AichiTool\AichiSelenium\src\utils\html_utils.py", line 8, in wait_until_presence
    WebDriverWait(browser, timeout).until(EC.presence_of_element_located((by, html)))
  File "C:\Users\USER\anaconda3\envs\aichi\lib\site-packages\selenium\webdriver\support\wait.py", line 105, in until
    raise TimeoutException(message, screen, stacktrace)
selenium.common.exceptions.TimeoutException: Message: 
Stacktrace:
	GetHandleVerifier [0x00007FF72E94F922+3045234]
	(No symbol) [0x00007FF72E5F3652]
	(No symbol) [0x00007FF72E4B7564]
	(No symbol) [0x00007FF72E505F9D]
	(No symbol) [0x00007FF72E50606C]
	(No symbol) [0x00007FF72E54BDD7]
	(No symbol) [0x00007FF72E529DEF]
	(No symbol) [0x00007FF72E5491C4]
	(No symbol) [0x00007FF72E529B53]
	(No symbol) [0x00007FF72E4F813C]
	(No symbol) [0x00007FF72E4F8D71]
	GetHandleVerifier [0x00007FF72E97E89D+3237613]
	GetHandleVerifier [0x00007FF72E9C0BA7+3508727]
	GetHandleVerifier [0x00007FF72E9B976F+3478975]
	GetHandleVerifier [0x00007FF72E72F1C6+815126]
	(No symbol) [0x00007FF72E5FED0F]
	(No symbol) [0x00007FF72E5F9854]
	(No symbol) [0x00007FF72E5F99E2]
	(No symbol) [0x00007FF72E5EA574]
	BaseThreadInitThunk [0x00007FFFFB45257D+29]
	RtlUserThreadStart [0x00007FFFFCEEAA48+40]


During handling of the above exception, another exception occurred:

Traceback (most recent call last):
  File "C:\Users\USER\Projects\AichiTool\AichiSelenium\src\controllers\main_controller.py", line 58, in subprocess
    result = access.login(browser)
  File "C:\Users\USER\Projects\AichiTool\AichiSelenium\src\controllers\access.py", line 53, in login
    self.logger.error("Failed to login", e)
  File "C:\Users\USER\Projects\AichiTool\AichiSelenium\src\logs.py", line 73, in error
    self._log(logging.ERROR, *msg)
  File "C:\Users\USER\Projects\AichiTool\AichiSelenium\src\logs.py", line 90, in _log
    message = " ".join(msg)
TypeError: sequence item 1: expected str instance, TimeoutException found

During handling of the above exception, another exception occurred:

Traceback (most recent call last):
  File "C:\Users\USER\Projects\AichiTool\AichiSelenium\src\controllers\access.py", line 29, in login
    wait_until_presence(browser, By.ID, "userLoginForm.userId")
  File "C:\Users\USER\Projects\AichiTool\AichiSelenium\src\utils\html_utils.py", line 8, in wait_until_presence
    WebDriverWait(browser, timeout).until(EC.presence_of_element_located((by, html)))
  File "C:\Users\USER\anaconda3\envs\aichi\lib\site-packages\selenium\webdriver\support\wait.py", line 96, in until
    value = method(self._driver)
  File "C:\Users\USER\anaconda3\envs\aichi\lib\site-packages\selenium\webdriver\support\expected_conditions.py", line 84, in _predicate
    return driver.find_element(*locator)
  File "C:\Users\USER\anaconda3\envs\aichi\lib\site-packages\seleniumbase\core\sb_driver.py", line 20, in find_element
    return self.driver.default_find_element(by=by, value=value)
  File "C:\Users\USER\anaconda3\envs\aichi\lib\site-packages\selenium\webdriver\remote\webdriver.py", line 741, in find_element
    return self.execute(Command.FIND_ELEMENT, {"using": by, "value": value})["value"]
  File "C:\Users\USER\anaconda3\envs\aichi\lib\site-packages\selenium\webdriver\remote\webdriver.py", line 347, in execute
    self.error_handler.check_response(response)
  File "C:\Users\USER\anaconda3\envs\aichi\lib\site-packages\selenium\webdriver\remote\errorhandler.py", line 229, in check_response
    raise exception_class(message, screen, stacktrace)
selenium.common.exceptions.NoSuchWindowException: Message: no such window: target window already closed
from unknown error: web view not found
  (Session info: chrome=124.0.6367.63)
Stacktrace:
	GetHandleVerifier [0x00007FF72E94F922+3045234]
	(No symbol) [0x00007FF72E5F3652]
	(No symbol) [0x00007FF72E4B7564]
	(No symbol) [0x00007FF72E48DB4F]
	(No symbol) [0x00007FF72E531087]
	(No symbol) [0x00007FF72E548871]
	(No symbol) [0x00007FF72E529B53]
	(No symbol) [0x00007FF72E4F813C]
	(No symbol) [0x00007FF72E4F8D71]
	GetHandleVerifier [0x00007FF72E97E89D+3237613]
	GetHandleVerifier [0x00007FF72E9C0BA7+3508727]
	GetHandleVerifier [0x00007FF72E9B976F+3478975]
	GetHandleVerifier [0x00007FF72E72F1C6+815126]
	(No symbol) [0x00007FF72E5FED0F]
	(No symbol) [0x00007FF72E5F9854]
	(No symbol) [0x00007FF72E5F99E2]
	(No symbol) [0x00007FF72E5EA574]
	BaseThreadInitThunk [0x00007FFFFB45257D+29]
	RtlUserThreadStart [0x00007FFFFCEEAA48+40]


During handling of the above exception, another exception occurred:

Traceback (most recent call last):
  File "C:\Users\USER\Projects\AichiTool\AichiSelenium\src\controllers\main_controller.py", line 58, in subprocess
    result = access.login(browser)
  File "C:\Users\USER\Projects\AichiTool\AichiSelenium\src\controllers\access.py", line 53, in login
    self.logger.error("Failed to login", e)
  File "C:\Users\USER\Projects\AichiTool\AichiSelenium\src\logs.py", line 73, in error
    self._log(logging.ERROR, *msg)
  File "C:\Users\USER\Projects\AichiTool\AichiSelenium\src\logs.py", line 90, in _log
    message = " ".join(msg)
TypeError: sequence item 1: expected str instance, NoSuchWindowException found
[ 2024-04-30 22:45:21,632 ] 79 main_controller - ERROR - Caught exception: sequence item 1: expected str instance, NoSuchWindowException found
Traceback (most recent call last):
  File "C:\Users\USER\Projects\AichiTool\AichiSelenium\src\controllers\access.py", line 29, in login
    wait_until_presence(browser, By.ID, "userLoginForm.userId")
  File "C:\Users\USER\Projects\AichiTool\AichiSelenium\src\utils\html_utils.py", line 8, in wait_until_presence
    WebDriverWait(browser, timeout).until(EC.presence_of_element_located((by, html)))
  File "C:\Users\USER\anaconda3\envs\aichi\lib\site-packages\selenium\webdriver\support\wait.py", line 105, in until
    raise TimeoutException(message, screen, stacktrace)
selenium.common.exceptions.TimeoutException: Message: 
Stacktrace:
	GetHandleVerifier [0x00007FF72E94F922+3045234]
	(No symbol) [0x00007FF72E5F3652]
	(No symbol) [0x00007FF72E4B7564]
	(No symbol) [0x00007FF72E505F9D]
	(No symbol) [0x00007FF72E50606C]
	(No symbol) [0x00007FF72E54BDD7]
	(No symbol) [0x00007FF72E529DEF]
	(No symbol) [0x00007FF72E5491C4]
	(No symbol) [0x00007FF72E529B53]
	(No symbol) [0x00007FF72E4F813C]
	(No symbol) [0x00007FF72E4F8D71]
	GetHandleVerifier [0x00007FF72E97E89D+3237613]
	GetHandleVerifier [0x00007FF72E9C0BA7+3508727]
	GetHandleVerifier [0x00007FF72E9B976F+3478975]
	GetHandleVerifier [0x00007FF72E72F1C6+815126]
	(No symbol) [0x00007FF72E5FED0F]
	(No symbol) [0x00007FF72E5F9854]
	(No symbol) [0x00007FF72E5F99E2]
	(No symbol) [0x00007FF72E5EA574]
	BaseThreadInitThunk [0x00007FFFFB45257D+29]
	RtlUserThreadStart [0x00007FFFFCEEAA48+40]


During handling of the above exception, another exception occurred:

Traceback (most recent call last):
  File "C:\Users\USER\Projects\AichiTool\AichiSelenium\src\controllers\main_controller.py", line 58, in subprocess
    result = access.login(browser)
  File "C:\Users\USER\Projects\AichiTool\AichiSelenium\src\controllers\access.py", line 53, in login
    self.logger.error("Failed to login", e)
  File "C:\Users\USER\Projects\AichiTool\AichiSelenium\src\logs.py", line 73, in error
    self._log(logging.ERROR, *msg)
  File "C:\Users\USER\Projects\AichiTool\AichiSelenium\src\logs.py", line 90, in _log
    message = " ".join(msg)
TypeError: sequence item 1: expected str instance, TimeoutException found

During handling of the above exception, another exception occurred:

Traceback (most recent call last):
  File "C:\Users\USER\Projects\AichiTool\AichiSelenium\src\controllers\access.py", line 29, in login
    wait_until_presence(browser, By.ID, "userLoginForm.userId")
  File "C:\Users\USER\Projects\AichiTool\AichiSelenium\src\utils\html_utils.py", line 8, in wait_until_presence
    WebDriverWait(browser, timeout).until(EC.presence_of_element_located((by, html)))
  File "C:\Users\USER\anaconda3\envs\aichi\lib\site-packages\selenium\webdriver\support\wait.py", line 96, in until
    value = method(self._driver)
  File "C:\Users\USER\anaconda3\envs\aichi\lib\site-packages\selenium\webdriver\support\expected_conditions.py", line 84, in _predicate
    return driver.find_element(*locator)
  File "C:\Users\USER\anaconda3\envs\aichi\lib\site-packages\seleniumbase\core\sb_driver.py", line 20, in find_element
    return self.driver.default_find_element(by=by, value=value)
  File "C:\Users\USER\anaconda3\envs\aichi\lib\site-packages\selenium\webdriver\remote\webdriver.py", line 741, in find_element
    return self.execute(Command.FIND_ELEMENT, {"using": by, "value": value})["value"]
  File "C:\Users\USER\anaconda3\envs\aichi\lib\site-packages\selenium\webdriver\remote\webdriver.py", line 347, in execute
    self.error_handler.check_response(response)
  File "C:\Users\USER\anaconda3\envs\aichi\lib\site-packages\selenium\webdriver\remote\errorhandler.py", line 229, in check_response
    raise exception_class(message, screen, stacktrace)
selenium.common.exceptions.NoSuchWindowException: Message: no such window: target window already closed
from unknown error: web view not found
  (Session info: chrome=124.0.6367.63)
Stacktrace:
	GetHandleVerifier [0x00007FF72E94F922+3045234]
	(No symbol) [0x00007FF72E5F3652]
	(No symbol) [0x00007FF72E4B7564]
	(No symbol) [0x00007FF72E48DB4F]
	(No symbol) [0x00007FF72E531087]
	(No symbol) [0x00007FF72E548871]
	(No symbol) [0x00007FF72E529B53]
	(No symbol) [0x00007FF72E4F813C]
	(No symbol) [0x00007FF72E4F8D71]
	GetHandleVerifier [0x00007FF72E97E89D+3237613]
	GetHandleVerifier [0x00007FF72E9C0BA7+3508727]
	GetHandleVerifier [0x00007FF72E9B976F+3478975]
	GetHandleVerifier [0x00007FF72E72F1C6+815126]
	(No symbol) [0x00007FF72E5FED0F]
	(No symbol) [0x00007FF72E5F9854]
	(No symbol) [0x00007FF72E5F99E2]
	(No symbol) [0x00007FF72E5EA574]
	BaseThreadInitThunk [0x00007FFFFB45257D+29]
	RtlUserThreadStart [0x00007FFFFCEEAA48+40]


During handling of the above exception, another exception occurred:

Traceback (most recent call last):
  File "C:\Users\USER\Projects\AichiTool\AichiSelenium\src\controllers\main_controller.py", line 58, in subprocess
    result = access.login(browser)
  File "C:\Users\USER\Projects\AichiTool\AichiSelenium\src\controllers\access.py", line 53, in login
    self.logger.error("Failed to login", e)
  File "C:\Users\USER\Projects\AichiTool\AichiSelenium\src\logs.py", line 73, in error
    self._log(logging.ERROR, *msg)
  File "C:\Users\USER\Projects\AichiTool\AichiSelenium\src\logs.py", line 90, in _log
    message = " ".join(msg)
TypeError: sequence item 1: expected str instance, NoSuchWindowException found
[ 2024-04-30 22:45:21,632 ] 79 main_controller - ERROR - Caught exception: sequence item 1: expected str instance, NoSuchWindowException found
Traceback (most recent call last):
  File "C:\Users\USER\Projects\AichiTool\AichiSelenium\src\controllers\access.py", line 29, in login
    wait_until_presence(browser, By.ID, "userLoginForm.userId")
  File "C:\Users\USER\Projects\AichiTool\AichiSelenium\src\utils\html_utils.py", line 8, in wait_until_presence
    WebDriverWait(browser, timeout).until(EC.presence_of_element_located((by, html)))
  File "C:\Users\USER\anaconda3\envs\aichi\lib\site-packages\selenium\webdriver\support\wait.py", line 105, in until
    raise TimeoutException(message, screen, stacktrace)
selenium.common.exceptions.TimeoutException: Message: 
Stacktrace:
	GetHandleVerifier [0x00007FF72E94F922+3045234]
	(No symbol) [0x00007FF72E5F3652]
	(No symbol) [0x00007FF72E4B7564]
	(No symbol) [0x00007FF72E505F9D]
	(No symbol) [0x00007FF72E50606C]
	(No symbol) [0x00007FF72E54BDD7]
	(No symbol) [0x00007FF72E529DEF]
	(No symbol) [0x00007FF72E5491C4]
	(No symbol) [0x00007FF72E529B53]
	(No symbol) [0x00007FF72E4F813C]
	(No symbol) [0x00007FF72E4F8D71]
	GetHandleVerifier [0x00007FF72E97E89D+3237613]
	GetHandleVerifier [0x00007FF72E9C0BA7+3508727]
	GetHandleVerifier [0x00007FF72E9B976F+3478975]
	GetHandleVerifier [0x00007FF72E72F1C6+815126]
	(No symbol) [0x00007FF72E5FED0F]
	(No symbol) [0x00007FF72E5F9854]
	(No symbol) [0x00007FF72E5F99E2]
	(No symbol) [0x00007FF72E5EA574]
	BaseThreadInitThunk [0x00007FFFFB45257D+29]
	RtlUserThreadStart [0x00007FFFFCEEAA48+40]


During handling of the above exception, another exception occurred:

Traceback (most recent call last):
  File "C:\Users\USER\Projects\AichiTool\AichiSelenium\src\controllers\main_controller.py", line 58, in subprocess
    result = access.login(browser)
  File "C:\Users\USER\Projects\AichiTool\AichiSelenium\src\controllers\access.py", line 53, in login
    self.logger.error("Failed to login", e)
  File "C:\Users\USER\Projects\AichiTool\AichiSelenium\src\logs.py", line 73, in error
    self._log(logging.ERROR, *msg)
  File "C:\Users\USER\Projects\AichiTool\AichiSelenium\src\logs.py", line 90, in _log
    message = " ".join(msg)
TypeError: sequence item 1: expected str instance, TimeoutException found

During handling of the above exception, another exception occurred:

Traceback (most recent call last):
  File "C:\Users\USER\Projects\AichiTool\AichiSelenium\src\controllers\access.py", line 29, in login
    wait_until_presence(browser, By.ID, "userLoginForm.userId")
  File "C:\Users\USER\Projects\AichiTool\AichiSelenium\src\utils\html_utils.py", line 8, in wait_until_presence
    WebDriverWait(browser, timeout).until(EC.presence_of_element_located((by, html)))
  File "C:\Users\USER\anaconda3\envs\aichi\lib\site-packages\selenium\webdriver\support\wait.py", line 96, in until
    value = method(self._driver)
  File "C:\Users\USER\anaconda3\envs\aichi\lib\site-packages\selenium\webdriver\support\expected_conditions.py", line 84, in _predicate
    return driver.find_element(*locator)
  File "C:\Users\USER\anaconda3\envs\aichi\lib\site-packages\seleniumbase\core\sb_driver.py", line 20, in find_element
    return self.driver.default_find_element(by=by, value=value)
  File "C:\Users\USER\anaconda3\envs\aichi\lib\site-packages\selenium\webdriver\remote\webdriver.py", line 741, in find_element
    return self.execute(Command.FIND_ELEMENT, {"using": by, "value": value})["value"]
  File "C:\Users\USER\anaconda3\envs\aichi\lib\site-packages\selenium\webdriver\remote\webdriver.py", line 347, in execute
    self.error_handler.check_response(response)
  File "C:\Users\USER\anaconda3\envs\aichi\lib\site-packages\selenium\webdriver\remote\errorhandler.py", line 229, in check_response
    raise exception_class(message, screen, stacktrace)
selenium.common.exceptions.NoSuchWindowException: Message: no such window: target window already closed
from unknown error: web view not found
  (Session info: chrome=124.0.6367.63)
Stacktrace:
	GetHandleVerifier [0x00007FF72E94F922+3045234]
	(No symbol) [0x00007FF72E5F3652]
	(No symbol) [0x00007FF72E4B7564]
	(No symbol) [0x00007FF72E48DB4F]
	(No symbol) [0x00007FF72E531087]
	(No symbol) [0x00007FF72E548871]
	(No symbol) [0x00007FF72E529B53]
	(No symbol) [0x00007FF72E4F813C]
	(No symbol) [0x00007FF72E4F8D71]
	GetHandleVerifier [0x00007FF72E97E89D+3237613]
	GetHandleVerifier [0x00007FF72E9C0BA7+3508727]
	GetHandleVerifier [0x00007FF72E9B976F+3478975]
	GetHandleVerifier [0x00007FF72E72F1C6+815126]
	(No symbol) [0x00007FF72E5FED0F]
	(No symbol) [0x00007FF72E5F9854]
	(No symbol) [0x00007FF72E5F99E2]
	(No symbol) [0x00007FF72E5EA574]
	BaseThreadInitThunk [0x00007FFFFB45257D+29]
	RtlUserThreadStart [0x00007FFFFCEEAA48+40]


During handling of the above exception, another exception occurred:

Traceback (most recent call last):
  File "C:\Users\USER\Projects\AichiTool\AichiSelenium\src\controllers\main_controller.py", line 58, in subprocess
    result = access.login(browser)
  File "C:\Users\USER\Projects\AichiTool\AichiSelenium\src\controllers\access.py", line 53, in login
    self.logger.error("Failed to login", e)
  File "C:\Users\USER\Projects\AichiTool\AichiSelenium\src\logs.py", line 73, in error
    self._log(logging.ERROR, *msg)
  File "C:\Users\USER\Projects\AichiTool\AichiSelenium\src\logs.py", line 90, in _log
    message = " ".join(msg)
TypeError: sequence item 1: expected str instance, NoSuchWindowException found
[ 2024-04-30 22:45:21,632 ] 79 main_controller - ERROR - Caught exception: sequence item 1: expected str instance, NoSuchWindowException found
Traceback (most recent call last):
  File "C:\Users\USER\Projects\AichiTool\AichiSelenium\src\controllers\access.py", line 29, in login
    wait_until_presence(browser, By.ID, "userLoginForm.userId")
  File "C:\Users\USER\Projects\AichiTool\AichiSelenium\src\utils\html_utils.py", line 8, in wait_until_presence
    WebDriverWait(browser, timeout).until(EC.presence_of_element_located((by, html)))
  File "C:\Users\USER\anaconda3\envs\aichi\lib\site-packages\selenium\webdriver\support\wait.py", line 105, in until
    raise TimeoutException(message, screen, stacktrace)
selenium.common.exceptions.TimeoutException: Message: 
Stacktrace:
	GetHandleVerifier [0x00007FF72E94F922+3045234]
	(No symbol) [0x00007FF72E5F3652]
	(No symbol) [0x00007FF72E4B7564]
	(No symbol) [0x00007FF72E505F9D]
	(No symbol) [0x00007FF72E50606C]
	(No symbol) [0x00007FF72E54BDD7]
	(No symbol) [0x00007FF72E529DEF]
	(No symbol) [0x00007FF72E5491C4]
	(No symbol) [0x00007FF72E529B53]
	(No symbol) [0x00007FF72E4F813C]
	(No symbol) [0x00007FF72E4F8D71]
	GetHandleVerifier [0x00007FF72E97E89D+3237613]
	GetHandleVerifier [0x00007FF72E9C0BA7+3508727]
	GetHandleVerifier [0x00007FF72E9B976F+3478975]
	GetHandleVerifier [0x00007FF72E72F1C6+815126]
	(No symbol) [0x00007FF72E5FED0F]
	(No symbol) [0x00007FF72E5F9854]
	(No symbol) [0x00007FF72E5F99E2]
	(No symbol) [0x00007FF72E5EA574]
	BaseThreadInitThunk [0x00007FFFFB45257D+29]
	RtlUserThreadStart [0x00007FFFFCEEAA48+40]


During handling of the above exception, another exception occurred:

Traceback (most recent call last):
  File "C:\Users\USER\Projects\AichiTool\AichiSelenium\src\controllers\main_controller.py", line 58, in subprocess
    result = access.login(browser)
  File "C:\Users\USER\Projects\AichiTool\AichiSelenium\src\controllers\access.py", line 53, in login
    self.logger.error("Failed to login", e)
  File "C:\Users\USER\Projects\AichiTool\AichiSelenium\src\logs.py", line 73, in error
    self._log(logging.ERROR, *msg)
  File "C:\Users\USER\Projects\AichiTool\AichiSelenium\src\logs.py", line 90, in _log
    message = " ".join(msg)
TypeError: sequence item 1: expected str instance, TimeoutException found

During handling of the above exception, another exception occurred:

Traceback (most recent call last):
  File "C:\Users\USER\Projects\AichiTool\AichiSelenium\src\controllers\access.py", line 29, in login
    wait_until_presence(browser, By.ID, "userLoginForm.userId")
  File "C:\Users\USER\Projects\AichiTool\AichiSelenium\src\utils\html_utils.py", line 8, in wait_until_presence
    WebDriverWait(browser, timeout).until(EC.presence_of_element_located((by, html)))
  File "C:\Users\USER\anaconda3\envs\aichi\lib\site-packages\selenium\webdriver\support\wait.py", line 96, in until
    value = method(self._driver)
  File "C:\Users\USER\anaconda3\envs\aichi\lib\site-packages\selenium\webdriver\support\expected_conditions.py", line 84, in _predicate
    return driver.find_element(*locator)
  File "C:\Users\USER\anaconda3\envs\aichi\lib\site-packages\seleniumbase\core\sb_driver.py", line 20, in find_element
    return self.driver.default_find_element(by=by, value=value)
  File "C:\Users\USER\anaconda3\envs\aichi\lib\site-packages\selenium\webdriver\remote\webdriver.py", line 741, in find_element
    return self.execute(Command.FIND_ELEMENT, {"using": by, "value": value})["value"]
  File "C:\Users\USER\anaconda3\envs\aichi\lib\site-packages\selenium\webdriver\remote\webdriver.py", line 347, in execute
    self.error_handler.check_response(response)
  File "C:\Users\USER\anaconda3\envs\aichi\lib\site-packages\selenium\webdriver\remote\errorhandler.py", line 229, in check_response
    raise exception_class(message, screen, stacktrace)
selenium.common.exceptions.NoSuchWindowException: Message: no such window: target window already closed
from unknown error: web view not found
  (Session info: chrome=124.0.6367.63)
Stacktrace:
	GetHandleVerifier [0x00007FF72E94F922+3045234]
	(No symbol) [0x00007FF72E5F3652]
	(No symbol) [0x00007FF72E4B7564]
	(No symbol) [0x00007FF72E48DB4F]
	(No symbol) [0x00007FF72E531087]
	(No symbol) [0x00007FF72E548871]
	(No symbol) [0x00007FF72E529B53]
	(No symbol) [0x00007FF72E4F813C]
	(No symbol) [0x00007FF72E4F8D71]
	GetHandleVerifier [0x00007FF72E97E89D+3237613]
	GetHandleVerifier [0x00007FF72E9C0BA7+3508727]
	GetHandleVerifier [0x00007FF72E9B976F+3478975]
	GetHandleVerifier [0x00007FF72E72F1C6+815126]
	(No symbol) [0x00007FF72E5FED0F]
	(No symbol) [0x00007FF72E5F9854]
	(No symbol) [0x00007FF72E5F99E2]
	(No symbol) [0x00007FF72E5EA574]
	BaseThreadInitThunk [0x00007FFFFB45257D+29]
	RtlUserThreadStart [0x00007FFFFCEEAA48+40]


During handling of the above exception, another exception occurred:

Traceback (most recent call last):
  File "C:\Users\USER\Projects\AichiTool\AichiSelenium\src\controllers\main_controller.py", line 58, in subprocess
    result = access.login(browser)
  File "C:\Users\USER\Projects\AichiTool\AichiSelenium\src\controllers\access.py", line 53, in login
    self.logger.error("Failed to login", e)
  File "C:\Users\USER\Projects\AichiTool\AichiSelenium\src\logs.py", line 73, in error
    self._log(logging.ERROR, *msg)
  File "C:\Users\USER\Projects\AichiTool\AichiSelenium\src\logs.py", line 90, in _log
    message = " ".join(msg)
TypeError: sequence item 1: expected str instance, NoSuchWindowException found
[ 2024-04-30 22:45:21,632 ] 79 main_controller - ERROR - Caught exception: sequence item 1: expected str instance, NoSuchWindowException found
Traceback (most recent call last):
  File "C:\Users\USER\Projects\AichiTool\AichiSelenium\src\controllers\access.py", line 29, in login
    wait_until_presence(browser, By.ID, "userLoginForm.userId")
  File "C:\Users\USER\Projects\AichiTool\AichiSelenium\src\utils\html_utils.py", line 8, in wait_until_presence
    WebDriverWait(browser, timeout).until(EC.presence_of_element_located((by, html)))
  File "C:\Users\USER\anaconda3\envs\aichi\lib\site-packages\selenium\webdriver\support\wait.py", line 105, in until
    raise TimeoutException(message, screen, stacktrace)
selenium.common.exceptions.TimeoutException: Message: 
Stacktrace:
	GetHandleVerifier [0x00007FF72E94F922+3045234]
	(No symbol) [0x00007FF72E5F3652]
	(No symbol) [0x00007FF72E4B7564]
	(No symbol) [0x00007FF72E505F9D]
	(No symbol) [0x00007FF72E50606C]
	(No symbol) [0x00007FF72E54BDD7]
	(No symbol) [0x00007FF72E529DEF]
	(No symbol) [0x00007FF72E5491C4]
	(No symbol) [0x00007FF72E529B53]
	(No symbol) [0x00007FF72E4F813C]
	(No symbol) [0x00007FF72E4F8D71]
	GetHandleVerifier [0x00007FF72E97E89D+3237613]
	GetHandleVerifier [0x00007FF72E9C0BA7+3508727]
	GetHandleVerifier [0x00007FF72E9B976F+3478975]
	GetHandleVerifier [0x00007FF72E72F1C6+815126]
	(No symbol) [0x00007FF72E5FED0F]
	(No symbol) [0x00007FF72E5F9854]
	(No symbol) [0x00007FF72E5F99E2]
	(No symbol) [0x00007FF72E5EA574]
	BaseThreadInitThunk [0x00007FFFFB45257D+29]
	RtlUserThreadStart [0x00007FFFFCEEAA48+40]


During handling of the above exception, another exception occurred:

Traceback (most recent call last):
  File "C:\Users\USER\Projects\AichiTool\AichiSelenium\src\controllers\main_controller.py", line 58, in subprocess
    result = access.login(browser)
  File "C:\Users\USER\Projects\AichiTool\AichiSelenium\src\controllers\access.py", line 53, in login
    self.logger.error("Failed to login", e)
  File "C:\Users\USER\Projects\AichiTool\AichiSelenium\src\logs.py", line 73, in error
    self._log(logging.ERROR, *msg)
  File "C:\Users\USER\Projects\AichiTool\AichiSelenium\src\logs.py", line 90, in _log
    message = " ".join(msg)
TypeError: sequence item 1: expected str instance, TimeoutException found

During handling of the above exception, another exception occurred:

Traceback (most recent call last):
  File "C:\Users\USER\Projects\AichiTool\AichiSelenium\src\controllers\access.py", line 29, in login
    wait_until_presence(browser, By.ID, "userLoginForm.userId")
  File "C:\Users\USER\Projects\AichiTool\AichiSelenium\src\utils\html_utils.py", line 8, in wait_until_presence
    WebDriverWait(browser, timeout).until(EC.presence_of_element_located((by, html)))
  File "C:\Users\USER\anaconda3\envs\aichi\lib\site-packages\selenium\webdriver\support\wait.py", line 96, in until
    value = method(self._driver)
  File "C:\Users\USER\anaconda3\envs\aichi\lib\site-packages\selenium\webdriver\support\expected_conditions.py", line 84, in _predicate
    return driver.find_element(*locator)
  File "C:\Users\USER\anaconda3\envs\aichi\lib\site-packages\seleniumbase\core\sb_driver.py", line 20, in find_element
    return self.driver.default_find_element(by=by, value=value)
  File "C:\Users\USER\anaconda3\envs\aichi\lib\site-packages\selenium\webdriver\remote\webdriver.py", line 741, in find_element
    return self.execute(Command.FIND_ELEMENT, {"using": by, "value": value})["value"]
  File "C:\Users\USER\anaconda3\envs\aichi\lib\site-packages\selenium\webdriver\remote\webdriver.py", line 347, in execute
    self.error_handler.check_response(response)
  File "C:\Users\USER\anaconda3\envs\aichi\lib\site-packages\selenium\webdriver\remote\errorhandler.py", line 229, in check_response
    raise exception_class(message, screen, stacktrace)
selenium.common.exceptions.NoSuchWindowException: Message: no such window: target window already closed
from unknown error: web view not found
  (Session info: chrome=124.0.6367.63)
Stacktrace:
	GetHandleVerifier [0x00007FF72E94F922+3045234]
	(No symbol) [0x00007FF72E5F3652]
	(No symbol) [0x00007FF72E4B7564]
	(No symbol) [0x00007FF72E48DB4F]
	(No symbol) [0x00007FF72E531087]
	(No symbol) [0x00007FF72E548871]
	(No symbol) [0x00007FF72E529B53]
	(No symbol) [0x00007FF72E4F813C]
	(No symbol) [0x00007FF72E4F8D71]
	GetHandleVerifier [0x00007FF72E97E89D+3237613]
	GetHandleVerifier [0x00007FF72E9C0BA7+3508727]
	GetHandleVerifier [0x00007FF72E9B976F+3478975]
	GetHandleVerifier [0x00007FF72E72F1C6+815126]
	(No symbol) [0x00007FF72E5FED0F]
	(No symbol) [0x00007FF72E5F9854]
	(No symbol) [0x00007FF72E5F99E2]
	(No symbol) [0x00007FF72E5EA574]
	BaseThreadInitThunk [0x00007FFFFB45257D+29]
	RtlUserThreadStart [0x00007FFFFCEEAA48+40]


During handling of the above exception, another exception occurred:

Traceback (most recent call last):
  File "C:\Users\USER\Projects\AichiTool\AichiSelenium\src\controllers\main_controller.py", line 58, in subprocess
    result = access.login(browser)
  File "C:\Users\USER\Projects\AichiTool\AichiSelenium\src\controllers\access.py", line 53, in login
    self.logger.error("Failed to login", e)
  File "C:\Users\USER\Projects\AichiTool\AichiSelenium\src\logs.py", line 73, in error
    self._log(logging.ERROR, *msg)
  File "C:\Users\USER\Projects\AichiTool\AichiSelenium\src\logs.py", line 90, in _log
    message = " ".join(msg)
TypeError: sequence item 1: expected str instance, NoSuchWindowException found
[ 2024-04-30 22:45:21,632 ] 79 main_controller - ERROR - Caught exception: sequence item 1: expected str instance, NoSuchWindowException found
Traceback (most recent call last):
  File "C:\Users\USER\Projects\AichiTool\AichiSelenium\src\controllers\access.py", line 29, in login
    wait_until_presence(browser, By.ID, "userLoginForm.userId")
  File "C:\Users\USER\Projects\AichiTool\AichiSelenium\src\utils\html_utils.py", line 8, in wait_until_presence
    WebDriverWait(browser, timeout).until(EC.presence_of_element_located((by, html)))
  File "C:\Users\USER\anaconda3\envs\aichi\lib\site-packages\selenium\webdriver\support\wait.py", line 105, in until
    raise TimeoutException(message, screen, stacktrace)
selenium.common.exceptions.TimeoutException: Message: 
Stacktrace:
	GetHandleVerifier [0x00007FF72E94F922+3045234]
	(No symbol) [0x00007FF72E5F3652]
	(No symbol) [0x00007FF72E4B7564]
	(No symbol) [0x00007FF72E505F9D]
	(No symbol) [0x00007FF72E50606C]
	(No symbol) [0x00007FF72E54BDD7]
	(No symbol) [0x00007FF72E529DEF]
	(No symbol) [0x00007FF72E5491C4]
	(No symbol) [0x00007FF72E529B53]
	(No symbol) [0x00007FF72E4F813C]
	(No symbol) [0x00007FF72E4F8D71]
	GetHandleVerifier [0x00007FF72E97E89D+3237613]
	GetHandleVerifier [0x00007FF72E9C0BA7+3508727]
	GetHandleVerifier [0x00007FF72E9B976F+3478975]
	GetHandleVerifier [0x00007FF72E72F1C6+815126]
	(No symbol) [0x00007FF72E5FED0F]
	(No symbol) [0x00007FF72E5F9854]
	(No symbol) [0x00007FF72E5F99E2]
	(No symbol) [0x00007FF72E5EA574]
	BaseThreadInitThunk [0x00007FFFFB45257D+29]
	RtlUserThreadStart [0x00007FFFFCEEAA48+40]


During handling of the above exception, another exception occurred:

Traceback (most recent call last):
  File "C:\Users\USER\Projects\AichiTool\AichiSelenium\src\controllers\main_controller.py", line 58, in subprocess
    result = access.login(browser)
  File "C:\Users\USER\Projects\AichiTool\AichiSelenium\src\controllers\access.py", line 53, in login
    self.logger.error("Failed to login", e)
  File "C:\Users\USER\Projects\AichiTool\AichiSelenium\src\logs.py", line 73, in error
    self._log(logging.ERROR, *msg)
  File "C:\Users\USER\Projects\AichiTool\AichiSelenium\src\logs.py", line 90, in _log
    message = " ".join(msg)
TypeError: sequence item 1: expected str instance, TimeoutException found

During handling of the above exception, another exception occurred:

Traceback (most recent call last):
  File "C:\Users\USER\Projects\AichiTool\AichiSelenium\src\controllers\access.py", line 29, in login
    wait_until_presence(browser, By.ID, "userLoginForm.userId")
  File "C:\Users\USER\Projects\AichiTool\AichiSelenium\src\utils\html_utils.py", line 8, in wait_until_presence
    WebDriverWait(browser, timeout).until(EC.presence_of_element_located((by, html)))
  File "C:\Users\USER\anaconda3\envs\aichi\lib\site-packages\selenium\webdriver\support\wait.py", line 96, in until
    value = method(self._driver)
  File "C:\Users\USER\anaconda3\envs\aichi\lib\site-packages\selenium\webdriver\support\expected_conditions.py", line 84, in _predicate
    return driver.find_element(*locator)
  File "C:\Users\USER\anaconda3\envs\aichi\lib\site-packages\seleniumbase\core\sb_driver.py", line 20, in find_element
    return self.driver.default_find_element(by=by, value=value)
  File "C:\Users\USER\anaconda3\envs\aichi\lib\site-packages\selenium\webdriver\remote\webdriver.py", line 741, in find_element
    return self.execute(Command.FIND_ELEMENT, {"using": by, "value": value})["value"]
  File "C:\Users\USER\anaconda3\envs\aichi\lib\site-packages\selenium\webdriver\remote\webdriver.py", line 347, in execute
    self.error_handler.check_response(response)
  File "C:\Users\USER\anaconda3\envs\aichi\lib\site-packages\selenium\webdriver\remote\errorhandler.py", line 229, in check_response
    raise exception_class(message, screen, stacktrace)
selenium.common.exceptions.NoSuchWindowException: Message: no such window: target window already closed
from unknown error: web view not found
  (Session info: chrome=124.0.6367.63)
Stacktrace:
	GetHandleVerifier [0x00007FF72E94F922+3045234]
	(No symbol) [0x00007FF72E5F3652]
	(No symbol) [0x00007FF72E4B7564]
	(No symbol) [0x00007FF72E48DB4F]
	(No symbol) [0x00007FF72E531087]
	(No symbol) [0x00007FF72E548871]
	(No symbol) [0x00007FF72E529B53]
	(No symbol) [0x00007FF72E4F813C]
	(No symbol) [0x00007FF72E4F8D71]
	GetHandleVerifier [0x00007FF72E97E89D+3237613]
	GetHandleVerifier [0x00007FF72E9C0BA7+3508727]
	GetHandleVerifier [0x00007FF72E9B976F+3478975]
	GetHandleVerifier [0x00007FF72E72F1C6+815126]
	(No symbol) [0x00007FF72E5FED0F]
	(No symbol) [0x00007FF72E5F9854]
	(No symbol) [0x00007FF72E5F99E2]
	(No symbol) [0x00007FF72E5EA574]
	BaseThreadInitThunk [0x00007FFFFB45257D+29]
	RtlUserThreadStart [0x00007FFFFCEEAA48+40]


During handling of the above exception, another exception occurred:

Traceback (most recent call last):
  File "C:\Users\USER\Projects\AichiTool\AichiSelenium\src\controllers\main_controller.py", line 58, in subprocess
    result = access.login(browser)
  File "C:\Users\USER\Projects\AichiTool\AichiSelenium\src\controllers\access.py", line 53, in login
    self.logger.error("Failed to login", e)
  File "C:\Users\USER\Projects\AichiTool\AichiSelenium\src\logs.py", line 73, in error
    self._log(logging.ERROR, *msg)
  File "C:\Users\USER\Projects\AichiTool\AichiSelenium\src\logs.py", line 90, in _log
    message = " ".join(msg)
TypeError: sequence item 1: expected str instance, NoSuchWindowException found
[ 2024-04-30 22:45:22,190 ] 91 main_controller - INFO - Subprocess 0 started with trial number 2
[ 2024-04-30 22:45:22,190 ] 91 main_controller - INFO - Subprocess 0 started with trial number 2
[ 2024-04-30 22:45:22,190 ] 91 main_controller - INFO - Subprocess 0 started with trial number 2
[ 2024-04-30 22:45:22,190 ] 91 main_controller - INFO - Subprocess 0 started with trial number 2
[ 2024-04-30 22:45:22,190 ] 91 main_controller - INFO - Subprocess 0 started with trial number 2
[ 2024-04-30 22:45:22,190 ] 91 main_controller - INFO - Subprocess 0 started with trial number 2
[ 2024-04-30 22:45:22,190 ] 91 main_controller - INFO - Subprocess 0 started with trial number 2
[ 2024-04-30 22:45:22,866 ] 79 main_controller - ERROR - Caught exception: sequence item 1: expected str instance, NoSuchWindowException found
Traceback (most recent call last):
  File "C:\Users\USER\Projects\AichiTool\AichiSelenium\src\controllers\access.py", line 29, in login
    wait_until_presence(browser, By.ID, "userLoginForm.userId")
  File "C:\Users\USER\Projects\AichiTool\AichiSelenium\src\utils\html_utils.py", line 8, in wait_until_presence
    WebDriverWait(browser, timeout).until(EC.presence_of_element_located((by, html)))
  File "C:\Users\USER\anaconda3\envs\aichi\lib\site-packages\selenium\webdriver\support\wait.py", line 105, in until
    raise TimeoutException(message, screen, stacktrace)
selenium.common.exceptions.TimeoutException: Message: 
Stacktrace:
	GetHandleVerifier [0x00007FF72E94F922+3045234]
	(No symbol) [0x00007FF72E5F3652]
	(No symbol) [0x00007FF72E4B7564]
	(No symbol) [0x00007FF72E505F9D]
	(No symbol) [0x00007FF72E50606C]
	(No symbol) [0x00007FF72E54BDD7]
	(No symbol) [0x00007FF72E529DEF]
	(No symbol) [0x00007FF72E5491C4]
	(No symbol) [0x00007FF72E529B53]
	(No symbol) [0x00007FF72E4F813C]
	(No symbol) [0x00007FF72E4F8D71]
	GetHandleVerifier [0x00007FF72E97E89D+3237613]
	GetHandleVerifier [0x00007FF72E9C0BA7+3508727]
	GetHandleVerifier [0x00007FF72E9B976F+3478975]
	GetHandleVerifier [0x00007FF72E72F1C6+815126]
	(No symbol) [0x00007FF72E5FED0F]
	(No symbol) [0x00007FF72E5F9854]
	(No symbol) [0x00007FF72E5F99E2]
	(No symbol) [0x00007FF72E5EA574]
	BaseThreadInitThunk [0x00007FFFFB45257D+29]
	RtlUserThreadStart [0x00007FFFFCEEAA48+40]


During handling of the above exception, another exception occurred:

Traceback (most recent call last):
  File "C:\Users\USER\Projects\AichiTool\AichiSelenium\src\controllers\main_controller.py", line 58, in subprocess
    result = access.login(browser)
  File "C:\Users\USER\Projects\AichiTool\AichiSelenium\src\controllers\access.py", line 53, in login
    self.logger.error("Failed to login", e)
  File "C:\Users\USER\Projects\AichiTool\AichiSelenium\src\logs.py", line 73, in error
    self._log(logging.ERROR, *msg)
  File "C:\Users\USER\Projects\AichiTool\AichiSelenium\src\logs.py", line 90, in _log
    message = " ".join(msg)
TypeError: sequence item 1: expected str instance, TimeoutException found

During handling of the above exception, another exception occurred:

Traceback (most recent call last):
  File "C:\Users\USER\Projects\AichiTool\AichiSelenium\src\controllers\access.py", line 29, in login
    wait_until_presence(browser, By.ID, "userLoginForm.userId")
  File "C:\Users\USER\Projects\AichiTool\AichiSelenium\src\utils\html_utils.py", line 8, in wait_until_presence
    WebDriverWait(browser, timeout).until(EC.presence_of_element_located((by, html)))
  File "C:\Users\USER\anaconda3\envs\aichi\lib\site-packages\selenium\webdriver\support\wait.py", line 96, in until
    value = method(self._driver)
  File "C:\Users\USER\anaconda3\envs\aichi\lib\site-packages\selenium\webdriver\support\expected_conditions.py", line 84, in _predicate
    return driver.find_element(*locator)
  File "C:\Users\USER\anaconda3\envs\aichi\lib\site-packages\seleniumbase\core\sb_driver.py", line 20, in find_element
    return self.driver.default_find_element(by=by, value=value)
  File "C:\Users\USER\anaconda3\envs\aichi\lib\site-packages\selenium\webdriver\remote\webdriver.py", line 741, in find_element
    return self.execute(Command.FIND_ELEMENT, {"using": by, "value": value})["value"]
  File "C:\Users\USER\anaconda3\envs\aichi\lib\site-packages\selenium\webdriver\remote\webdriver.py", line 347, in execute
    self.error_handler.check_response(response)
  File "C:\Users\USER\anaconda3\envs\aichi\lib\site-packages\selenium\webdriver\remote\errorhandler.py", line 229, in check_response
    raise exception_class(message, screen, stacktrace)
selenium.common.exceptions.NoSuchWindowException: Message: no such window: target window already closed
from unknown error: web view not found
  (Session info: chrome=124.0.6367.63)
Stacktrace:
	GetHandleVerifier [0x00007FF72E94F922+3045234]
	(No symbol) [0x00007FF72E5F3652]
	(No symbol) [0x00007FF72E4B7564]
	(No symbol) [0x00007FF72E48DB4F]
	(No symbol) [0x00007FF72E531087]
	(No symbol) [0x00007FF72E548871]
	(No symbol) [0x00007FF72E529B53]
	(No symbol) [0x00007FF72E4F813C]
	(No symbol) [0x00007FF72E4F8D71]
	GetHandleVerifier [0x00007FF72E97E89D+3237613]
	GetHandleVerifier [0x00007FF72E9C0BA7+3508727]
	GetHandleVerifier [0x00007FF72E9B976F+3478975]
	GetHandleVerifier [0x00007FF72E72F1C6+815126]
	(No symbol) [0x00007FF72E5FED0F]
	(No symbol) [0x00007FF72E5F9854]
	(No symbol) [0x00007FF72E5F99E2]
	(No symbol) [0x00007FF72E5EA574]
	BaseThreadInitThunk [0x00007FFFFB45257D+29]
	RtlUserThreadStart [0x00007FFFFCEEAA48+40]


During handling of the above exception, another exception occurred:

Traceback (most recent call last):
  File "C:\Users\USER\Projects\AichiTool\AichiSelenium\src\controllers\main_controller.py", line 58, in subprocess
    result = access.login(browser)
  File "C:\Users\USER\Projects\AichiTool\AichiSelenium\src\controllers\access.py", line 53, in login
    self.logger.error("Failed to login", e)
  File "C:\Users\USER\Projects\AichiTool\AichiSelenium\src\logs.py", line 73, in error
    self._log(logging.ERROR, *msg)
  File "C:\Users\USER\Projects\AichiTool\AichiSelenium\src\logs.py", line 90, in _log
    message = " ".join(msg)
TypeError: sequence item 1: expected str instance, NoSuchWindowException found
[ 2024-04-30 22:45:22,866 ] 79 main_controller - ERROR - Caught exception: sequence item 1: expected str instance, NoSuchWindowException found
Traceback (most recent call last):
  File "C:\Users\USER\Projects\AichiTool\AichiSelenium\src\controllers\access.py", line 29, in login
    wait_until_presence(browser, By.ID, "userLoginForm.userId")
  File "C:\Users\USER\Projects\AichiTool\AichiSelenium\src\utils\html_utils.py", line 8, in wait_until_presence
    WebDriverWait(browser, timeout).until(EC.presence_of_element_located((by, html)))
  File "C:\Users\USER\anaconda3\envs\aichi\lib\site-packages\selenium\webdriver\support\wait.py", line 105, in until
    raise TimeoutException(message, screen, stacktrace)
selenium.common.exceptions.TimeoutException: Message: 
Stacktrace:
	GetHandleVerifier [0x00007FF72E94F922+3045234]
	(No symbol) [0x00007FF72E5F3652]
	(No symbol) [0x00007FF72E4B7564]
	(No symbol) [0x00007FF72E505F9D]
	(No symbol) [0x00007FF72E50606C]
	(No symbol) [0x00007FF72E54BDD7]
	(No symbol) [0x00007FF72E529DEF]
	(No symbol) [0x00007FF72E5491C4]
	(No symbol) [0x00007FF72E529B53]
	(No symbol) [0x00007FF72E4F813C]
	(No symbol) [0x00007FF72E4F8D71]
	GetHandleVerifier [0x00007FF72E97E89D+3237613]
	GetHandleVerifier [0x00007FF72E9C0BA7+3508727]
	GetHandleVerifier [0x00007FF72E9B976F+3478975]
	GetHandleVerifier [0x00007FF72E72F1C6+815126]
	(No symbol) [0x00007FF72E5FED0F]
	(No symbol) [0x00007FF72E5F9854]
	(No symbol) [0x00007FF72E5F99E2]
	(No symbol) [0x00007FF72E5EA574]
	BaseThreadInitThunk [0x00007FFFFB45257D+29]
	RtlUserThreadStart [0x00007FFFFCEEAA48+40]


During handling of the above exception, another exception occurred:

Traceback (most recent call last):
  File "C:\Users\USER\Projects\AichiTool\AichiSelenium\src\controllers\main_controller.py", line 58, in subprocess
    result = access.login(browser)
  File "C:\Users\USER\Projects\AichiTool\AichiSelenium\src\controllers\access.py", line 53, in login
    self.logger.error("Failed to login", e)
  File "C:\Users\USER\Projects\AichiTool\AichiSelenium\src\logs.py", line 73, in error
    self._log(logging.ERROR, *msg)
  File "C:\Users\USER\Projects\AichiTool\AichiSelenium\src\logs.py", line 90, in _log
    message = " ".join(msg)
TypeError: sequence item 1: expected str instance, TimeoutException found

During handling of the above exception, another exception occurred:

Traceback (most recent call last):
  File "C:\Users\USER\Projects\AichiTool\AichiSelenium\src\controllers\access.py", line 29, in login
    wait_until_presence(browser, By.ID, "userLoginForm.userId")
  File "C:\Users\USER\Projects\AichiTool\AichiSelenium\src\utils\html_utils.py", line 8, in wait_until_presence
    WebDriverWait(browser, timeout).until(EC.presence_of_element_located((by, html)))
  File "C:\Users\USER\anaconda3\envs\aichi\lib\site-packages\selenium\webdriver\support\wait.py", line 96, in until
    value = method(self._driver)
  File "C:\Users\USER\anaconda3\envs\aichi\lib\site-packages\selenium\webdriver\support\expected_conditions.py", line 84, in _predicate
    return driver.find_element(*locator)
  File "C:\Users\USER\anaconda3\envs\aichi\lib\site-packages\seleniumbase\core\sb_driver.py", line 20, in find_element
    return self.driver.default_find_element(by=by, value=value)
  File "C:\Users\USER\anaconda3\envs\aichi\lib\site-packages\selenium\webdriver\remote\webdriver.py", line 741, in find_element
    return self.execute(Command.FIND_ELEMENT, {"using": by, "value": value})["value"]
  File "C:\Users\USER\anaconda3\envs\aichi\lib\site-packages\selenium\webdriver\remote\webdriver.py", line 347, in execute
    self.error_handler.check_response(response)
  File "C:\Users\USER\anaconda3\envs\aichi\lib\site-packages\selenium\webdriver\remote\errorhandler.py", line 229, in check_response
    raise exception_class(message, screen, stacktrace)
selenium.common.exceptions.NoSuchWindowException: Message: no such window: target window already closed
from unknown error: web view not found
  (Session info: chrome=124.0.6367.63)
Stacktrace:
	GetHandleVerifier [0x00007FF72E94F922+3045234]
	(No symbol) [0x00007FF72E5F3652]
	(No symbol) [0x00007FF72E4B7564]
	(No symbol) [0x00007FF72E48DB4F]
	(No symbol) [0x00007FF72E531087]
	(No symbol) [0x00007FF72E548871]
	(No symbol) [0x00007FF72E529B53]
	(No symbol) [0x00007FF72E4F813C]
	(No symbol) [0x00007FF72E4F8D71]
	GetHandleVerifier [0x00007FF72E97E89D+3237613]
	GetHandleVerifier [0x00007FF72E9C0BA7+3508727]
	GetHandleVerifier [0x00007FF72E9B976F+3478975]
	GetHandleVerifier [0x00007FF72E72F1C6+815126]
	(No symbol) [0x00007FF72E5FED0F]
	(No symbol) [0x00007FF72E5F9854]
	(No symbol) [0x00007FF72E5F99E2]
	(No symbol) [0x00007FF72E5EA574]
	BaseThreadInitThunk [0x00007FFFFB45257D+29]
	RtlUserThreadStart [0x00007FFFFCEEAA48+40]


During handling of the above exception, another exception occurred:

Traceback (most recent call last):
  File "C:\Users\USER\Projects\AichiTool\AichiSelenium\src\controllers\main_controller.py", line 58, in subprocess
    result = access.login(browser)
  File "C:\Users\USER\Projects\AichiTool\AichiSelenium\src\controllers\access.py", line 53, in login
    self.logger.error("Failed to login", e)
  File "C:\Users\USER\Projects\AichiTool\AichiSelenium\src\logs.py", line 73, in error
    self._log(logging.ERROR, *msg)
  File "C:\Users\USER\Projects\AichiTool\AichiSelenium\src\logs.py", line 90, in _log
    message = " ".join(msg)
TypeError: sequence item 1: expected str instance, NoSuchWindowException found
[ 2024-04-30 22:45:22,866 ] 79 main_controller - ERROR - Caught exception: sequence item 1: expected str instance, NoSuchWindowException found
Traceback (most recent call last):
  File "C:\Users\USER\Projects\AichiTool\AichiSelenium\src\controllers\access.py", line 29, in login
    wait_until_presence(browser, By.ID, "userLoginForm.userId")
  File "C:\Users\USER\Projects\AichiTool\AichiSelenium\src\utils\html_utils.py", line 8, in wait_until_presence
    WebDriverWait(browser, timeout).until(EC.presence_of_element_located((by, html)))
  File "C:\Users\USER\anaconda3\envs\aichi\lib\site-packages\selenium\webdriver\support\wait.py", line 105, in until
    raise TimeoutException(message, screen, stacktrace)
selenium.common.exceptions.TimeoutException: Message: 
Stacktrace:
	GetHandleVerifier [0x00007FF72E94F922+3045234]
	(No symbol) [0x00007FF72E5F3652]
	(No symbol) [0x00007FF72E4B7564]
	(No symbol) [0x00007FF72E505F9D]
	(No symbol) [0x00007FF72E50606C]
	(No symbol) [0x00007FF72E54BDD7]
	(No symbol) [0x00007FF72E529DEF]
	(No symbol) [0x00007FF72E5491C4]
	(No symbol) [0x00007FF72E529B53]
	(No symbol) [0x00007FF72E4F813C]
	(No symbol) [0x00007FF72E4F8D71]
	GetHandleVerifier [0x00007FF72E97E89D+3237613]
	GetHandleVerifier [0x00007FF72E9C0BA7+3508727]
	GetHandleVerifier [0x00007FF72E9B976F+3478975]
	GetHandleVerifier [0x00007FF72E72F1C6+815126]
	(No symbol) [0x00007FF72E5FED0F]
	(No symbol) [0x00007FF72E5F9854]
	(No symbol) [0x00007FF72E5F99E2]
	(No symbol) [0x00007FF72E5EA574]
	BaseThreadInitThunk [0x00007FFFFB45257D+29]
	RtlUserThreadStart [0x00007FFFFCEEAA48+40]


During handling of the above exception, another exception occurred:

Traceback (most recent call last):
  File "C:\Users\USER\Projects\AichiTool\AichiSelenium\src\controllers\main_controller.py", line 58, in subprocess
    result = access.login(browser)
  File "C:\Users\USER\Projects\AichiTool\AichiSelenium\src\controllers\access.py", line 53, in login
    self.logger.error("Failed to login", e)
  File "C:\Users\USER\Projects\AichiTool\AichiSelenium\src\logs.py", line 73, in error
    self._log(logging.ERROR, *msg)
  File "C:\Users\USER\Projects\AichiTool\AichiSelenium\src\logs.py", line 90, in _log
    message = " ".join(msg)
TypeError: sequence item 1: expected str instance, TimeoutException found

During handling of the above exception, another exception occurred:

Traceback (most recent call last):
  File "C:\Users\USER\Projects\AichiTool\AichiSelenium\src\controllers\access.py", line 29, in login
    wait_until_presence(browser, By.ID, "userLoginForm.userId")
  File "C:\Users\USER\Projects\AichiTool\AichiSelenium\src\utils\html_utils.py", line 8, in wait_until_presence
    WebDriverWait(browser, timeout).until(EC.presence_of_element_located((by, html)))
  File "C:\Users\USER\anaconda3\envs\aichi\lib\site-packages\selenium\webdriver\support\wait.py", line 96, in until
    value = method(self._driver)
  File "C:\Users\USER\anaconda3\envs\aichi\lib\site-packages\selenium\webdriver\support\expected_conditions.py", line 84, in _predicate
    return driver.find_element(*locator)
  File "C:\Users\USER\anaconda3\envs\aichi\lib\site-packages\seleniumbase\core\sb_driver.py", line 20, in find_element
    return self.driver.default_find_element(by=by, value=value)
  File "C:\Users\USER\anaconda3\envs\aichi\lib\site-packages\selenium\webdriver\remote\webdriver.py", line 741, in find_element
    return self.execute(Command.FIND_ELEMENT, {"using": by, "value": value})["value"]
  File "C:\Users\USER\anaconda3\envs\aichi\lib\site-packages\selenium\webdriver\remote\webdriver.py", line 347, in execute
    self.error_handler.check_response(response)
  File "C:\Users\USER\anaconda3\envs\aichi\lib\site-packages\selenium\webdriver\remote\errorhandler.py", line 229, in check_response
    raise exception_class(message, screen, stacktrace)
selenium.common.exceptions.NoSuchWindowException: Message: no such window: target window already closed
from unknown error: web view not found
  (Session info: chrome=124.0.6367.63)
Stacktrace:
	GetHandleVerifier [0x00007FF72E94F922+3045234]
	(No symbol) [0x00007FF72E5F3652]
	(No symbol) [0x00007FF72E4B7564]
	(No symbol) [0x00007FF72E48DB4F]
	(No symbol) [0x00007FF72E531087]
	(No symbol) [0x00007FF72E548871]
	(No symbol) [0x00007FF72E529B53]
	(No symbol) [0x00007FF72E4F813C]
	(No symbol) [0x00007FF72E4F8D71]
	GetHandleVerifier [0x00007FF72E97E89D+3237613]
	GetHandleVerifier [0x00007FF72E9C0BA7+3508727]
	GetHandleVerifier [0x00007FF72E9B976F+3478975]
	GetHandleVerifier [0x00007FF72E72F1C6+815126]
	(No symbol) [0x00007FF72E5FED0F]
	(No symbol) [0x00007FF72E5F9854]
	(No symbol) [0x00007FF72E5F99E2]
	(No symbol) [0x00007FF72E5EA574]
	BaseThreadInitThunk [0x00007FFFFB45257D+29]
	RtlUserThreadStart [0x00007FFFFCEEAA48+40]


During handling of the above exception, another exception occurred:

Traceback (most recent call last):
  File "C:\Users\USER\Projects\AichiTool\AichiSelenium\src\controllers\main_controller.py", line 58, in subprocess
    result = access.login(browser)
  File "C:\Users\USER\Projects\AichiTool\AichiSelenium\src\controllers\access.py", line 53, in login
    self.logger.error("Failed to login", e)
  File "C:\Users\USER\Projects\AichiTool\AichiSelenium\src\logs.py", line 73, in error
    self._log(logging.ERROR, *msg)
  File "C:\Users\USER\Projects\AichiTool\AichiSelenium\src\logs.py", line 90, in _log
    message = " ".join(msg)
TypeError: sequence item 1: expected str instance, NoSuchWindowException found
[ 2024-04-30 22:45:22,866 ] 79 main_controller - ERROR - Caught exception: sequence item 1: expected str instance, NoSuchWindowException found
Traceback (most recent call last):
  File "C:\Users\USER\Projects\AichiTool\AichiSelenium\src\controllers\access.py", line 29, in login
    wait_until_presence(browser, By.ID, "userLoginForm.userId")
  File "C:\Users\USER\Projects\AichiTool\AichiSelenium\src\utils\html_utils.py", line 8, in wait_until_presence
    WebDriverWait(browser, timeout).until(EC.presence_of_element_located((by, html)))
  File "C:\Users\USER\anaconda3\envs\aichi\lib\site-packages\selenium\webdriver\support\wait.py", line 105, in until
    raise TimeoutException(message, screen, stacktrace)
selenium.common.exceptions.TimeoutException: Message: 
Stacktrace:
	GetHandleVerifier [0x00007FF72E94F922+3045234]
	(No symbol) [0x00007FF72E5F3652]
	(No symbol) [0x00007FF72E4B7564]
	(No symbol) [0x00007FF72E505F9D]
	(No symbol) [0x00007FF72E50606C]
	(No symbol) [0x00007FF72E54BDD7]
	(No symbol) [0x00007FF72E529DEF]
	(No symbol) [0x00007FF72E5491C4]
	(No symbol) [0x00007FF72E529B53]
	(No symbol) [0x00007FF72E4F813C]
	(No symbol) [0x00007FF72E4F8D71]
	GetHandleVerifier [0x00007FF72E97E89D+3237613]
	GetHandleVerifier [0x00007FF72E9C0BA7+3508727]
	GetHandleVerifier [0x00007FF72E9B976F+3478975]
	GetHandleVerifier [0x00007FF72E72F1C6+815126]
	(No symbol) [0x00007FF72E5FED0F]
	(No symbol) [0x00007FF72E5F9854]
	(No symbol) [0x00007FF72E5F99E2]
	(No symbol) [0x00007FF72E5EA574]
	BaseThreadInitThunk [0x00007FFFFB45257D+29]
	RtlUserThreadStart [0x00007FFFFCEEAA48+40]


During handling of the above exception, another exception occurred:

Traceback (most recent call last):
  File "C:\Users\USER\Projects\AichiTool\AichiSelenium\src\controllers\main_controller.py", line 58, in subprocess
    result = access.login(browser)
  File "C:\Users\USER\Projects\AichiTool\AichiSelenium\src\controllers\access.py", line 53, in login
    self.logger.error("Failed to login", e)
  File "C:\Users\USER\Projects\AichiTool\AichiSelenium\src\logs.py", line 73, in error
    self._log(logging.ERROR, *msg)
  File "C:\Users\USER\Projects\AichiTool\AichiSelenium\src\logs.py", line 90, in _log
    message = " ".join(msg)
TypeError: sequence item 1: expected str instance, TimeoutException found

During handling of the above exception, another exception occurred:

Traceback (most recent call last):
  File "C:\Users\USER\Projects\AichiTool\AichiSelenium\src\controllers\access.py", line 29, in login
    wait_until_presence(browser, By.ID, "userLoginForm.userId")
  File "C:\Users\USER\Projects\AichiTool\AichiSelenium\src\utils\html_utils.py", line 8, in wait_until_presence
    WebDriverWait(browser, timeout).until(EC.presence_of_element_located((by, html)))
  File "C:\Users\USER\anaconda3\envs\aichi\lib\site-packages\selenium\webdriver\support\wait.py", line 96, in until
    value = method(self._driver)
  File "C:\Users\USER\anaconda3\envs\aichi\lib\site-packages\selenium\webdriver\support\expected_conditions.py", line 84, in _predicate
    return driver.find_element(*locator)
  File "C:\Users\USER\anaconda3\envs\aichi\lib\site-packages\seleniumbase\core\sb_driver.py", line 20, in find_element
    return self.driver.default_find_element(by=by, value=value)
  File "C:\Users\USER\anaconda3\envs\aichi\lib\site-packages\selenium\webdriver\remote\webdriver.py", line 741, in find_element
    return self.execute(Command.FIND_ELEMENT, {"using": by, "value": value})["value"]
  File "C:\Users\USER\anaconda3\envs\aichi\lib\site-packages\selenium\webdriver\remote\webdriver.py", line 347, in execute
    self.error_handler.check_response(response)
  File "C:\Users\USER\anaconda3\envs\aichi\lib\site-packages\selenium\webdriver\remote\errorhandler.py", line 229, in check_response
    raise exception_class(message, screen, stacktrace)
selenium.common.exceptions.NoSuchWindowException: Message: no such window: target window already closed
from unknown error: web view not found
  (Session info: chrome=124.0.6367.63)
Stacktrace:
	GetHandleVerifier [0x00007FF72E94F922+3045234]
	(No symbol) [0x00007FF72E5F3652]
	(No symbol) [0x00007FF72E4B7564]
	(No symbol) [0x00007FF72E48DB4F]
	(No symbol) [0x00007FF72E531087]
	(No symbol) [0x00007FF72E548871]
	(No symbol) [0x00007FF72E529B53]
	(No symbol) [0x00007FF72E4F813C]
	(No symbol) [0x00007FF72E4F8D71]
	GetHandleVerifier [0x00007FF72E97E89D+3237613]
	GetHandleVerifier [0x00007FF72E9C0BA7+3508727]
	GetHandleVerifier [0x00007FF72E9B976F+3478975]
	GetHandleVerifier [0x00007FF72E72F1C6+815126]
	(No symbol) [0x00007FF72E5FED0F]
	(No symbol) [0x00007FF72E5F9854]
	(No symbol) [0x00007FF72E5F99E2]
	(No symbol) [0x00007FF72E5EA574]
	BaseThreadInitThunk [0x00007FFFFB45257D+29]
	RtlUserThreadStart [0x00007FFFFCEEAA48+40]


During handling of the above exception, another exception occurred:

Traceback (most recent call last):
  File "C:\Users\USER\Projects\AichiTool\AichiSelenium\src\controllers\main_controller.py", line 58, in subprocess
    result = access.login(browser)
  File "C:\Users\USER\Projects\AichiTool\AichiSelenium\src\controllers\access.py", line 53, in login
    self.logger.error("Failed to login", e)
  File "C:\Users\USER\Projects\AichiTool\AichiSelenium\src\logs.py", line 73, in error
    self._log(logging.ERROR, *msg)
  File "C:\Users\USER\Projects\AichiTool\AichiSelenium\src\logs.py", line 90, in _log
    message = " ".join(msg)
TypeError: sequence item 1: expected str instance, NoSuchWindowException found
[ 2024-04-30 22:45:22,866 ] 79 main_controller - ERROR - Caught exception: sequence item 1: expected str instance, NoSuchWindowException found
Traceback (most recent call last):
  File "C:\Users\USER\Projects\AichiTool\AichiSelenium\src\controllers\access.py", line 29, in login
    wait_until_presence(browser, By.ID, "userLoginForm.userId")
  File "C:\Users\USER\Projects\AichiTool\AichiSelenium\src\utils\html_utils.py", line 8, in wait_until_presence
    WebDriverWait(browser, timeout).until(EC.presence_of_element_located((by, html)))
  File "C:\Users\USER\anaconda3\envs\aichi\lib\site-packages\selenium\webdriver\support\wait.py", line 105, in until
    raise TimeoutException(message, screen, stacktrace)
selenium.common.exceptions.TimeoutException: Message: 
Stacktrace:
	GetHandleVerifier [0x00007FF72E94F922+3045234]
	(No symbol) [0x00007FF72E5F3652]
	(No symbol) [0x00007FF72E4B7564]
	(No symbol) [0x00007FF72E505F9D]
	(No symbol) [0x00007FF72E50606C]
	(No symbol) [0x00007FF72E54BDD7]
	(No symbol) [0x00007FF72E529DEF]
	(No symbol) [0x00007FF72E5491C4]
	(No symbol) [0x00007FF72E529B53]
	(No symbol) [0x00007FF72E4F813C]
	(No symbol) [0x00007FF72E4F8D71]
	GetHandleVerifier [0x00007FF72E97E89D+3237613]
	GetHandleVerifier [0x00007FF72E9C0BA7+3508727]
	GetHandleVerifier [0x00007FF72E9B976F+3478975]
	GetHandleVerifier [0x00007FF72E72F1C6+815126]
	(No symbol) [0x00007FF72E5FED0F]
	(No symbol) [0x00007FF72E5F9854]
	(No symbol) [0x00007FF72E5F99E2]
	(No symbol) [0x00007FF72E5EA574]
	BaseThreadInitThunk [0x00007FFFFB45257D+29]
	RtlUserThreadStart [0x00007FFFFCEEAA48+40]


During handling of the above exception, another exception occurred:

Traceback (most recent call last):
  File "C:\Users\USER\Projects\AichiTool\AichiSelenium\src\controllers\main_controller.py", line 58, in subprocess
    result = access.login(browser)
  File "C:\Users\USER\Projects\AichiTool\AichiSelenium\src\controllers\access.py", line 53, in login
    self.logger.error("Failed to login", e)
  File "C:\Users\USER\Projects\AichiTool\AichiSelenium\src\logs.py", line 73, in error
    self._log(logging.ERROR, *msg)
  File "C:\Users\USER\Projects\AichiTool\AichiSelenium\src\logs.py", line 90, in _log
    message = " ".join(msg)
TypeError: sequence item 1: expected str instance, TimeoutException found

During handling of the above exception, another exception occurred:

Traceback (most recent call last):
  File "C:\Users\USER\Projects\AichiTool\AichiSelenium\src\controllers\access.py", line 29, in login
    wait_until_presence(browser, By.ID, "userLoginForm.userId")
  File "C:\Users\USER\Projects\AichiTool\AichiSelenium\src\utils\html_utils.py", line 8, in wait_until_presence
    WebDriverWait(browser, timeout).until(EC.presence_of_element_located((by, html)))
  File "C:\Users\USER\anaconda3\envs\aichi\lib\site-packages\selenium\webdriver\support\wait.py", line 96, in until
    value = method(self._driver)
  File "C:\Users\USER\anaconda3\envs\aichi\lib\site-packages\selenium\webdriver\support\expected_conditions.py", line 84, in _predicate
    return driver.find_element(*locator)
  File "C:\Users\USER\anaconda3\envs\aichi\lib\site-packages\seleniumbase\core\sb_driver.py", line 20, in find_element
    return self.driver.default_find_element(by=by, value=value)
  File "C:\Users\USER\anaconda3\envs\aichi\lib\site-packages\selenium\webdriver\remote\webdriver.py", line 741, in find_element
    return self.execute(Command.FIND_ELEMENT, {"using": by, "value": value})["value"]
  File "C:\Users\USER\anaconda3\envs\aichi\lib\site-packages\selenium\webdriver\remote\webdriver.py", line 347, in execute
    self.error_handler.check_response(response)
  File "C:\Users\USER\anaconda3\envs\aichi\lib\site-packages\selenium\webdriver\remote\errorhandler.py", line 229, in check_response
    raise exception_class(message, screen, stacktrace)
selenium.common.exceptions.NoSuchWindowException: Message: no such window: target window already closed
from unknown error: web view not found
  (Session info: chrome=124.0.6367.63)
Stacktrace:
	GetHandleVerifier [0x00007FF72E94F922+3045234]
	(No symbol) [0x00007FF72E5F3652]
	(No symbol) [0x00007FF72E4B7564]
	(No symbol) [0x00007FF72E48DB4F]
	(No symbol) [0x00007FF72E531087]
	(No symbol) [0x00007FF72E548871]
	(No symbol) [0x00007FF72E529B53]
	(No symbol) [0x00007FF72E4F813C]
	(No symbol) [0x00007FF72E4F8D71]
	GetHandleVerifier [0x00007FF72E97E89D+3237613]
	GetHandleVerifier [0x00007FF72E9C0BA7+3508727]
	GetHandleVerifier [0x00007FF72E9B976F+3478975]
	GetHandleVerifier [0x00007FF72E72F1C6+815126]
	(No symbol) [0x00007FF72E5FED0F]
	(No symbol) [0x00007FF72E5F9854]
	(No symbol) [0x00007FF72E5F99E2]
	(No symbol) [0x00007FF72E5EA574]
	BaseThreadInitThunk [0x00007FFFFB45257D+29]
	RtlUserThreadStart [0x00007FFFFCEEAA48+40]


During handling of the above exception, another exception occurred:

Traceback (most recent call last):
  File "C:\Users\USER\Projects\AichiTool\AichiSelenium\src\controllers\main_controller.py", line 58, in subprocess
    result = access.login(browser)
  File "C:\Users\USER\Projects\AichiTool\AichiSelenium\src\controllers\access.py", line 53, in login
    self.logger.error("Failed to login", e)
  File "C:\Users\USER\Projects\AichiTool\AichiSelenium\src\logs.py", line 73, in error
    self._log(logging.ERROR, *msg)
  File "C:\Users\USER\Projects\AichiTool\AichiSelenium\src\logs.py", line 90, in _log
    message = " ".join(msg)
TypeError: sequence item 1: expected str instance, NoSuchWindowException found
[ 2024-04-30 22:45:22,866 ] 79 main_controller - ERROR - Caught exception: sequence item 1: expected str instance, NoSuchWindowException found
Traceback (most recent call last):
  File "C:\Users\USER\Projects\AichiTool\AichiSelenium\src\controllers\access.py", line 29, in login
    wait_until_presence(browser, By.ID, "userLoginForm.userId")
  File "C:\Users\USER\Projects\AichiTool\AichiSelenium\src\utils\html_utils.py", line 8, in wait_until_presence
    WebDriverWait(browser, timeout).until(EC.presence_of_element_located((by, html)))
  File "C:\Users\USER\anaconda3\envs\aichi\lib\site-packages\selenium\webdriver\support\wait.py", line 105, in until
    raise TimeoutException(message, screen, stacktrace)
selenium.common.exceptions.TimeoutException: Message: 
Stacktrace:
	GetHandleVerifier [0x00007FF72E94F922+3045234]
	(No symbol) [0x00007FF72E5F3652]
	(No symbol) [0x00007FF72E4B7564]
	(No symbol) [0x00007FF72E505F9D]
	(No symbol) [0x00007FF72E50606C]
	(No symbol) [0x00007FF72E54BDD7]
	(No symbol) [0x00007FF72E529DEF]
	(No symbol) [0x00007FF72E5491C4]
	(No symbol) [0x00007FF72E529B53]
	(No symbol) [0x00007FF72E4F813C]
	(No symbol) [0x00007FF72E4F8D71]
	GetHandleVerifier [0x00007FF72E97E89D+3237613]
	GetHandleVerifier [0x00007FF72E9C0BA7+3508727]
	GetHandleVerifier [0x00007FF72E9B976F+3478975]
	GetHandleVerifier [0x00007FF72E72F1C6+815126]
	(No symbol) [0x00007FF72E5FED0F]
	(No symbol) [0x00007FF72E5F9854]
	(No symbol) [0x00007FF72E5F99E2]
	(No symbol) [0x00007FF72E5EA574]
	BaseThreadInitThunk [0x00007FFFFB45257D+29]
	RtlUserThreadStart [0x00007FFFFCEEAA48+40]


During handling of the above exception, another exception occurred:

Traceback (most recent call last):
  File "C:\Users\USER\Projects\AichiTool\AichiSelenium\src\controllers\main_controller.py", line 58, in subprocess
    result = access.login(browser)
  File "C:\Users\USER\Projects\AichiTool\AichiSelenium\src\controllers\access.py", line 53, in login
    self.logger.error("Failed to login", e)
  File "C:\Users\USER\Projects\AichiTool\AichiSelenium\src\logs.py", line 73, in error
    self._log(logging.ERROR, *msg)
  File "C:\Users\USER\Projects\AichiTool\AichiSelenium\src\logs.py", line 90, in _log
    message = " ".join(msg)
TypeError: sequence item 1: expected str instance, TimeoutException found

During handling of the above exception, another exception occurred:

Traceback (most recent call last):
  File "C:\Users\USER\Projects\AichiTool\AichiSelenium\src\controllers\access.py", line 29, in login
    wait_until_presence(browser, By.ID, "userLoginForm.userId")
  File "C:\Users\USER\Projects\AichiTool\AichiSelenium\src\utils\html_utils.py", line 8, in wait_until_presence
    WebDriverWait(browser, timeout).until(EC.presence_of_element_located((by, html)))
  File "C:\Users\USER\anaconda3\envs\aichi\lib\site-packages\selenium\webdriver\support\wait.py", line 96, in until
    value = method(self._driver)
  File "C:\Users\USER\anaconda3\envs\aichi\lib\site-packages\selenium\webdriver\support\expected_conditions.py", line 84, in _predicate
    return driver.find_element(*locator)
  File "C:\Users\USER\anaconda3\envs\aichi\lib\site-packages\seleniumbase\core\sb_driver.py", line 20, in find_element
    return self.driver.default_find_element(by=by, value=value)
  File "C:\Users\USER\anaconda3\envs\aichi\lib\site-packages\selenium\webdriver\remote\webdriver.py", line 741, in find_element
    return self.execute(Command.FIND_ELEMENT, {"using": by, "value": value})["value"]
  File "C:\Users\USER\anaconda3\envs\aichi\lib\site-packages\selenium\webdriver\remote\webdriver.py", line 347, in execute
    self.error_handler.check_response(response)
  File "C:\Users\USER\anaconda3\envs\aichi\lib\site-packages\selenium\webdriver\remote\errorhandler.py", line 229, in check_response
    raise exception_class(message, screen, stacktrace)
selenium.common.exceptions.NoSuchWindowException: Message: no such window: target window already closed
from unknown error: web view not found
  (Session info: chrome=124.0.6367.63)
Stacktrace:
	GetHandleVerifier [0x00007FF72E94F922+3045234]
	(No symbol) [0x00007FF72E5F3652]
	(No symbol) [0x00007FF72E4B7564]
	(No symbol) [0x00007FF72E48DB4F]
	(No symbol) [0x00007FF72E531087]
	(No symbol) [0x00007FF72E548871]
	(No symbol) [0x00007FF72E529B53]
	(No symbol) [0x00007FF72E4F813C]
	(No symbol) [0x00007FF72E4F8D71]
	GetHandleVerifier [0x00007FF72E97E89D+3237613]
	GetHandleVerifier [0x00007FF72E9C0BA7+3508727]
	GetHandleVerifier [0x00007FF72E9B976F+3478975]
	GetHandleVerifier [0x00007FF72E72F1C6+815126]
	(No symbol) [0x00007FF72E5FED0F]
	(No symbol) [0x00007FF72E5F9854]
	(No symbol) [0x00007FF72E5F99E2]
	(No symbol) [0x00007FF72E5EA574]
	BaseThreadInitThunk [0x00007FFFFB45257D+29]
	RtlUserThreadStart [0x00007FFFFCEEAA48+40]


During handling of the above exception, another exception occurred:

Traceback (most recent call last):
  File "C:\Users\USER\Projects\AichiTool\AichiSelenium\src\controllers\main_controller.py", line 58, in subprocess
    result = access.login(browser)
  File "C:\Users\USER\Projects\AichiTool\AichiSelenium\src\controllers\access.py", line 53, in login
    self.logger.error("Failed to login", e)
  File "C:\Users\USER\Projects\AichiTool\AichiSelenium\src\logs.py", line 73, in error
    self._log(logging.ERROR, *msg)
  File "C:\Users\USER\Projects\AichiTool\AichiSelenium\src\logs.py", line 90, in _log
    message = " ".join(msg)
TypeError: sequence item 1: expected str instance, NoSuchWindowException found
[ 2024-04-30 22:45:22,866 ] 79 main_controller - ERROR - Caught exception: sequence item 1: expected str instance, NoSuchWindowException found
Traceback (most recent call last):
  File "C:\Users\USER\Projects\AichiTool\AichiSelenium\src\controllers\access.py", line 29, in login
    wait_until_presence(browser, By.ID, "userLoginForm.userId")
  File "C:\Users\USER\Projects\AichiTool\AichiSelenium\src\utils\html_utils.py", line 8, in wait_until_presence
    WebDriverWait(browser, timeout).until(EC.presence_of_element_located((by, html)))
  File "C:\Users\USER\anaconda3\envs\aichi\lib\site-packages\selenium\webdriver\support\wait.py", line 105, in until
    raise TimeoutException(message, screen, stacktrace)
selenium.common.exceptions.TimeoutException: Message: 
Stacktrace:
	GetHandleVerifier [0x00007FF72E94F922+3045234]
	(No symbol) [0x00007FF72E5F3652]
	(No symbol) [0x00007FF72E4B7564]
	(No symbol) [0x00007FF72E505F9D]
	(No symbol) [0x00007FF72E50606C]
	(No symbol) [0x00007FF72E54BDD7]
	(No symbol) [0x00007FF72E529DEF]
	(No symbol) [0x00007FF72E5491C4]
	(No symbol) [0x00007FF72E529B53]
	(No symbol) [0x00007FF72E4F813C]
	(No symbol) [0x00007FF72E4F8D71]
	GetHandleVerifier [0x00007FF72E97E89D+3237613]
	GetHandleVerifier [0x00007FF72E9C0BA7+3508727]
	GetHandleVerifier [0x00007FF72E9B976F+3478975]
	GetHandleVerifier [0x00007FF72E72F1C6+815126]
	(No symbol) [0x00007FF72E5FED0F]
	(No symbol) [0x00007FF72E5F9854]
	(No symbol) [0x00007FF72E5F99E2]
	(No symbol) [0x00007FF72E5EA574]
	BaseThreadInitThunk [0x00007FFFFB45257D+29]
	RtlUserThreadStart [0x00007FFFFCEEAA48+40]


During handling of the above exception, another exception occurred:

Traceback (most recent call last):
  File "C:\Users\USER\Projects\AichiTool\AichiSelenium\src\controllers\main_controller.py", line 58, in subprocess
    result = access.login(browser)
  File "C:\Users\USER\Projects\AichiTool\AichiSelenium\src\controllers\access.py", line 53, in login
    self.logger.error("Failed to login", e)
  File "C:\Users\USER\Projects\AichiTool\AichiSelenium\src\logs.py", line 73, in error
    self._log(logging.ERROR, *msg)
  File "C:\Users\USER\Projects\AichiTool\AichiSelenium\src\logs.py", line 90, in _log
    message = " ".join(msg)
TypeError: sequence item 1: expected str instance, TimeoutException found

During handling of the above exception, another exception occurred:

Traceback (most recent call last):
  File "C:\Users\USER\Projects\AichiTool\AichiSelenium\src\controllers\access.py", line 29, in login
    wait_until_presence(browser, By.ID, "userLoginForm.userId")
  File "C:\Users\USER\Projects\AichiTool\AichiSelenium\src\utils\html_utils.py", line 8, in wait_until_presence
    WebDriverWait(browser, timeout).until(EC.presence_of_element_located((by, html)))
  File "C:\Users\USER\anaconda3\envs\aichi\lib\site-packages\selenium\webdriver\support\wait.py", line 96, in until
    value = method(self._driver)
  File "C:\Users\USER\anaconda3\envs\aichi\lib\site-packages\selenium\webdriver\support\expected_conditions.py", line 84, in _predicate
    return driver.find_element(*locator)
  File "C:\Users\USER\anaconda3\envs\aichi\lib\site-packages\seleniumbase\core\sb_driver.py", line 20, in find_element
    return self.driver.default_find_element(by=by, value=value)
  File "C:\Users\USER\anaconda3\envs\aichi\lib\site-packages\selenium\webdriver\remote\webdriver.py", line 741, in find_element
    return self.execute(Command.FIND_ELEMENT, {"using": by, "value": value})["value"]
  File "C:\Users\USER\anaconda3\envs\aichi\lib\site-packages\selenium\webdriver\remote\webdriver.py", line 347, in execute
    self.error_handler.check_response(response)
  File "C:\Users\USER\anaconda3\envs\aichi\lib\site-packages\selenium\webdriver\remote\errorhandler.py", line 229, in check_response
    raise exception_class(message, screen, stacktrace)
selenium.common.exceptions.NoSuchWindowException: Message: no such window: target window already closed
from unknown error: web view not found
  (Session info: chrome=124.0.6367.63)
Stacktrace:
	GetHandleVerifier [0x00007FF72E94F922+3045234]
	(No symbol) [0x00007FF72E5F3652]
	(No symbol) [0x00007FF72E4B7564]
	(No symbol) [0x00007FF72E48DB4F]
	(No symbol) [0x00007FF72E531087]
	(No symbol) [0x00007FF72E548871]
	(No symbol) [0x00007FF72E529B53]
	(No symbol) [0x00007FF72E4F813C]
	(No symbol) [0x00007FF72E4F8D71]
	GetHandleVerifier [0x00007FF72E97E89D+3237613]
	GetHandleVerifier [0x00007FF72E9C0BA7+3508727]
	GetHandleVerifier [0x00007FF72E9B976F+3478975]
	GetHandleVerifier [0x00007FF72E72F1C6+815126]
	(No symbol) [0x00007FF72E5FED0F]
	(No symbol) [0x00007FF72E5F9854]
	(No symbol) [0x00007FF72E5F99E2]
	(No symbol) [0x00007FF72E5EA574]
	BaseThreadInitThunk [0x00007FFFFB45257D+29]
	RtlUserThreadStart [0x00007FFFFCEEAA48+40]


During handling of the above exception, another exception occurred:

Traceback (most recent call last):
  File "C:\Users\USER\Projects\AichiTool\AichiSelenium\src\controllers\main_controller.py", line 58, in subprocess
    result = access.login(browser)
  File "C:\Users\USER\Projects\AichiTool\AichiSelenium\src\controllers\access.py", line 53, in login
    self.logger.error("Failed to login", e)
  File "C:\Users\USER\Projects\AichiTool\AichiSelenium\src\logs.py", line 73, in error
    self._log(logging.ERROR, *msg)
  File "C:\Users\USER\Projects\AichiTool\AichiSelenium\src\logs.py", line 90, in _log
    message = " ".join(msg)
TypeError: sequence item 1: expected str instance, NoSuchWindowException found
[ 2024-04-30 22:45:24,097 ] 91 main_controller - INFO - Subprocess 1 started with trial number 2
[ 2024-04-30 22:45:24,097 ] 91 main_controller - INFO - Subprocess 1 started with trial number 2
[ 2024-04-30 22:45:24,097 ] 91 main_controller - INFO - Subprocess 1 started with trial number 2
[ 2024-04-30 22:45:24,097 ] 91 main_controller - INFO - Subprocess 1 started with trial number 2
[ 2024-04-30 22:45:24,097 ] 91 main_controller - INFO - Subprocess 1 started with trial number 2
[ 2024-04-30 22:45:24,097 ] 91 main_controller - INFO - Subprocess 1 started with trial number 2
[ 2024-04-30 22:45:24,097 ] 91 main_controller - INFO - Subprocess 1 started with trial number 2
[ 2024-04-30 22:45:24,097 ] 91 main_controller - INFO - Subprocess 1 started with trial number 2
[ 2024-04-30 22:45:24,253 ] 91 main_controller - INFO - Browser opened
[ 2024-04-30 22:45:24,253 ] 91 main_controller - INFO - Browser opened
[ 2024-04-30 22:45:24,253 ] 91 main_controller - INFO - Browser opened
[ 2024-04-30 22:45:24,253 ] 91 main_controller - INFO - Browser opened
[ 2024-04-30 22:45:24,253 ] 91 main_controller - INFO - Browser opened
[ 2024-04-30 22:45:24,253 ] 91 main_controller - INFO - Browser opened
[ 2024-04-30 22:45:24,253 ] 91 main_controller - INFO - Browser opened
[ 2024-04-30 22:45:24,253 ] 91 main_controller - INFO - Browser opened
[ 2024-04-30 22:45:25,496 ] 91 main_controller - INFO - Browser opened
[ 2024-04-30 22:45:25,496 ] 91 main_controller - INFO - Browser opened
[ 2024-04-30 22:45:25,496 ] 91 main_controller - INFO - Browser opened
[ 2024-04-30 22:45:25,496 ] 91 main_controller - INFO - Browser opened
[ 2024-04-30 22:45:25,496 ] 91 main_controller - INFO - Browser opened
[ 2024-04-30 22:45:25,496 ] 91 main_controller - INFO - Browser opened
[ 2024-04-30 22:45:25,496 ] 91 main_controller - INFO - Browser opened
[ 2024-04-30 22:45:25,496 ] 91 main_controller - INFO - Browser opened
[ 2024-04-30 22:45:25,505 ] 91 main_controller - INFO - Subprocess 2 started with trial number 2
[ 2024-04-30 22:45:25,505 ] 91 main_controller - INFO - Subprocess 2 started with trial number 2
[ 2024-04-30 22:45:25,505 ] 91 main_controller - INFO - Subprocess 2 started with trial number 2
[ 2024-04-30 22:45:25,505 ] 91 main_controller - INFO - Subprocess 2 started with trial number 2
[ 2024-04-30 22:45:25,505 ] 91 main_controller - INFO - Subprocess 2 started with trial number 2
[ 2024-04-30 22:45:25,505 ] 91 main_controller - INFO - Subprocess 2 started with trial number 2
[ 2024-04-30 22:45:25,505 ] 91 main_controller - INFO - Subprocess 2 started with trial number 2
[ 2024-04-30 22:45:25,505 ] 91 main_controller - INFO - Subprocess 2 started with trial number 2
[ 2024-04-30 22:45:25,505 ] 91 main_controller - INFO - Subprocess 2 started with trial number 2
[ 2024-04-30 22:45:27,381 ] 91 main_controller - INFO - Browser opened
[ 2024-04-30 22:45:27,381 ] 91 main_controller - INFO - Browser opened
[ 2024-04-30 22:45:27,381 ] 91 main_controller - INFO - Browser opened
[ 2024-04-30 22:45:27,381 ] 91 main_controller - INFO - Browser opened
[ 2024-04-30 22:45:27,381 ] 91 main_controller - INFO - Browser opened
[ 2024-04-30 22:45:27,381 ] 91 main_controller - INFO - Browser opened
[ 2024-04-30 22:45:27,381 ] 91 main_controller - INFO - Browser opened
[ 2024-04-30 22:45:27,381 ] 91 main_controller - INFO - Browser opened
[ 2024-04-30 22:45:27,381 ] 91 main_controller - INFO - Browser opened
