[ 2024-04-24 15:06:50,028 ] 91 main_controller - INFO - Subprocess 0 started with trial number 0
[ 2024-04-24 15:06:50,029 ] 91 main_controller - ERROR - Account is a dictionary, convert to Account object: Username: luthien5921@gmail.com, Password: aichi@5921
[ 2024-04-24 15:06:52,252 ] 91 main_controller - INFO - Browser opened
[ 2024-04-24 15:07:02,640 ] 91 main_controller - INFO - Logged in successfully
[ 2024-04-24 15:07:02,876 ] 91 main_controller - INFO - Screenshot saved to C:\Users\USER\Projects\AichiTool\AichiSelenium\logs\2024_04_24\15_06_49\screenshot_luthien5921.png
[ 2024-04-24 15:07:02,877 ] 91 main_controller - INFO - Finding forms
[ 2024-04-24 15:07:04,692 ] 79 main_controller - ERROR - Caught exception: 'NoneType' object has no attribute 'group'
Traceback (most recent call last):
  File "C:\Users\USER\Projects\AichiTool\AichiSelenium\src\controllers\main_controller.py", line 72, in subprocess
    list_form_info = finder.find(browser)
  File "C:\Users\USER\Projects\AichiTool\AichiSelenium\src\controllers\finder.py", line 25, in find
    self._collect(browser)
  File "C:\Users\USER\Projects\AichiTool\AichiSelenium\src\controllers\finder.py", line 58, in _collect
    form_info = self._parse_data(form_text)
  File "C:\Users\USER\Projects\AichiTool\AichiSelenium\src\controllers\finder.py", line 97, in _parse_data
    form_info = FormInfo(title, status, start_date_str, end_date_str, template_seq)
  File "C:\Users\USER\Projects\AichiTool\AichiSelenium\src\models\form.py", line 83, in __init__
    self.end_datetime = du.string_to_datetime(end_date_str)
  File "C:\Users\USER\Projects\AichiTool\AichiSelenium\src\utils\data_utils.py", line 57, in string_to_datetime
    year = int(match_date.group(1))
AttributeError: 'NoneType' object has no attribute 'group'
[ 2024-04-24 15:07:07,034 ] 91 main_controller - INFO - Subprocess 0 started with trial number 1
[ 2024-04-24 15:07:07,034 ] 91 main_controller - INFO - Subprocess 0 started with trial number 1
[ 2024-04-24 15:07:09,123 ] 91 main_controller - INFO - Browser opened
[ 2024-04-24 15:07:09,123 ] 91 main_controller - INFO - Browser opened
[ 2024-04-24 15:07:19,250 ] 91 main_controller - INFO - Logged in successfully
[ 2024-04-24 15:07:19,250 ] 91 main_controller - INFO - Logged in successfully
[ 2024-04-24 15:07:19,506 ] 91 main_controller - INFO - Screenshot saved to C:\Users\USER\Projects\AichiTool\AichiSelenium\logs\2024_04_24\15_06_49\screenshot_luthien5921.png
[ 2024-04-24 15:07:19,506 ] 91 main_controller - INFO - Screenshot saved to C:\Users\USER\Projects\AichiTool\AichiSelenium\logs\2024_04_24\15_06_49\screenshot_luthien5921.png
[ 2024-04-24 15:07:19,506 ] 91 main_controller - INFO - Finding forms
[ 2024-04-24 15:07:19,506 ] 91 main_controller - INFO - Finding forms
[ 2024-04-24 15:07:21,348 ] 79 main_controller - ERROR - Caught exception: 'NoneType' object has no attribute 'group'
Traceback (most recent call last):
  File "C:\Users\USER\Projects\AichiTool\AichiSelenium\src\controllers\main_controller.py", line 72, in subprocess
    list_form_info = finder.find(browser)
  File "C:\Users\USER\Projects\AichiTool\AichiSelenium\src\controllers\finder.py", line 25, in find
    self._collect(browser)
  File "C:\Users\USER\Projects\AichiTool\AichiSelenium\src\controllers\finder.py", line 58, in _collect
    form_info = self._parse_data(form_text)
  File "C:\Users\USER\Projects\AichiTool\AichiSelenium\src\controllers\finder.py", line 97, in _parse_data
    form_info = FormInfo(title, status, start_date_str, end_date_str, template_seq)
  File "C:\Users\USER\Projects\AichiTool\AichiSelenium\src\models\form.py", line 83, in __init__
    self.end_datetime = du.string_to_datetime(end_date_str)
  File "C:\Users\USER\Projects\AichiTool\AichiSelenium\src\utils\data_utils.py", line 57, in string_to_datetime
    year = int(match_date.group(1))
AttributeError: 'NoneType' object has no attribute 'group'

During handling of the above exception, another exception occurred:

Traceback (most recent call last):
  File "C:\Users\USER\Projects\AichiTool\AichiSelenium\src\controllers\main_controller.py", line 72, in subprocess
    list_form_info = finder.find(browser)
  File "C:\Users\USER\Projects\AichiTool\AichiSelenium\src\controllers\finder.py", line 25, in find
    self._collect(browser)
  File "C:\Users\USER\Projects\AichiTool\AichiSelenium\src\controllers\finder.py", line 58, in _collect
    form_info = self._parse_data(form_text)
  File "C:\Users\USER\Projects\AichiTool\AichiSelenium\src\controllers\finder.py", line 97, in _parse_data
    form_info = FormInfo(title, status, start_date_str, end_date_str, template_seq)
  File "C:\Users\USER\Projects\AichiTool\AichiSelenium\src\models\form.py", line 83, in __init__
    self.end_datetime = du.string_to_datetime(end_date_str)
  File "C:\Users\USER\Projects\AichiTool\AichiSelenium\src\utils\data_utils.py", line 57, in string_to_datetime
    year = int(match_date.group(1))
AttributeError: 'NoneType' object has no attribute 'group'
[ 2024-04-24 15:07:21,348 ] 79 main_controller - ERROR - Caught exception: 'NoneType' object has no attribute 'group'
Traceback (most recent call last):
  File "C:\Users\USER\Projects\AichiTool\AichiSelenium\src\controllers\main_controller.py", line 72, in subprocess
    list_form_info = finder.find(browser)
  File "C:\Users\USER\Projects\AichiTool\AichiSelenium\src\controllers\finder.py", line 25, in find
    self._collect(browser)
  File "C:\Users\USER\Projects\AichiTool\AichiSelenium\src\controllers\finder.py", line 58, in _collect
    form_info = self._parse_data(form_text)
  File "C:\Users\USER\Projects\AichiTool\AichiSelenium\src\controllers\finder.py", line 97, in _parse_data
    form_info = FormInfo(title, status, start_date_str, end_date_str, template_seq)
  File "C:\Users\USER\Projects\AichiTool\AichiSelenium\src\models\form.py", line 83, in __init__
    self.end_datetime = du.string_to_datetime(end_date_str)
  File "C:\Users\USER\Projects\AichiTool\AichiSelenium\src\utils\data_utils.py", line 57, in string_to_datetime
    year = int(match_date.group(1))
AttributeError: 'NoneType' object has no attribute 'group'

During handling of the above exception, another exception occurred:

Traceback (most recent call last):
  File "C:\Users\USER\Projects\AichiTool\AichiSelenium\src\controllers\main_controller.py", line 72, in subprocess
    list_form_info = finder.find(browser)
  File "C:\Users\USER\Projects\AichiTool\AichiSelenium\src\controllers\finder.py", line 25, in find
    self._collect(browser)
  File "C:\Users\USER\Projects\AichiTool\AichiSelenium\src\controllers\finder.py", line 58, in _collect
    form_info = self._parse_data(form_text)
  File "C:\Users\USER\Projects\AichiTool\AichiSelenium\src\controllers\finder.py", line 97, in _parse_data
    form_info = FormInfo(title, status, start_date_str, end_date_str, template_seq)
  File "C:\Users\USER\Projects\AichiTool\AichiSelenium\src\models\form.py", line 83, in __init__
    self.end_datetime = du.string_to_datetime(end_date_str)
  File "C:\Users\USER\Projects\AichiTool\AichiSelenium\src\utils\data_utils.py", line 57, in string_to_datetime
    year = int(match_date.group(1))
AttributeError: 'NoneType' object has no attribute 'group'
[ 2024-04-24 15:07:23,568 ] 91 main_controller - INFO - Subprocess 0 started with trial number 2
[ 2024-04-24 15:07:23,568 ] 91 main_controller - INFO - Subprocess 0 started with trial number 2
[ 2024-04-24 15:07:23,568 ] 91 main_controller - INFO - Subprocess 0 started with trial number 2
[ 2024-04-24 15:07:25,495 ] 91 main_controller - INFO - Browser opened
[ 2024-04-24 15:07:25,495 ] 91 main_controller - INFO - Browser opened
[ 2024-04-24 15:07:25,495 ] 91 main_controller - INFO - Browser opened
[ 2024-04-24 15:07:35,243 ] 91 main_controller - INFO - Logged in successfully
[ 2024-04-24 15:07:35,243 ] 91 main_controller - INFO - Logged in successfully
[ 2024-04-24 15:07:35,243 ] 91 main_controller - INFO - Logged in successfully
[ 2024-04-24 15:07:35,552 ] 91 main_controller - INFO - Screenshot saved to C:\Users\USER\Projects\AichiTool\AichiSelenium\logs\2024_04_24\15_06_49\screenshot_luthien5921.png
[ 2024-04-24 15:07:35,552 ] 91 main_controller - INFO - Screenshot saved to C:\Users\USER\Projects\AichiTool\AichiSelenium\logs\2024_04_24\15_06_49\screenshot_luthien5921.png
[ 2024-04-24 15:07:35,552 ] 91 main_controller - INFO - Screenshot saved to C:\Users\USER\Projects\AichiTool\AichiSelenium\logs\2024_04_24\15_06_49\screenshot_luthien5921.png
[ 2024-04-24 15:07:35,552 ] 91 main_controller - INFO - Finding forms
[ 2024-04-24 15:07:35,552 ] 91 main_controller - INFO - Finding forms
[ 2024-04-24 15:07:35,552 ] 91 main_controller - INFO - Finding forms
[ 2024-04-24 15:07:37,107 ] 79 main_controller - ERROR - Caught exception: 'NoneType' object has no attribute 'group'
Traceback (most recent call last):
  File "C:\Users\USER\Projects\AichiTool\AichiSelenium\src\controllers\main_controller.py", line 72, in subprocess
    list_form_info = finder.find(browser)
  File "C:\Users\USER\Projects\AichiTool\AichiSelenium\src\controllers\finder.py", line 25, in find
    self._collect(browser)
  File "C:\Users\USER\Projects\AichiTool\AichiSelenium\src\controllers\finder.py", line 58, in _collect
    form_info = self._parse_data(form_text)
  File "C:\Users\USER\Projects\AichiTool\AichiSelenium\src\controllers\finder.py", line 97, in _parse_data
    form_info = FormInfo(title, status, start_date_str, end_date_str, template_seq)
  File "C:\Users\USER\Projects\AichiTool\AichiSelenium\src\models\form.py", line 83, in __init__
    self.end_datetime = du.string_to_datetime(self.end_date_str)
  File "C:\Users\USER\Projects\AichiTool\AichiSelenium\src\utils\data_utils.py", line 57, in string_to_datetime
    year = int(match_date.group(1))
AttributeError: 'NoneType' object has no attribute 'group'

During handling of the above exception, another exception occurred:

Traceback (most recent call last):
  File "C:\Users\USER\Projects\AichiTool\AichiSelenium\src\controllers\main_controller.py", line 72, in subprocess
    list_form_info = finder.find(browser)
  File "C:\Users\USER\Projects\AichiTool\AichiSelenium\src\controllers\finder.py", line 25, in find
    self._collect(browser)
  File "C:\Users\USER\Projects\AichiTool\AichiSelenium\src\controllers\finder.py", line 58, in _collect
    form_info = self._parse_data(form_text)
  File "C:\Users\USER\Projects\AichiTool\AichiSelenium\src\controllers\finder.py", line 97, in _parse_data
    form_info = FormInfo(title, status, start_date_str, end_date_str, template_seq)
  File "C:\Users\USER\Projects\AichiTool\AichiSelenium\src\models\form.py", line 83, in __init__
    self.end_datetime = du.string_to_datetime(self.end_date_str)
  File "C:\Users\USER\Projects\AichiTool\AichiSelenium\src\utils\data_utils.py", line 57, in string_to_datetime
    year = int(match_date.group(1))
AttributeError: 'NoneType' object has no attribute 'group'

During handling of the above exception, another exception occurred:

Traceback (most recent call last):
  File "C:\Users\USER\Projects\AichiTool\AichiSelenium\src\controllers\main_controller.py", line 72, in subprocess
    list_form_info = finder.find(browser)
  File "C:\Users\USER\Projects\AichiTool\AichiSelenium\src\controllers\finder.py", line 25, in find
    self._collect(browser)
  File "C:\Users\USER\Projects\AichiTool\AichiSelenium\src\controllers\finder.py", line 58, in _collect
    form_info = self._parse_data(form_text)
  File "C:\Users\USER\Projects\AichiTool\AichiSelenium\src\controllers\finder.py", line 97, in _parse_data
    form_info = FormInfo(title, status, start_date_str, end_date_str, template_seq)
  File "C:\Users\USER\Projects\AichiTool\AichiSelenium\src\models\form.py", line 83, in __init__
    self.end_datetime = du.string_to_datetime(self.end_date_str)
  File "C:\Users\USER\Projects\AichiTool\AichiSelenium\src\utils\data_utils.py", line 57, in string_to_datetime
    year = int(match_date.group(1))
AttributeError: 'NoneType' object has no attribute 'group'
[ 2024-04-24 15:07:37,107 ] 79 main_controller - ERROR - Caught exception: 'NoneType' object has no attribute 'group'
Traceback (most recent call last):
  File "C:\Users\USER\Projects\AichiTool\AichiSelenium\src\controllers\main_controller.py", line 72, in subprocess
    list_form_info = finder.find(browser)
  File "C:\Users\USER\Projects\AichiTool\AichiSelenium\src\controllers\finder.py", line 25, in find
    self._collect(browser)
  File "C:\Users\USER\Projects\AichiTool\AichiSelenium\src\controllers\finder.py", line 58, in _collect
    form_info = self._parse_data(form_text)
  File "C:\Users\USER\Projects\AichiTool\AichiSelenium\src\controllers\finder.py", line 97, in _parse_data
    form_info = FormInfo(title, status, start_date_str, end_date_str, template_seq)
  File "C:\Users\USER\Projects\AichiTool\AichiSelenium\src\models\form.py", line 83, in __init__
    self.end_datetime = du.string_to_datetime(self.end_date_str)
  File "C:\Users\USER\Projects\AichiTool\AichiSelenium\src\utils\data_utils.py", line 57, in string_to_datetime
    year = int(match_date.group(1))
AttributeError: 'NoneType' object has no attribute 'group'

During handling of the above exception, another exception occurred:

Traceback (most recent call last):
  File "C:\Users\USER\Projects\AichiTool\AichiSelenium\src\controllers\main_controller.py", line 72, in subprocess
    list_form_info = finder.find(browser)
  File "C:\Users\USER\Projects\AichiTool\AichiSelenium\src\controllers\finder.py", line 25, in find
    self._collect(browser)
  File "C:\Users\USER\Projects\AichiTool\AichiSelenium\src\controllers\finder.py", line 58, in _collect
    form_info = self._parse_data(form_text)
  File "C:\Users\USER\Projects\AichiTool\AichiSelenium\src\controllers\finder.py", line 97, in _parse_data
    form_info = FormInfo(title, status, start_date_str, end_date_str, template_seq)
  File "C:\Users\USER\Projects\AichiTool\AichiSelenium\src\models\form.py", line 83, in __init__
    self.end_datetime = du.string_to_datetime(self.end_date_str)
  File "C:\Users\USER\Projects\AichiTool\AichiSelenium\src\utils\data_utils.py", line 57, in string_to_datetime
    year = int(match_date.group(1))
AttributeError: 'NoneType' object has no attribute 'group'

During handling of the above exception, another exception occurred:

Traceback (most recent call last):
  File "C:\Users\USER\Projects\AichiTool\AichiSelenium\src\controllers\main_controller.py", line 72, in subprocess
    list_form_info = finder.find(browser)
  File "C:\Users\USER\Projects\AichiTool\AichiSelenium\src\controllers\finder.py", line 25, in find
    self._collect(browser)
  File "C:\Users\USER\Projects\AichiTool\AichiSelenium\src\controllers\finder.py", line 58, in _collect
    form_info = self._parse_data(form_text)
  File "C:\Users\USER\Projects\AichiTool\AichiSelenium\src\controllers\finder.py", line 97, in _parse_data
    form_info = FormInfo(title, status, start_date_str, end_date_str, template_seq)
  File "C:\Users\USER\Projects\AichiTool\AichiSelenium\src\models\form.py", line 83, in __init__
    self.end_datetime = du.string_to_datetime(self.end_date_str)
  File "C:\Users\USER\Projects\AichiTool\AichiSelenium\src\utils\data_utils.py", line 57, in string_to_datetime
    year = int(match_date.group(1))
AttributeError: 'NoneType' object has no attribute 'group'
[ 2024-04-24 15:07:37,107 ] 79 main_controller - ERROR - Caught exception: 'NoneType' object has no attribute 'group'
Traceback (most recent call last):
  File "C:\Users\USER\Projects\AichiTool\AichiSelenium\src\controllers\main_controller.py", line 72, in subprocess
    list_form_info = finder.find(browser)
  File "C:\Users\USER\Projects\AichiTool\AichiSelenium\src\controllers\finder.py", line 25, in find
    self._collect(browser)
  File "C:\Users\USER\Projects\AichiTool\AichiSelenium\src\controllers\finder.py", line 58, in _collect
    form_info = self._parse_data(form_text)
  File "C:\Users\USER\Projects\AichiTool\AichiSelenium\src\controllers\finder.py", line 97, in _parse_data
    form_info = FormInfo(title, status, start_date_str, end_date_str, template_seq)
  File "C:\Users\USER\Projects\AichiTool\AichiSelenium\src\models\form.py", line 83, in __init__
    self.end_datetime = du.string_to_datetime(self.end_date_str)
  File "C:\Users\USER\Projects\AichiTool\AichiSelenium\src\utils\data_utils.py", line 57, in string_to_datetime
    year = int(match_date.group(1))
AttributeError: 'NoneType' object has no attribute 'group'

During handling of the above exception, another exception occurred:

Traceback (most recent call last):
  File "C:\Users\USER\Projects\AichiTool\AichiSelenium\src\controllers\main_controller.py", line 72, in subprocess
    list_form_info = finder.find(browser)
  File "C:\Users\USER\Projects\AichiTool\AichiSelenium\src\controllers\finder.py", line 25, in find
    self._collect(browser)
  File "C:\Users\USER\Projects\AichiTool\AichiSelenium\src\controllers\finder.py", line 58, in _collect
    form_info = self._parse_data(form_text)
  File "C:\Users\USER\Projects\AichiTool\AichiSelenium\src\controllers\finder.py", line 97, in _parse_data
    form_info = FormInfo(title, status, start_date_str, end_date_str, template_seq)
  File "C:\Users\USER\Projects\AichiTool\AichiSelenium\src\models\form.py", line 83, in __init__
    self.end_datetime = du.string_to_datetime(self.end_date_str)
  File "C:\Users\USER\Projects\AichiTool\AichiSelenium\src\utils\data_utils.py", line 57, in string_to_datetime
    year = int(match_date.group(1))
AttributeError: 'NoneType' object has no attribute 'group'

During handling of the above exception, another exception occurred:

Traceback (most recent call last):
  File "C:\Users\USER\Projects\AichiTool\AichiSelenium\src\controllers\main_controller.py", line 72, in subprocess
    list_form_info = finder.find(browser)
  File "C:\Users\USER\Projects\AichiTool\AichiSelenium\src\controllers\finder.py", line 25, in find
    self._collect(browser)
  File "C:\Users\USER\Projects\AichiTool\AichiSelenium\src\controllers\finder.py", line 58, in _collect
    form_info = self._parse_data(form_text)
  File "C:\Users\USER\Projects\AichiTool\AichiSelenium\src\controllers\finder.py", line 97, in _parse_data
    form_info = FormInfo(title, status, start_date_str, end_date_str, template_seq)
  File "C:\Users\USER\Projects\AichiTool\AichiSelenium\src\models\form.py", line 83, in __init__
    self.end_datetime = du.string_to_datetime(self.end_date_str)
  File "C:\Users\USER\Projects\AichiTool\AichiSelenium\src\utils\data_utils.py", line 57, in string_to_datetime
    year = int(match_date.group(1))
AttributeError: 'NoneType' object has no attribute 'group'
[ 2024-04-24 15:07:39,320 ] 91 main_controller - INFO - Subprocess 0 started with trial number 3
[ 2024-04-24 15:07:39,320 ] 91 main_controller - INFO - Subprocess 0 started with trial number 3
[ 2024-04-24 15:07:39,320 ] 91 main_controller - INFO - Subprocess 0 started with trial number 3
[ 2024-04-24 15:07:39,320 ] 91 main_controller - INFO - Subprocess 0 started with trial number 3
[ 2024-04-24 15:07:41,553 ] 91 main_controller - INFO - Browser opened
[ 2024-04-24 15:07:41,553 ] 91 main_controller - INFO - Browser opened
[ 2024-04-24 15:07:41,553 ] 91 main_controller - INFO - Browser opened
[ 2024-04-24 15:07:41,553 ] 91 main_controller - INFO - Browser opened
[ 2024-04-24 15:07:51,551 ] 91 main_controller - INFO - Logged in successfully
[ 2024-04-24 15:07:51,551 ] 91 main_controller - INFO - Logged in successfully
[ 2024-04-24 15:07:51,551 ] 91 main_controller - INFO - Logged in successfully
[ 2024-04-24 15:07:51,551 ] 91 main_controller - INFO - Logged in successfully
[ 2024-04-24 15:07:51,819 ] 91 main_controller - INFO - Screenshot saved to C:\Users\USER\Projects\AichiTool\AichiSelenium\logs\2024_04_24\15_06_49\screenshot_luthien5921.png
[ 2024-04-24 15:07:51,819 ] 91 main_controller - INFO - Screenshot saved to C:\Users\USER\Projects\AichiTool\AichiSelenium\logs\2024_04_24\15_06_49\screenshot_luthien5921.png
[ 2024-04-24 15:07:51,819 ] 91 main_controller - INFO - Screenshot saved to C:\Users\USER\Projects\AichiTool\AichiSelenium\logs\2024_04_24\15_06_49\screenshot_luthien5921.png
[ 2024-04-24 15:07:51,819 ] 91 main_controller - INFO - Screenshot saved to C:\Users\USER\Projects\AichiTool\AichiSelenium\logs\2024_04_24\15_06_49\screenshot_luthien5921.png
[ 2024-04-24 15:07:51,820 ] 91 main_controller - INFO - Finding forms
[ 2024-04-24 15:07:51,820 ] 91 main_controller - INFO - Finding forms
[ 2024-04-24 15:07:51,820 ] 91 main_controller - INFO - Finding forms
[ 2024-04-24 15:07:51,820 ] 91 main_controller - INFO - Finding forms
[ 2024-04-24 15:07:53,731 ] 79 main_controller - ERROR - Caught exception: 'NoneType' object has no attribute 'group'
Traceback (most recent call last):
  File "C:\Users\USER\Projects\AichiTool\AichiSelenium\src\controllers\main_controller.py", line 72, in subprocess
    list_form_info = finder.find(browser)
  File "C:\Users\USER\Projects\AichiTool\AichiSelenium\src\controllers\finder.py", line 25, in find
    self._collect(browser)
  File "C:\Users\USER\Projects\AichiTool\AichiSelenium\src\controllers\finder.py", line 58, in _collect
    form_info = self._parse_data(form_text)
  File "C:\Users\USER\Projects\AichiTool\AichiSelenium\src\controllers\finder.py", line 97, in _parse_data
    form_info = FormInfo(title, status, start_date_str, end_date_str, template_seq)
  File "C:\Users\USER\Projects\AichiTool\AichiSelenium\src\models\form.py", line 83, in __init__
    self.end_datetime = du.string_to_datetime(self.end_date_str)
  File "C:\Users\USER\Projects\AichiTool\AichiSelenium\src\utils\data_utils.py", line 57, in string_to_datetime
    year = int(match_date.group(1))
AttributeError: 'NoneType' object has no attribute 'group'

During handling of the above exception, another exception occurred:

Traceback (most recent call last):
  File "C:\Users\USER\Projects\AichiTool\AichiSelenium\src\controllers\main_controller.py", line 72, in subprocess
    list_form_info = finder.find(browser)
  File "C:\Users\USER\Projects\AichiTool\AichiSelenium\src\controllers\finder.py", line 25, in find
    self._collect(browser)
  File "C:\Users\USER\Projects\AichiTool\AichiSelenium\src\controllers\finder.py", line 58, in _collect
    form_info = self._parse_data(form_text)
  File "C:\Users\USER\Projects\AichiTool\AichiSelenium\src\controllers\finder.py", line 97, in _parse_data
    form_info = FormInfo(title, status, start_date_str, end_date_str, template_seq)
  File "C:\Users\USER\Projects\AichiTool\AichiSelenium\src\models\form.py", line 83, in __init__
    self.end_datetime = du.string_to_datetime(self.end_date_str)
  File "C:\Users\USER\Projects\AichiTool\AichiSelenium\src\utils\data_utils.py", line 57, in string_to_datetime
    year = int(match_date.group(1))
AttributeError: 'NoneType' object has no attribute 'group'

During handling of the above exception, another exception occurred:

Traceback (most recent call last):
  File "C:\Users\USER\Projects\AichiTool\AichiSelenium\src\controllers\main_controller.py", line 72, in subprocess
    list_form_info = finder.find(browser)
  File "C:\Users\USER\Projects\AichiTool\AichiSelenium\src\controllers\finder.py", line 25, in find
    self._collect(browser)
  File "C:\Users\USER\Projects\AichiTool\AichiSelenium\src\controllers\finder.py", line 58, in _collect
    form_info = self._parse_data(form_text)
  File "C:\Users\USER\Projects\AichiTool\AichiSelenium\src\controllers\finder.py", line 97, in _parse_data
    form_info = FormInfo(title, status, start_date_str, end_date_str, template_seq)
  File "C:\Users\USER\Projects\AichiTool\AichiSelenium\src\models\form.py", line 83, in __init__
    self.end_datetime = du.string_to_datetime(self.end_date_str)
  File "C:\Users\USER\Projects\AichiTool\AichiSelenium\src\utils\data_utils.py", line 57, in string_to_datetime
    year = int(match_date.group(1))
AttributeError: 'NoneType' object has no attribute 'group'

During handling of the above exception, another exception occurred:

Traceback (most recent call last):
  File "C:\Users\USER\Projects\AichiTool\AichiSelenium\src\controllers\main_controller.py", line 72, in subprocess
    list_form_info = finder.find(browser)
  File "C:\Users\USER\Projects\AichiTool\AichiSelenium\src\controllers\finder.py", line 25, in find
    self._collect(browser)
  File "C:\Users\USER\Projects\AichiTool\AichiSelenium\src\controllers\finder.py", line 58, in _collect
    form_info = self._parse_data(form_text)
  File "C:\Users\USER\Projects\AichiTool\AichiSelenium\src\controllers\finder.py", line 97, in _parse_data
    form_info = FormInfo(title, status, start_date_str, end_date_str, template_seq)
  File "C:\Users\USER\Projects\AichiTool\AichiSelenium\src\models\form.py", line 83, in __init__
    self.end_datetime = du.string_to_datetime(self.end_date_str)
  File "C:\Users\USER\Projects\AichiTool\AichiSelenium\src\utils\data_utils.py", line 57, in string_to_datetime
    year = int(match_date.group(1))
AttributeError: 'NoneType' object has no attribute 'group'
[ 2024-04-24 15:07:53,731 ] 79 main_controller - ERROR - Caught exception: 'NoneType' object has no attribute 'group'
Traceback (most recent call last):
  File "C:\Users\USER\Projects\AichiTool\AichiSelenium\src\controllers\main_controller.py", line 72, in subprocess
    list_form_info = finder.find(browser)
  File "C:\Users\USER\Projects\AichiTool\AichiSelenium\src\controllers\finder.py", line 25, in find
    self._collect(browser)
  File "C:\Users\USER\Projects\AichiTool\AichiSelenium\src\controllers\finder.py", line 58, in _collect
    form_info = self._parse_data(form_text)
  File "C:\Users\USER\Projects\AichiTool\AichiSelenium\src\controllers\finder.py", line 97, in _parse_data
    form_info = FormInfo(title, status, start_date_str, end_date_str, template_seq)
  File "C:\Users\USER\Projects\AichiTool\AichiSelenium\src\models\form.py", line 83, in __init__
    self.end_datetime = du.string_to_datetime(self.end_date_str)
  File "C:\Users\USER\Projects\AichiTool\AichiSelenium\src\utils\data_utils.py", line 57, in string_to_datetime
    year = int(match_date.group(1))
AttributeError: 'NoneType' object has no attribute 'group'

During handling of the above exception, another exception occurred:

Traceback (most recent call last):
  File "C:\Users\USER\Projects\AichiTool\AichiSelenium\src\controllers\main_controller.py", line 72, in subprocess
    list_form_info = finder.find(browser)
  File "C:\Users\USER\Projects\AichiTool\AichiSelenium\src\controllers\finder.py", line 25, in find
    self._collect(browser)
  File "C:\Users\USER\Projects\AichiTool\AichiSelenium\src\controllers\finder.py", line 58, in _collect
    form_info = self._parse_data(form_text)
  File "C:\Users\USER\Projects\AichiTool\AichiSelenium\src\controllers\finder.py", line 97, in _parse_data
    form_info = FormInfo(title, status, start_date_str, end_date_str, template_seq)
  File "C:\Users\USER\Projects\AichiTool\AichiSelenium\src\models\form.py", line 83, in __init__
    self.end_datetime = du.string_to_datetime(self.end_date_str)
  File "C:\Users\USER\Projects\AichiTool\AichiSelenium\src\utils\data_utils.py", line 57, in string_to_datetime
    year = int(match_date.group(1))
AttributeError: 'NoneType' object has no attribute 'group'

During handling of the above exception, another exception occurred:

Traceback (most recent call last):
  File "C:\Users\USER\Projects\AichiTool\AichiSelenium\src\controllers\main_controller.py", line 72, in subprocess
    list_form_info = finder.find(browser)
  File "C:\Users\USER\Projects\AichiTool\AichiSelenium\src\controllers\finder.py", line 25, in find
    self._collect(browser)
  File "C:\Users\USER\Projects\AichiTool\AichiSelenium\src\controllers\finder.py", line 58, in _collect
    form_info = self._parse_data(form_text)
  File "C:\Users\USER\Projects\AichiTool\AichiSelenium\src\controllers\finder.py", line 97, in _parse_data
    form_info = FormInfo(title, status, start_date_str, end_date_str, template_seq)
  File "C:\Users\USER\Projects\AichiTool\AichiSelenium\src\models\form.py", line 83, in __init__
    self.end_datetime = du.string_to_datetime(self.end_date_str)
  File "C:\Users\USER\Projects\AichiTool\AichiSelenium\src\utils\data_utils.py", line 57, in string_to_datetime
    year = int(match_date.group(1))
AttributeError: 'NoneType' object has no attribute 'group'

During handling of the above exception, another exception occurred:

Traceback (most recent call last):
  File "C:\Users\USER\Projects\AichiTool\AichiSelenium\src\controllers\main_controller.py", line 72, in subprocess
    list_form_info = finder.find(browser)
  File "C:\Users\USER\Projects\AichiTool\AichiSelenium\src\controllers\finder.py", line 25, in find
    self._collect(browser)
  File "C:\Users\USER\Projects\AichiTool\AichiSelenium\src\controllers\finder.py", line 58, in _collect
    form_info = self._parse_data(form_text)
  File "C:\Users\USER\Projects\AichiTool\AichiSelenium\src\controllers\finder.py", line 97, in _parse_data
    form_info = FormInfo(title, status, start_date_str, end_date_str, template_seq)
  File "C:\Users\USER\Projects\AichiTool\AichiSelenium\src\models\form.py", line 83, in __init__
    self.end_datetime = du.string_to_datetime(self.end_date_str)
  File "C:\Users\USER\Projects\AichiTool\AichiSelenium\src\utils\data_utils.py", line 57, in string_to_datetime
    year = int(match_date.group(1))
AttributeError: 'NoneType' object has no attribute 'group'
[ 2024-04-24 15:07:53,731 ] 79 main_controller - ERROR - Caught exception: 'NoneType' object has no attribute 'group'
Traceback (most recent call last):
  File "C:\Users\USER\Projects\AichiTool\AichiSelenium\src\controllers\main_controller.py", line 72, in subprocess
    list_form_info = finder.find(browser)
  File "C:\Users\USER\Projects\AichiTool\AichiSelenium\src\controllers\finder.py", line 25, in find
    self._collect(browser)
  File "C:\Users\USER\Projects\AichiTool\AichiSelenium\src\controllers\finder.py", line 58, in _collect
    form_info = self._parse_data(form_text)
  File "C:\Users\USER\Projects\AichiTool\AichiSelenium\src\controllers\finder.py", line 97, in _parse_data
    form_info = FormInfo(title, status, start_date_str, end_date_str, template_seq)
  File "C:\Users\USER\Projects\AichiTool\AichiSelenium\src\models\form.py", line 83, in __init__
    self.end_datetime = du.string_to_datetime(self.end_date_str)
  File "C:\Users\USER\Projects\AichiTool\AichiSelenium\src\utils\data_utils.py", line 57, in string_to_datetime
    year = int(match_date.group(1))
AttributeError: 'NoneType' object has no attribute 'group'

During handling of the above exception, another exception occurred:

Traceback (most recent call last):
  File "C:\Users\USER\Projects\AichiTool\AichiSelenium\src\controllers\main_controller.py", line 72, in subprocess
    list_form_info = finder.find(browser)
  File "C:\Users\USER\Projects\AichiTool\AichiSelenium\src\controllers\finder.py", line 25, in find
    self._collect(browser)
  File "C:\Users\USER\Projects\AichiTool\AichiSelenium\src\controllers\finder.py", line 58, in _collect
    form_info = self._parse_data(form_text)
  File "C:\Users\USER\Projects\AichiTool\AichiSelenium\src\controllers\finder.py", line 97, in _parse_data
    form_info = FormInfo(title, status, start_date_str, end_date_str, template_seq)
  File "C:\Users\USER\Projects\AichiTool\AichiSelenium\src\models\form.py", line 83, in __init__
    self.end_datetime = du.string_to_datetime(self.end_date_str)
  File "C:\Users\USER\Projects\AichiTool\AichiSelenium\src\utils\data_utils.py", line 57, in string_to_datetime
    year = int(match_date.group(1))
AttributeError: 'NoneType' object has no attribute 'group'

During handling of the above exception, another exception occurred:

Traceback (most recent call last):
  File "C:\Users\USER\Projects\AichiTool\AichiSelenium\src\controllers\main_controller.py", line 72, in subprocess
    list_form_info = finder.find(browser)
  File "C:\Users\USER\Projects\AichiTool\AichiSelenium\src\controllers\finder.py", line 25, in find
    self._collect(browser)
  File "C:\Users\USER\Projects\AichiTool\AichiSelenium\src\controllers\finder.py", line 58, in _collect
    form_info = self._parse_data(form_text)
  File "C:\Users\USER\Projects\AichiTool\AichiSelenium\src\controllers\finder.py", line 97, in _parse_data
    form_info = FormInfo(title, status, start_date_str, end_date_str, template_seq)
  File "C:\Users\USER\Projects\AichiTool\AichiSelenium\src\models\form.py", line 83, in __init__
    self.end_datetime = du.string_to_datetime(self.end_date_str)
  File "C:\Users\USER\Projects\AichiTool\AichiSelenium\src\utils\data_utils.py", line 57, in string_to_datetime
    year = int(match_date.group(1))
AttributeError: 'NoneType' object has no attribute 'group'

During handling of the above exception, another exception occurred:

Traceback (most recent call last):
  File "C:\Users\USER\Projects\AichiTool\AichiSelenium\src\controllers\main_controller.py", line 72, in subprocess
    list_form_info = finder.find(browser)
  File "C:\Users\USER\Projects\AichiTool\AichiSelenium\src\controllers\finder.py", line 25, in find
    self._collect(browser)
  File "C:\Users\USER\Projects\AichiTool\AichiSelenium\src\controllers\finder.py", line 58, in _collect
    form_info = self._parse_data(form_text)
  File "C:\Users\USER\Projects\AichiTool\AichiSelenium\src\controllers\finder.py", line 97, in _parse_data
    form_info = FormInfo(title, status, start_date_str, end_date_str, template_seq)
  File "C:\Users\USER\Projects\AichiTool\AichiSelenium\src\models\form.py", line 83, in __init__
    self.end_datetime = du.string_to_datetime(self.end_date_str)
  File "C:\Users\USER\Projects\AichiTool\AichiSelenium\src\utils\data_utils.py", line 57, in string_to_datetime
    year = int(match_date.group(1))
AttributeError: 'NoneType' object has no attribute 'group'
[ 2024-04-24 15:07:53,731 ] 79 main_controller - ERROR - Caught exception: 'NoneType' object has no attribute 'group'
Traceback (most recent call last):
  File "C:\Users\USER\Projects\AichiTool\AichiSelenium\src\controllers\main_controller.py", line 72, in subprocess
    list_form_info = finder.find(browser)
  File "C:\Users\USER\Projects\AichiTool\AichiSelenium\src\controllers\finder.py", line 25, in find
    self._collect(browser)
  File "C:\Users\USER\Projects\AichiTool\AichiSelenium\src\controllers\finder.py", line 58, in _collect
    form_info = self._parse_data(form_text)
  File "C:\Users\USER\Projects\AichiTool\AichiSelenium\src\controllers\finder.py", line 97, in _parse_data
    form_info = FormInfo(title, status, start_date_str, end_date_str, template_seq)
  File "C:\Users\USER\Projects\AichiTool\AichiSelenium\src\models\form.py", line 83, in __init__
    self.end_datetime = du.string_to_datetime(self.end_date_str)
  File "C:\Users\USER\Projects\AichiTool\AichiSelenium\src\utils\data_utils.py", line 57, in string_to_datetime
    year = int(match_date.group(1))
AttributeError: 'NoneType' object has no attribute 'group'

During handling of the above exception, another exception occurred:

Traceback (most recent call last):
  File "C:\Users\USER\Projects\AichiTool\AichiSelenium\src\controllers\main_controller.py", line 72, in subprocess
    list_form_info = finder.find(browser)
  File "C:\Users\USER\Projects\AichiTool\AichiSelenium\src\controllers\finder.py", line 25, in find
    self._collect(browser)
  File "C:\Users\USER\Projects\AichiTool\AichiSelenium\src\controllers\finder.py", line 58, in _collect
    form_info = self._parse_data(form_text)
  File "C:\Users\USER\Projects\AichiTool\AichiSelenium\src\controllers\finder.py", line 97, in _parse_data
    form_info = FormInfo(title, status, start_date_str, end_date_str, template_seq)
  File "C:\Users\USER\Projects\AichiTool\AichiSelenium\src\models\form.py", line 83, in __init__
    self.end_datetime = du.string_to_datetime(self.end_date_str)
  File "C:\Users\USER\Projects\AichiTool\AichiSelenium\src\utils\data_utils.py", line 57, in string_to_datetime
    year = int(match_date.group(1))
AttributeError: 'NoneType' object has no attribute 'group'

During handling of the above exception, another exception occurred:

Traceback (most recent call last):
  File "C:\Users\USER\Projects\AichiTool\AichiSelenium\src\controllers\main_controller.py", line 72, in subprocess
    list_form_info = finder.find(browser)
  File "C:\Users\USER\Projects\AichiTool\AichiSelenium\src\controllers\finder.py", line 25, in find
    self._collect(browser)
  File "C:\Users\USER\Projects\AichiTool\AichiSelenium\src\controllers\finder.py", line 58, in _collect
    form_info = self._parse_data(form_text)
  File "C:\Users\USER\Projects\AichiTool\AichiSelenium\src\controllers\finder.py", line 97, in _parse_data
    form_info = FormInfo(title, status, start_date_str, end_date_str, template_seq)
  File "C:\Users\USER\Projects\AichiTool\AichiSelenium\src\models\form.py", line 83, in __init__
    self.end_datetime = du.string_to_datetime(self.end_date_str)
  File "C:\Users\USER\Projects\AichiTool\AichiSelenium\src\utils\data_utils.py", line 57, in string_to_datetime
    year = int(match_date.group(1))
AttributeError: 'NoneType' object has no attribute 'group'

During handling of the above exception, another exception occurred:

Traceback (most recent call last):
  File "C:\Users\USER\Projects\AichiTool\AichiSelenium\src\controllers\main_controller.py", line 72, in subprocess
    list_form_info = finder.find(browser)
  File "C:\Users\USER\Projects\AichiTool\AichiSelenium\src\controllers\finder.py", line 25, in find
    self._collect(browser)
  File "C:\Users\USER\Projects\AichiTool\AichiSelenium\src\controllers\finder.py", line 58, in _collect
    form_info = self._parse_data(form_text)
  File "C:\Users\USER\Projects\AichiTool\AichiSelenium\src\controllers\finder.py", line 97, in _parse_data
    form_info = FormInfo(title, status, start_date_str, end_date_str, template_seq)
  File "C:\Users\USER\Projects\AichiTool\AichiSelenium\src\models\form.py", line 83, in __init__
    self.end_datetime = du.string_to_datetime(self.end_date_str)
  File "C:\Users\USER\Projects\AichiTool\AichiSelenium\src\utils\data_utils.py", line 57, in string_to_datetime
    year = int(match_date.group(1))
AttributeError: 'NoneType' object has no attribute 'group'
[ 2024-04-24 15:07:55,942 ] 91 main_controller - INFO - Subprocess 0 started with trial number 4
[ 2024-04-24 15:07:55,942 ] 91 main_controller - INFO - Subprocess 0 started with trial number 4
[ 2024-04-24 15:07:55,942 ] 91 main_controller - INFO - Subprocess 0 started with trial number 4
[ 2024-04-24 15:07:55,942 ] 91 main_controller - INFO - Subprocess 0 started with trial number 4
[ 2024-04-24 15:07:55,942 ] 91 main_controller - INFO - Subprocess 0 started with trial number 4
[ 2024-04-24 15:07:58,274 ] 91 main_controller - INFO - Browser opened
[ 2024-04-24 15:07:58,274 ] 91 main_controller - INFO - Browser opened
[ 2024-04-24 15:07:58,274 ] 91 main_controller - INFO - Browser opened
[ 2024-04-24 15:07:58,274 ] 91 main_controller - INFO - Browser opened
[ 2024-04-24 15:07:58,274 ] 91 main_controller - INFO - Browser opened
[ 2024-04-24 15:08:04,899 ] 79 main_controller - ERROR - Caught exception: sequence item 1: expected str instance, NoSuchWindowException found
Traceback (most recent call last):
  File "C:\Users\USER\Projects\AichiTool\AichiSelenium\src\controllers\main_controller.py", line 72, in subprocess
    list_form_info = finder.find(browser)
  File "C:\Users\USER\Projects\AichiTool\AichiSelenium\src\controllers\finder.py", line 25, in find
    self._collect(browser)
  File "C:\Users\USER\Projects\AichiTool\AichiSelenium\src\controllers\finder.py", line 58, in _collect
    form_info = self._parse_data(form_text)
  File "C:\Users\USER\Projects\AichiTool\AichiSelenium\src\controllers\finder.py", line 97, in _parse_data
    form_info = FormInfo(title, status, start_date_str, end_date_str, template_seq)
  File "C:\Users\USER\Projects\AichiTool\AichiSelenium\src\models\form.py", line 83, in __init__
    self._filled = False
  File "C:\Users\USER\Projects\AichiTool\AichiSelenium\src\utils\data_utils.py", line 57, in string_to_datetime
    year = int(match_date.group(1))
AttributeError: 'NoneType' object has no attribute 'group'

During handling of the above exception, another exception occurred:

Traceback (most recent call last):
  File "C:\Users\USER\Projects\AichiTool\AichiSelenium\src\controllers\main_controller.py", line 72, in subprocess
    list_form_info = finder.find(browser)
  File "C:\Users\USER\Projects\AichiTool\AichiSelenium\src\controllers\finder.py", line 25, in find
    self._collect(browser)
  File "C:\Users\USER\Projects\AichiTool\AichiSelenium\src\controllers\finder.py", line 58, in _collect
    form_info = self._parse_data(form_text)
  File "C:\Users\USER\Projects\AichiTool\AichiSelenium\src\controllers\finder.py", line 97, in _parse_data
    form_info = FormInfo(title, status, start_date_str, end_date_str, template_seq)
  File "C:\Users\USER\Projects\AichiTool\AichiSelenium\src\models\form.py", line 83, in __init__
    self._filled = False
  File "C:\Users\USER\Projects\AichiTool\AichiSelenium\src\utils\data_utils.py", line 57, in string_to_datetime
    year = int(match_date.group(1))
AttributeError: 'NoneType' object has no attribute 'group'

During handling of the above exception, another exception occurred:

Traceback (most recent call last):
  File "C:\Users\USER\Projects\AichiTool\AichiSelenium\src\controllers\main_controller.py", line 72, in subprocess
    list_form_info = finder.find(browser)
  File "C:\Users\USER\Projects\AichiTool\AichiSelenium\src\controllers\finder.py", line 25, in find
    self._collect(browser)
  File "C:\Users\USER\Projects\AichiTool\AichiSelenium\src\controllers\finder.py", line 58, in _collect
    form_info = self._parse_data(form_text)
  File "C:\Users\USER\Projects\AichiTool\AichiSelenium\src\controllers\finder.py", line 97, in _parse_data
    form_info = FormInfo(title, status, start_date_str, end_date_str, template_seq)
  File "C:\Users\USER\Projects\AichiTool\AichiSelenium\src\models\form.py", line 83, in __init__
    self._filled = False
  File "C:\Users\USER\Projects\AichiTool\AichiSelenium\src\utils\data_utils.py", line 57, in string_to_datetime
    year = int(match_date.group(1))
AttributeError: 'NoneType' object has no attribute 'group'

During handling of the above exception, another exception occurred:

Traceback (most recent call last):
  File "C:\Users\USER\Projects\AichiTool\AichiSelenium\src\controllers\main_controller.py", line 72, in subprocess
    list_form_info = finder.find(browser)
  File "C:\Users\USER\Projects\AichiTool\AichiSelenium\src\controllers\finder.py", line 25, in find
    self._collect(browser)
  File "C:\Users\USER\Projects\AichiTool\AichiSelenium\src\controllers\finder.py", line 58, in _collect
    form_info = self._parse_data(form_text)
  File "C:\Users\USER\Projects\AichiTool\AichiSelenium\src\controllers\finder.py", line 97, in _parse_data
    form_info = FormInfo(title, status, start_date_str, end_date_str, template_seq)
  File "C:\Users\USER\Projects\AichiTool\AichiSelenium\src\models\form.py", line 83, in __init__
    self._filled = False
  File "C:\Users\USER\Projects\AichiTool\AichiSelenium\src\utils\data_utils.py", line 57, in string_to_datetime
    year = int(match_date.group(1))
AttributeError: 'NoneType' object has no attribute 'group'

During handling of the above exception, another exception occurred:

Traceback (most recent call last):
  File "C:\Users\USER\Projects\AichiTool\AichiSelenium\src\controllers\access.py", line 19, in login
    while browser.current_url != URLs.login_url:
  File "C:\Users\USER\anaconda3\envs\aichi\lib\site-packages\seleniumbase\undetected\__init__.py", line 326, in __getattribute__
    return super().__getattribute__(item)
  File "C:\Users\USER\anaconda3\envs\aichi\lib\site-packages\selenium\webdriver\remote\webdriver.py", line 437, in current_url
    return self.execute(Command.GET_CURRENT_URL)["value"]
  File "C:\Users\USER\anaconda3\envs\aichi\lib\site-packages\selenium\webdriver\remote\webdriver.py", line 347, in execute
    self.error_handler.check_response(response)
  File "C:\Users\USER\anaconda3\envs\aichi\lib\site-packages\selenium\webdriver\remote\errorhandler.py", line 229, in check_response
    raise exception_class(message, screen, stacktrace)
selenium.common.exceptions.NoSuchWindowException: Message: no such window: target window already closed
from unknown error: web view not found
  (Session info: chrome=124.0.6367.61)
Stacktrace:
	GetHandleVerifier [0x00007FF61B9DF922+3045234]
	(No symbol) [0x00007FF61B683652]
	(No symbol) [0x00007FF61B547564]
	(No symbol) [0x00007FF61B51DB4F]
	(No symbol) [0x00007FF61B5C1087]
	(No symbol) [0x00007FF61B5D8871]
	(No symbol) [0x00007FF61B5B9B53]
	(No symbol) [0x00007FF61B58813C]
	(No symbol) [0x00007FF61B588D71]
	GetHandleVerifier [0x00007FF61BA0E89D+3237613]
	GetHandleVerifier [0x00007FF61BA50BA7+3508727]
	GetHandleVerifier [0x00007FF61BA4976F+3478975]
	GetHandleVerifier [0x00007FF61B7BF1C6+815126]
	(No symbol) [0x00007FF61B68ED0F]
	(No symbol) [0x00007FF61B689854]
	(No symbol) [0x00007FF61B6899E2]
	(No symbol) [0x00007FF61B67A574]
	BaseThreadInitThunk [0x00007FF92E12257D+29]
	RtlUserThreadStart [0x00007FF93022AA48+40]


During handling of the above exception, another exception occurred:

Traceback (most recent call last):
  File "C:\Users\USER\Projects\AichiTool\AichiSelenium\src\controllers\main_controller.py", line 58, in subprocess
    result = access.login(browser)
  File "C:\Users\USER\Projects\AichiTool\AichiSelenium\src\controllers\access.py", line 51, in login
    self.logger.error("Failed to login", e)
  File "C:\Users\USER\Projects\AichiTool\AichiSelenium\src\logs.py", line 73, in error
    self._log(logging.ERROR, *msg)
  File "C:\Users\USER\Projects\AichiTool\AichiSelenium\src\logs.py", line 90, in _log
    message = " ".join(msg)
TypeError: sequence item 1: expected str instance, NoSuchWindowException found
[ 2024-04-24 15:08:04,899 ] 79 main_controller - ERROR - Caught exception: sequence item 1: expected str instance, NoSuchWindowException found
Traceback (most recent call last):
  File "C:\Users\USER\Projects\AichiTool\AichiSelenium\src\controllers\main_controller.py", line 72, in subprocess
    list_form_info = finder.find(browser)
  File "C:\Users\USER\Projects\AichiTool\AichiSelenium\src\controllers\finder.py", line 25, in find
    self._collect(browser)
  File "C:\Users\USER\Projects\AichiTool\AichiSelenium\src\controllers\finder.py", line 58, in _collect
    form_info = self._parse_data(form_text)
  File "C:\Users\USER\Projects\AichiTool\AichiSelenium\src\controllers\finder.py", line 97, in _parse_data
    form_info = FormInfo(title, status, start_date_str, end_date_str, template_seq)
  File "C:\Users\USER\Projects\AichiTool\AichiSelenium\src\models\form.py", line 83, in __init__
    self._filled = False
  File "C:\Users\USER\Projects\AichiTool\AichiSelenium\src\utils\data_utils.py", line 57, in string_to_datetime
    year = int(match_date.group(1))
AttributeError: 'NoneType' object has no attribute 'group'

During handling of the above exception, another exception occurred:

Traceback (most recent call last):
  File "C:\Users\USER\Projects\AichiTool\AichiSelenium\src\controllers\main_controller.py", line 72, in subprocess
    list_form_info = finder.find(browser)
  File "C:\Users\USER\Projects\AichiTool\AichiSelenium\src\controllers\finder.py", line 25, in find
    self._collect(browser)
  File "C:\Users\USER\Projects\AichiTool\AichiSelenium\src\controllers\finder.py", line 58, in _collect
    form_info = self._parse_data(form_text)
  File "C:\Users\USER\Projects\AichiTool\AichiSelenium\src\controllers\finder.py", line 97, in _parse_data
    form_info = FormInfo(title, status, start_date_str, end_date_str, template_seq)
  File "C:\Users\USER\Projects\AichiTool\AichiSelenium\src\models\form.py", line 83, in __init__
    self._filled = False
  File "C:\Users\USER\Projects\AichiTool\AichiSelenium\src\utils\data_utils.py", line 57, in string_to_datetime
    year = int(match_date.group(1))
AttributeError: 'NoneType' object has no attribute 'group'

During handling of the above exception, another exception occurred:

Traceback (most recent call last):
  File "C:\Users\USER\Projects\AichiTool\AichiSelenium\src\controllers\main_controller.py", line 72, in subprocess
    list_form_info = finder.find(browser)
  File "C:\Users\USER\Projects\AichiTool\AichiSelenium\src\controllers\finder.py", line 25, in find
    self._collect(browser)
  File "C:\Users\USER\Projects\AichiTool\AichiSelenium\src\controllers\finder.py", line 58, in _collect
    form_info = self._parse_data(form_text)
  File "C:\Users\USER\Projects\AichiTool\AichiSelenium\src\controllers\finder.py", line 97, in _parse_data
    form_info = FormInfo(title, status, start_date_str, end_date_str, template_seq)
  File "C:\Users\USER\Projects\AichiTool\AichiSelenium\src\models\form.py", line 83, in __init__
    self._filled = False
  File "C:\Users\USER\Projects\AichiTool\AichiSelenium\src\utils\data_utils.py", line 57, in string_to_datetime
    year = int(match_date.group(1))
AttributeError: 'NoneType' object has no attribute 'group'

During handling of the above exception, another exception occurred:

Traceback (most recent call last):
  File "C:\Users\USER\Projects\AichiTool\AichiSelenium\src\controllers\main_controller.py", line 72, in subprocess
    list_form_info = finder.find(browser)
  File "C:\Users\USER\Projects\AichiTool\AichiSelenium\src\controllers\finder.py", line 25, in find
    self._collect(browser)
  File "C:\Users\USER\Projects\AichiTool\AichiSelenium\src\controllers\finder.py", line 58, in _collect
    form_info = self._parse_data(form_text)
  File "C:\Users\USER\Projects\AichiTool\AichiSelenium\src\controllers\finder.py", line 97, in _parse_data
    form_info = FormInfo(title, status, start_date_str, end_date_str, template_seq)
  File "C:\Users\USER\Projects\AichiTool\AichiSelenium\src\models\form.py", line 83, in __init__
    self._filled = False
  File "C:\Users\USER\Projects\AichiTool\AichiSelenium\src\utils\data_utils.py", line 57, in string_to_datetime
    year = int(match_date.group(1))
AttributeError: 'NoneType' object has no attribute 'group'

During handling of the above exception, another exception occurred:

Traceback (most recent call last):
  File "C:\Users\USER\Projects\AichiTool\AichiSelenium\src\controllers\access.py", line 19, in login
    while browser.current_url != URLs.login_url:
  File "C:\Users\USER\anaconda3\envs\aichi\lib\site-packages\seleniumbase\undetected\__init__.py", line 326, in __getattribute__
    return super().__getattribute__(item)
  File "C:\Users\USER\anaconda3\envs\aichi\lib\site-packages\selenium\webdriver\remote\webdriver.py", line 437, in current_url
    return self.execute(Command.GET_CURRENT_URL)["value"]
  File "C:\Users\USER\anaconda3\envs\aichi\lib\site-packages\selenium\webdriver\remote\webdriver.py", line 347, in execute
    self.error_handler.check_response(response)
  File "C:\Users\USER\anaconda3\envs\aichi\lib\site-packages\selenium\webdriver\remote\errorhandler.py", line 229, in check_response
    raise exception_class(message, screen, stacktrace)
selenium.common.exceptions.NoSuchWindowException: Message: no such window: target window already closed
from unknown error: web view not found
  (Session info: chrome=124.0.6367.61)
Stacktrace:
	GetHandleVerifier [0x00007FF61B9DF922+3045234]
	(No symbol) [0x00007FF61B683652]
	(No symbol) [0x00007FF61B547564]
	(No symbol) [0x00007FF61B51DB4F]
	(No symbol) [0x00007FF61B5C1087]
	(No symbol) [0x00007FF61B5D8871]
	(No symbol) [0x00007FF61B5B9B53]
	(No symbol) [0x00007FF61B58813C]
	(No symbol) [0x00007FF61B588D71]
	GetHandleVerifier [0x00007FF61BA0E89D+3237613]
	GetHandleVerifier [0x00007FF61BA50BA7+3508727]
	GetHandleVerifier [0x00007FF61BA4976F+3478975]
	GetHandleVerifier [0x00007FF61B7BF1C6+815126]
	(No symbol) [0x00007FF61B68ED0F]
	(No symbol) [0x00007FF61B689854]
	(No symbol) [0x00007FF61B6899E2]
	(No symbol) [0x00007FF61B67A574]
	BaseThreadInitThunk [0x00007FF92E12257D+29]
	RtlUserThreadStart [0x00007FF93022AA48+40]


During handling of the above exception, another exception occurred:

Traceback (most recent call last):
  File "C:\Users\USER\Projects\AichiTool\AichiSelenium\src\controllers\main_controller.py", line 58, in subprocess
    result = access.login(browser)
  File "C:\Users\USER\Projects\AichiTool\AichiSelenium\src\controllers\access.py", line 51, in login
    self.logger.error("Failed to login", e)
  File "C:\Users\USER\Projects\AichiTool\AichiSelenium\src\logs.py", line 73, in error
    self._log(logging.ERROR, *msg)
  File "C:\Users\USER\Projects\AichiTool\AichiSelenium\src\logs.py", line 90, in _log
    message = " ".join(msg)
TypeError: sequence item 1: expected str instance, NoSuchWindowException found
[ 2024-04-24 15:08:04,899 ] 79 main_controller - ERROR - Caught exception: sequence item 1: expected str instance, NoSuchWindowException found
Traceback (most recent call last):
  File "C:\Users\USER\Projects\AichiTool\AichiSelenium\src\controllers\main_controller.py", line 72, in subprocess
    list_form_info = finder.find(browser)
  File "C:\Users\USER\Projects\AichiTool\AichiSelenium\src\controllers\finder.py", line 25, in find
    self._collect(browser)
  File "C:\Users\USER\Projects\AichiTool\AichiSelenium\src\controllers\finder.py", line 58, in _collect
    form_info = self._parse_data(form_text)
  File "C:\Users\USER\Projects\AichiTool\AichiSelenium\src\controllers\finder.py", line 97, in _parse_data
    form_info = FormInfo(title, status, start_date_str, end_date_str, template_seq)
  File "C:\Users\USER\Projects\AichiTool\AichiSelenium\src\models\form.py", line 83, in __init__
    self._filled = False
  File "C:\Users\USER\Projects\AichiTool\AichiSelenium\src\utils\data_utils.py", line 57, in string_to_datetime
    year = int(match_date.group(1))
AttributeError: 'NoneType' object has no attribute 'group'

During handling of the above exception, another exception occurred:

Traceback (most recent call last):
  File "C:\Users\USER\Projects\AichiTool\AichiSelenium\src\controllers\main_controller.py", line 72, in subprocess
    list_form_info = finder.find(browser)
  File "C:\Users\USER\Projects\AichiTool\AichiSelenium\src\controllers\finder.py", line 25, in find
    self._collect(browser)
  File "C:\Users\USER\Projects\AichiTool\AichiSelenium\src\controllers\finder.py", line 58, in _collect
    form_info = self._parse_data(form_text)
  File "C:\Users\USER\Projects\AichiTool\AichiSelenium\src\controllers\finder.py", line 97, in _parse_data
    form_info = FormInfo(title, status, start_date_str, end_date_str, template_seq)
  File "C:\Users\USER\Projects\AichiTool\AichiSelenium\src\models\form.py", line 83, in __init__
    self._filled = False
  File "C:\Users\USER\Projects\AichiTool\AichiSelenium\src\utils\data_utils.py", line 57, in string_to_datetime
    year = int(match_date.group(1))
AttributeError: 'NoneType' object has no attribute 'group'

During handling of the above exception, another exception occurred:

Traceback (most recent call last):
  File "C:\Users\USER\Projects\AichiTool\AichiSelenium\src\controllers\main_controller.py", line 72, in subprocess
    list_form_info = finder.find(browser)
  File "C:\Users\USER\Projects\AichiTool\AichiSelenium\src\controllers\finder.py", line 25, in find
    self._collect(browser)
  File "C:\Users\USER\Projects\AichiTool\AichiSelenium\src\controllers\finder.py", line 58, in _collect
    form_info = self._parse_data(form_text)
  File "C:\Users\USER\Projects\AichiTool\AichiSelenium\src\controllers\finder.py", line 97, in _parse_data
    form_info = FormInfo(title, status, start_date_str, end_date_str, template_seq)
  File "C:\Users\USER\Projects\AichiTool\AichiSelenium\src\models\form.py", line 83, in __init__
    self._filled = False
  File "C:\Users\USER\Projects\AichiTool\AichiSelenium\src\utils\data_utils.py", line 57, in string_to_datetime
    year = int(match_date.group(1))
AttributeError: 'NoneType' object has no attribute 'group'

During handling of the above exception, another exception occurred:

Traceback (most recent call last):
  File "C:\Users\USER\Projects\AichiTool\AichiSelenium\src\controllers\main_controller.py", line 72, in subprocess
    list_form_info = finder.find(browser)
  File "C:\Users\USER\Projects\AichiTool\AichiSelenium\src\controllers\finder.py", line 25, in find
    self._collect(browser)
  File "C:\Users\USER\Projects\AichiTool\AichiSelenium\src\controllers\finder.py", line 58, in _collect
    form_info = self._parse_data(form_text)
  File "C:\Users\USER\Projects\AichiTool\AichiSelenium\src\controllers\finder.py", line 97, in _parse_data
    form_info = FormInfo(title, status, start_date_str, end_date_str, template_seq)
  File "C:\Users\USER\Projects\AichiTool\AichiSelenium\src\models\form.py", line 83, in __init__
    self._filled = False
  File "C:\Users\USER\Projects\AichiTool\AichiSelenium\src\utils\data_utils.py", line 57, in string_to_datetime
    year = int(match_date.group(1))
AttributeError: 'NoneType' object has no attribute 'group'

During handling of the above exception, another exception occurred:

Traceback (most recent call last):
  File "C:\Users\USER\Projects\AichiTool\AichiSelenium\src\controllers\access.py", line 19, in login
    while browser.current_url != URLs.login_url:
  File "C:\Users\USER\anaconda3\envs\aichi\lib\site-packages\seleniumbase\undetected\__init__.py", line 326, in __getattribute__
    return super().__getattribute__(item)
  File "C:\Users\USER\anaconda3\envs\aichi\lib\site-packages\selenium\webdriver\remote\webdriver.py", line 437, in current_url
    return self.execute(Command.GET_CURRENT_URL)["value"]
  File "C:\Users\USER\anaconda3\envs\aichi\lib\site-packages\selenium\webdriver\remote\webdriver.py", line 347, in execute
    self.error_handler.check_response(response)
  File "C:\Users\USER\anaconda3\envs\aichi\lib\site-packages\selenium\webdriver\remote\errorhandler.py", line 229, in check_response
    raise exception_class(message, screen, stacktrace)
selenium.common.exceptions.NoSuchWindowException: Message: no such window: target window already closed
from unknown error: web view not found
  (Session info: chrome=124.0.6367.61)
Stacktrace:
	GetHandleVerifier [0x00007FF61B9DF922+3045234]
	(No symbol) [0x00007FF61B683652]
	(No symbol) [0x00007FF61B547564]
	(No symbol) [0x00007FF61B51DB4F]
	(No symbol) [0x00007FF61B5C1087]
	(No symbol) [0x00007FF61B5D8871]
	(No symbol) [0x00007FF61B5B9B53]
	(No symbol) [0x00007FF61B58813C]
	(No symbol) [0x00007FF61B588D71]
	GetHandleVerifier [0x00007FF61BA0E89D+3237613]
	GetHandleVerifier [0x00007FF61BA50BA7+3508727]
	GetHandleVerifier [0x00007FF61BA4976F+3478975]
	GetHandleVerifier [0x00007FF61B7BF1C6+815126]
	(No symbol) [0x00007FF61B68ED0F]
	(No symbol) [0x00007FF61B689854]
	(No symbol) [0x00007FF61B6899E2]
	(No symbol) [0x00007FF61B67A574]
	BaseThreadInitThunk [0x00007FF92E12257D+29]
	RtlUserThreadStart [0x00007FF93022AA48+40]


During handling of the above exception, another exception occurred:

Traceback (most recent call last):
  File "C:\Users\USER\Projects\AichiTool\AichiSelenium\src\controllers\main_controller.py", line 58, in subprocess
    result = access.login(browser)
  File "C:\Users\USER\Projects\AichiTool\AichiSelenium\src\controllers\access.py", line 51, in login
    self.logger.error("Failed to login", e)
  File "C:\Users\USER\Projects\AichiTool\AichiSelenium\src\logs.py", line 73, in error
    self._log(logging.ERROR, *msg)
  File "C:\Users\USER\Projects\AichiTool\AichiSelenium\src\logs.py", line 90, in _log
    message = " ".join(msg)
TypeError: sequence item 1: expected str instance, NoSuchWindowException found
[ 2024-04-24 15:08:04,899 ] 79 main_controller - ERROR - Caught exception: sequence item 1: expected str instance, NoSuchWindowException found
Traceback (most recent call last):
  File "C:\Users\USER\Projects\AichiTool\AichiSelenium\src\controllers\main_controller.py", line 72, in subprocess
    list_form_info = finder.find(browser)
  File "C:\Users\USER\Projects\AichiTool\AichiSelenium\src\controllers\finder.py", line 25, in find
    self._collect(browser)
  File "C:\Users\USER\Projects\AichiTool\AichiSelenium\src\controllers\finder.py", line 58, in _collect
    form_info = self._parse_data(form_text)
  File "C:\Users\USER\Projects\AichiTool\AichiSelenium\src\controllers\finder.py", line 97, in _parse_data
    form_info = FormInfo(title, status, start_date_str, end_date_str, template_seq)
  File "C:\Users\USER\Projects\AichiTool\AichiSelenium\src\models\form.py", line 83, in __init__
    self._filled = False
  File "C:\Users\USER\Projects\AichiTool\AichiSelenium\src\utils\data_utils.py", line 57, in string_to_datetime
    year = int(match_date.group(1))
AttributeError: 'NoneType' object has no attribute 'group'

During handling of the above exception, another exception occurred:

Traceback (most recent call last):
  File "C:\Users\USER\Projects\AichiTool\AichiSelenium\src\controllers\main_controller.py", line 72, in subprocess
    list_form_info = finder.find(browser)
  File "C:\Users\USER\Projects\AichiTool\AichiSelenium\src\controllers\finder.py", line 25, in find
    self._collect(browser)
  File "C:\Users\USER\Projects\AichiTool\AichiSelenium\src\controllers\finder.py", line 58, in _collect
    form_info = self._parse_data(form_text)
  File "C:\Users\USER\Projects\AichiTool\AichiSelenium\src\controllers\finder.py", line 97, in _parse_data
    form_info = FormInfo(title, status, start_date_str, end_date_str, template_seq)
  File "C:\Users\USER\Projects\AichiTool\AichiSelenium\src\models\form.py", line 83, in __init__
    self._filled = False
  File "C:\Users\USER\Projects\AichiTool\AichiSelenium\src\utils\data_utils.py", line 57, in string_to_datetime
    year = int(match_date.group(1))
AttributeError: 'NoneType' object has no attribute 'group'

During handling of the above exception, another exception occurred:

Traceback (most recent call last):
  File "C:\Users\USER\Projects\AichiTool\AichiSelenium\src\controllers\main_controller.py", line 72, in subprocess
    list_form_info = finder.find(browser)
  File "C:\Users\USER\Projects\AichiTool\AichiSelenium\src\controllers\finder.py", line 25, in find
    self._collect(browser)
  File "C:\Users\USER\Projects\AichiTool\AichiSelenium\src\controllers\finder.py", line 58, in _collect
    form_info = self._parse_data(form_text)
  File "C:\Users\USER\Projects\AichiTool\AichiSelenium\src\controllers\finder.py", line 97, in _parse_data
    form_info = FormInfo(title, status, start_date_str, end_date_str, template_seq)
  File "C:\Users\USER\Projects\AichiTool\AichiSelenium\src\models\form.py", line 83, in __init__
    self._filled = False
  File "C:\Users\USER\Projects\AichiTool\AichiSelenium\src\utils\data_utils.py", line 57, in string_to_datetime
    year = int(match_date.group(1))
AttributeError: 'NoneType' object has no attribute 'group'

During handling of the above exception, another exception occurred:

Traceback (most recent call last):
  File "C:\Users\USER\Projects\AichiTool\AichiSelenium\src\controllers\main_controller.py", line 72, in subprocess
    list_form_info = finder.find(browser)
  File "C:\Users\USER\Projects\AichiTool\AichiSelenium\src\controllers\finder.py", line 25, in find
    self._collect(browser)
  File "C:\Users\USER\Projects\AichiTool\AichiSelenium\src\controllers\finder.py", line 58, in _collect
    form_info = self._parse_data(form_text)
  File "C:\Users\USER\Projects\AichiTool\AichiSelenium\src\controllers\finder.py", line 97, in _parse_data
    form_info = FormInfo(title, status, start_date_str, end_date_str, template_seq)
  File "C:\Users\USER\Projects\AichiTool\AichiSelenium\src\models\form.py", line 83, in __init__
    self._filled = False
  File "C:\Users\USER\Projects\AichiTool\AichiSelenium\src\utils\data_utils.py", line 57, in string_to_datetime
    year = int(match_date.group(1))
AttributeError: 'NoneType' object has no attribute 'group'

During handling of the above exception, another exception occurred:

Traceback (most recent call last):
  File "C:\Users\USER\Projects\AichiTool\AichiSelenium\src\controllers\access.py", line 19, in login
    while browser.current_url != URLs.login_url:
  File "C:\Users\USER\anaconda3\envs\aichi\lib\site-packages\seleniumbase\undetected\__init__.py", line 326, in __getattribute__
    return super().__getattribute__(item)
  File "C:\Users\USER\anaconda3\envs\aichi\lib\site-packages\selenium\webdriver\remote\webdriver.py", line 437, in current_url
    return self.execute(Command.GET_CURRENT_URL)["value"]
  File "C:\Users\USER\anaconda3\envs\aichi\lib\site-packages\selenium\webdriver\remote\webdriver.py", line 347, in execute
    self.error_handler.check_response(response)
  File "C:\Users\USER\anaconda3\envs\aichi\lib\site-packages\selenium\webdriver\remote\errorhandler.py", line 229, in check_response
    raise exception_class(message, screen, stacktrace)
selenium.common.exceptions.NoSuchWindowException: Message: no such window: target window already closed
from unknown error: web view not found
  (Session info: chrome=124.0.6367.61)
Stacktrace:
	GetHandleVerifier [0x00007FF61B9DF922+3045234]
	(No symbol) [0x00007FF61B683652]
	(No symbol) [0x00007FF61B547564]
	(No symbol) [0x00007FF61B51DB4F]
	(No symbol) [0x00007FF61B5C1087]
	(No symbol) [0x00007FF61B5D8871]
	(No symbol) [0x00007FF61B5B9B53]
	(No symbol) [0x00007FF61B58813C]
	(No symbol) [0x00007FF61B588D71]
	GetHandleVerifier [0x00007FF61BA0E89D+3237613]
	GetHandleVerifier [0x00007FF61BA50BA7+3508727]
	GetHandleVerifier [0x00007FF61BA4976F+3478975]
	GetHandleVerifier [0x00007FF61B7BF1C6+815126]
	(No symbol) [0x00007FF61B68ED0F]
	(No symbol) [0x00007FF61B689854]
	(No symbol) [0x00007FF61B6899E2]
	(No symbol) [0x00007FF61B67A574]
	BaseThreadInitThunk [0x00007FF92E12257D+29]
	RtlUserThreadStart [0x00007FF93022AA48+40]


During handling of the above exception, another exception occurred:

Traceback (most recent call last):
  File "C:\Users\USER\Projects\AichiTool\AichiSelenium\src\controllers\main_controller.py", line 58, in subprocess
    result = access.login(browser)
  File "C:\Users\USER\Projects\AichiTool\AichiSelenium\src\controllers\access.py", line 51, in login
    self.logger.error("Failed to login", e)
  File "C:\Users\USER\Projects\AichiTool\AichiSelenium\src\logs.py", line 73, in error
    self._log(logging.ERROR, *msg)
  File "C:\Users\USER\Projects\AichiTool\AichiSelenium\src\logs.py", line 90, in _log
    message = " ".join(msg)
TypeError: sequence item 1: expected str instance, NoSuchWindowException found
[ 2024-04-24 15:08:04,899 ] 79 main_controller - ERROR - Caught exception: sequence item 1: expected str instance, NoSuchWindowException found
Traceback (most recent call last):
  File "C:\Users\USER\Projects\AichiTool\AichiSelenium\src\controllers\main_controller.py", line 72, in subprocess
    list_form_info = finder.find(browser)
  File "C:\Users\USER\Projects\AichiTool\AichiSelenium\src\controllers\finder.py", line 25, in find
    self._collect(browser)
  File "C:\Users\USER\Projects\AichiTool\AichiSelenium\src\controllers\finder.py", line 58, in _collect
    form_info = self._parse_data(form_text)
  File "C:\Users\USER\Projects\AichiTool\AichiSelenium\src\controllers\finder.py", line 97, in _parse_data
    form_info = FormInfo(title, status, start_date_str, end_date_str, template_seq)
  File "C:\Users\USER\Projects\AichiTool\AichiSelenium\src\models\form.py", line 83, in __init__
    self._filled = False
  File "C:\Users\USER\Projects\AichiTool\AichiSelenium\src\utils\data_utils.py", line 57, in string_to_datetime
    year = int(match_date.group(1))
AttributeError: 'NoneType' object has no attribute 'group'

During handling of the above exception, another exception occurred:

Traceback (most recent call last):
  File "C:\Users\USER\Projects\AichiTool\AichiSelenium\src\controllers\main_controller.py", line 72, in subprocess
    list_form_info = finder.find(browser)
  File "C:\Users\USER\Projects\AichiTool\AichiSelenium\src\controllers\finder.py", line 25, in find
    self._collect(browser)
  File "C:\Users\USER\Projects\AichiTool\AichiSelenium\src\controllers\finder.py", line 58, in _collect
    form_info = self._parse_data(form_text)
  File "C:\Users\USER\Projects\AichiTool\AichiSelenium\src\controllers\finder.py", line 97, in _parse_data
    form_info = FormInfo(title, status, start_date_str, end_date_str, template_seq)
  File "C:\Users\USER\Projects\AichiTool\AichiSelenium\src\models\form.py", line 83, in __init__
    self._filled = False
  File "C:\Users\USER\Projects\AichiTool\AichiSelenium\src\utils\data_utils.py", line 57, in string_to_datetime
    year = int(match_date.group(1))
AttributeError: 'NoneType' object has no attribute 'group'

During handling of the above exception, another exception occurred:

Traceback (most recent call last):
  File "C:\Users\USER\Projects\AichiTool\AichiSelenium\src\controllers\main_controller.py", line 72, in subprocess
    list_form_info = finder.find(browser)
  File "C:\Users\USER\Projects\AichiTool\AichiSelenium\src\controllers\finder.py", line 25, in find
    self._collect(browser)
  File "C:\Users\USER\Projects\AichiTool\AichiSelenium\src\controllers\finder.py", line 58, in _collect
    form_info = self._parse_data(form_text)
  File "C:\Users\USER\Projects\AichiTool\AichiSelenium\src\controllers\finder.py", line 97, in _parse_data
    form_info = FormInfo(title, status, start_date_str, end_date_str, template_seq)
  File "C:\Users\USER\Projects\AichiTool\AichiSelenium\src\models\form.py", line 83, in __init__
    self._filled = False
  File "C:\Users\USER\Projects\AichiTool\AichiSelenium\src\utils\data_utils.py", line 57, in string_to_datetime
    year = int(match_date.group(1))
AttributeError: 'NoneType' object has no attribute 'group'

During handling of the above exception, another exception occurred:

Traceback (most recent call last):
  File "C:\Users\USER\Projects\AichiTool\AichiSelenium\src\controllers\main_controller.py", line 72, in subprocess
    list_form_info = finder.find(browser)
  File "C:\Users\USER\Projects\AichiTool\AichiSelenium\src\controllers\finder.py", line 25, in find
    self._collect(browser)
  File "C:\Users\USER\Projects\AichiTool\AichiSelenium\src\controllers\finder.py", line 58, in _collect
    form_info = self._parse_data(form_text)
  File "C:\Users\USER\Projects\AichiTool\AichiSelenium\src\controllers\finder.py", line 97, in _parse_data
    form_info = FormInfo(title, status, start_date_str, end_date_str, template_seq)
  File "C:\Users\USER\Projects\AichiTool\AichiSelenium\src\models\form.py", line 83, in __init__
    self._filled = False
  File "C:\Users\USER\Projects\AichiTool\AichiSelenium\src\utils\data_utils.py", line 57, in string_to_datetime
    year = int(match_date.group(1))
AttributeError: 'NoneType' object has no attribute 'group'

During handling of the above exception, another exception occurred:

Traceback (most recent call last):
  File "C:\Users\USER\Projects\AichiTool\AichiSelenium\src\controllers\access.py", line 19, in login
    while browser.current_url != URLs.login_url:
  File "C:\Users\USER\anaconda3\envs\aichi\lib\site-packages\seleniumbase\undetected\__init__.py", line 326, in __getattribute__
    return super().__getattribute__(item)
  File "C:\Users\USER\anaconda3\envs\aichi\lib\site-packages\selenium\webdriver\remote\webdriver.py", line 437, in current_url
    return self.execute(Command.GET_CURRENT_URL)["value"]
  File "C:\Users\USER\anaconda3\envs\aichi\lib\site-packages\selenium\webdriver\remote\webdriver.py", line 347, in execute
    self.error_handler.check_response(response)
  File "C:\Users\USER\anaconda3\envs\aichi\lib\site-packages\selenium\webdriver\remote\errorhandler.py", line 229, in check_response
    raise exception_class(message, screen, stacktrace)
selenium.common.exceptions.NoSuchWindowException: Message: no such window: target window already closed
from unknown error: web view not found
  (Session info: chrome=124.0.6367.61)
Stacktrace:
	GetHandleVerifier [0x00007FF61B9DF922+3045234]
	(No symbol) [0x00007FF61B683652]
	(No symbol) [0x00007FF61B547564]
	(No symbol) [0x00007FF61B51DB4F]
	(No symbol) [0x00007FF61B5C1087]
	(No symbol) [0x00007FF61B5D8871]
	(No symbol) [0x00007FF61B5B9B53]
	(No symbol) [0x00007FF61B58813C]
	(No symbol) [0x00007FF61B588D71]
	GetHandleVerifier [0x00007FF61BA0E89D+3237613]
	GetHandleVerifier [0x00007FF61BA50BA7+3508727]
	GetHandleVerifier [0x00007FF61BA4976F+3478975]
	GetHandleVerifier [0x00007FF61B7BF1C6+815126]
	(No symbol) [0x00007FF61B68ED0F]
	(No symbol) [0x00007FF61B689854]
	(No symbol) [0x00007FF61B6899E2]
	(No symbol) [0x00007FF61B67A574]
	BaseThreadInitThunk [0x00007FF92E12257D+29]
	RtlUserThreadStart [0x00007FF93022AA48+40]


During handling of the above exception, another exception occurred:

Traceback (most recent call last):
  File "C:\Users\USER\Projects\AichiTool\AichiSelenium\src\controllers\main_controller.py", line 58, in subprocess
    result = access.login(browser)
  File "C:\Users\USER\Projects\AichiTool\AichiSelenium\src\controllers\access.py", line 51, in login
    self.logger.error("Failed to login", e)
  File "C:\Users\USER\Projects\AichiTool\AichiSelenium\src\logs.py", line 73, in error
    self._log(logging.ERROR, *msg)
  File "C:\Users\USER\Projects\AichiTool\AichiSelenium\src\logs.py", line 90, in _log
    message = " ".join(msg)
TypeError: sequence item 1: expected str instance, NoSuchWindowException found
