[ 2024-04-16 23:46:37,915 ] 94 main_controller - INFO - Subprocess 0 started with trial number 0
[ 2024-04-16 23:46:37,915 ] 94 main_controller - ERROR - Account is a dictionary, convert to Account object: Username: Nickpown0411@gmail.com, Password: hoahong1234
[ 2024-04-16 23:46:39,848 ] 94 main_controller - INFO - Browser opened
[ 2024-04-16 23:46:39,924 ] 94 main_controller - INFO - Subprocess 1 started with trial number 0
[ 2024-04-16 23:46:39,924 ] 94 main_controller - INFO - Subprocess 1 started with trial number 0
[ 2024-04-16 23:46:39,925 ] 94 main_controller - ERROR - Account is a dictionary, convert to Account object: Username: marjyamada040493@gmail.com, Password: Marj0409
[ 2024-04-16 23:46:39,925 ] 94 main_controller - ERROR - Account is a dictionary, convert to Account object: Username: marjyamada040493@gmail.com, Password: Marj0409
[ 2024-04-16 23:46:41,263 ] 94 main_controller - INFO - Browser opened
[ 2024-04-16 23:46:41,263 ] 94 main_controller - INFO - Browser opened
[ 2024-04-16 23:46:46,718 ] 82 main_controller - ERROR - Caught exception: sequence item 1: expected str instance, NoSuchWindowException found
Traceback (most recent call last):
  File "C:\Users\USER\Projects\AichiTool\AichiSelenium\src\controllers\access.py", line 45, in login
    self.logger.info("Current url: {}".format(browser.current_url))
  File "c:\ProgramData\anaconda3\envs\aichi\lib\site-packages\seleniumbase\undetected\__init__.py", line 326, in __getattribute__
    return super().__getattribute__(item)
  File "c:\ProgramData\anaconda3\envs\aichi\lib\site-packages\selenium\webdriver\remote\webdriver.py", line 437, in current_url
    return self.execute(Command.GET_CURRENT_URL)["value"]
  File "c:\ProgramData\anaconda3\envs\aichi\lib\site-packages\selenium\webdriver\remote\webdriver.py", line 347, in execute
    self.error_handler.check_response(response)
  File "c:\ProgramData\anaconda3\envs\aichi\lib\site-packages\selenium\webdriver\remote\errorhandler.py", line 229, in check_response
    raise exception_class(message, screen, stacktrace)
selenium.common.exceptions.NoSuchWindowException: Message: no such window: target window already closed
from unknown error: web view not found
  (Session info: chrome=123.0.6312.123)
Stacktrace:
	GetHandleVerifier [0x00007FF770D87032+63090]
	(No symbol) [0x00007FF770CF2C82]
	(No symbol) [0x00007FF770B8EC65]
	(No symbol) [0x00007FF770B6CA7C]
	(No symbol) [0x00007FF770BFD687]
	(No symbol) [0x00007FF770C12AC1]
	(No symbol) [0x00007FF770BF6D83]
	(No symbol) [0x00007FF770BC83A8]
	(No symbol) [0x00007FF770BC9441]
	GetHandleVerifier [0x00007FF7711825AD+4238317]
	GetHandleVerifier [0x00007FF7711BF70D+4488525]
	GetHandleVerifier [0x00007FF7711B79EF+4456495]
	GetHandleVerifier [0x00007FF770E60576+953270]
	(No symbol) [0x00007FF770CFE54F]
	(No symbol) [0x00007FF770CF9224]
	(No symbol) [0x00007FF770CF935B]
	(No symbol) [0x00007FF770CE9B94]
	BaseThreadInitThunk [0x00007FFDC2F1257D+29]
	RtlUserThreadStart [0x00007FFDC3E0AA48+40]


During handling of the above exception, another exception occurred:

Traceback (most recent call last):
  File "C:\Users\USER\Projects\AichiTool\AichiSelenium\src\controllers\main_controller.py", line 57, in subprocess
    result = access.login(browser)
  File "C:\Users\USER\Projects\AichiTool\AichiSelenium\src\controllers\access.py", line 51, in login
    self.logger.error("Failed to login", e)
  File "C:\Users\USER\Projects\AichiTool\AichiSelenium\src\logs.py", line 76, in error
    self._log(logging.ERROR, *msg)
  File "C:\Users\USER\Projects\AichiTool\AichiSelenium\src\logs.py", line 93, in _log
    message = " ".join(msg)
TypeError: sequence item 1: expected str instance, NoSuchWindowException found
[ 2024-04-16 23:46:46,718 ] 82 main_controller - ERROR - Caught exception: sequence item 1: expected str instance, NoSuchWindowException found
Traceback (most recent call last):
  File "C:\Users\USER\Projects\AichiTool\AichiSelenium\src\controllers\access.py", line 45, in login
    self.logger.info("Current url: {}".format(browser.current_url))
  File "c:\ProgramData\anaconda3\envs\aichi\lib\site-packages\seleniumbase\undetected\__init__.py", line 326, in __getattribute__
    return super().__getattribute__(item)
  File "c:\ProgramData\anaconda3\envs\aichi\lib\site-packages\selenium\webdriver\remote\webdriver.py", line 437, in current_url
    return self.execute(Command.GET_CURRENT_URL)["value"]
  File "c:\ProgramData\anaconda3\envs\aichi\lib\site-packages\selenium\webdriver\remote\webdriver.py", line 347, in execute
    self.error_handler.check_response(response)
  File "c:\ProgramData\anaconda3\envs\aichi\lib\site-packages\selenium\webdriver\remote\errorhandler.py", line 229, in check_response
    raise exception_class(message, screen, stacktrace)
selenium.common.exceptions.NoSuchWindowException: Message: no such window: target window already closed
from unknown error: web view not found
  (Session info: chrome=123.0.6312.123)
Stacktrace:
	GetHandleVerifier [0x00007FF770D87032+63090]
	(No symbol) [0x00007FF770CF2C82]
	(No symbol) [0x00007FF770B8EC65]
	(No symbol) [0x00007FF770B6CA7C]
	(No symbol) [0x00007FF770BFD687]
	(No symbol) [0x00007FF770C12AC1]
	(No symbol) [0x00007FF770BF6D83]
	(No symbol) [0x00007FF770BC83A8]
	(No symbol) [0x00007FF770BC9441]
	GetHandleVerifier [0x00007FF7711825AD+4238317]
	GetHandleVerifier [0x00007FF7711BF70D+4488525]
	GetHandleVerifier [0x00007FF7711B79EF+4456495]
	GetHandleVerifier [0x00007FF770E60576+953270]
	(No symbol) [0x00007FF770CFE54F]
	(No symbol) [0x00007FF770CF9224]
	(No symbol) [0x00007FF770CF935B]
	(No symbol) [0x00007FF770CE9B94]
	BaseThreadInitThunk [0x00007FFDC2F1257D+29]
	RtlUserThreadStart [0x00007FFDC3E0AA48+40]


During handling of the above exception, another exception occurred:

Traceback (most recent call last):
  File "C:\Users\USER\Projects\AichiTool\AichiSelenium\src\controllers\main_controller.py", line 57, in subprocess
    result = access.login(browser)
  File "C:\Users\USER\Projects\AichiTool\AichiSelenium\src\controllers\access.py", line 51, in login
    self.logger.error("Failed to login", e)
  File "C:\Users\USER\Projects\AichiTool\AichiSelenium\src\logs.py", line 76, in error
    self._log(logging.ERROR, *msg)
  File "C:\Users\USER\Projects\AichiTool\AichiSelenium\src\logs.py", line 93, in _log
    message = " ".join(msg)
TypeError: sequence item 1: expected str instance, NoSuchWindowException found
[ 2024-04-16 23:46:46,732 ] 94 main_controller - INFO - Subprocess 0 started with trial number 1
[ 2024-04-16 23:46:46,732 ] 94 main_controller - INFO - Subprocess 0 started with trial number 1
[ 2024-04-16 23:46:46,732 ] 94 main_controller - INFO - Subprocess 0 started with trial number 1
